Workbook

Sheet Amortization
A1: HP-DEMO-001 — Amortization Schedule (เช่าซื้อรถ วิธี gross)
A3: PRINCIPAL (เงินต้น) | B3: 1000000 | D3: VAT (%) | E3: 7 | G3: ROU LIFE (เดือน) | H3: 48
A4: RATE / YEAR (%) | B4: 5 | D4: INSTALLMENT (จากระบบ) | E4: 23029.29 | G4: ดอกเบี้ยรวมทั้งสัญญา | H4: =SUM(F10:F57)
A5: TERM (MONTHS) | B5: 48 | D5: PAYMENT START DATE | E5: 46295 | G5: VAT รวมทั้งสัญญา | H5: =SUM(D10:D57)
A9: # | B9: PAYMENT DATE | C9: INSTALLMENT | D9: VAT | E9: TOTAL INC. VAT | F9: INTEREST | G9: ACCUM. INTEREST | H9: AMORTISATION | I9: BALANCE | J9: DEPRECIATION | K9: ROU BALANCE | L9: DEFERRED INT. BAL | M9: VAT BALANCE
A10: 1 | B10: =EOMONTH($E$5,1) | C10: =IF(1=$B$5,I9+F10,$E$4) | D10: =ROUND(C10*$E$3/100,2) | E10: =C10+D10 | F10: =ROUND($B$3*$B$4/100*O10/365,2) | G10: =IF(1=1,F10,G9+F10) | H10: =C10-F10 | I10: =$B$3-H10 | J10: =ROUND($B$3/$H$3,2) | K10: =$B$3-J10 | L10: =$H$4-G10 | M10: =ROUND($H$5-SUM($D$10:D10),2) | O10: =B10-$E$5
A11: 2 | B11: =EOMONTH($E$5,2) | C11: =IF(2=$B$5,I10+F11,$E$4) | D11: =ROUND(C11*$E$3/100,2) | E11: =C11+D11 | F11: =ROUND(I10*$B$4/100*O11/365,2) | G11: =IF(2=1,F11,G10+F11) | H11: =C11-F11 | I11: =I10-H11 | J11: =ROUND($B$3/$H$3,2) | K11: =K10-J11 | L11: =$H$4-G11 | M11: =ROUND($H$5-SUM($D$10:D11),2) | O11: =B11-B10
A12: 3 | B12: =EOMONTH($E$5,3) | C12: =IF(3=$B$5,I11+F12,$E$4) | D12: =ROUND(C12*$E$3/100,2) | E12: =C12+D12 | F12: =ROUND(I11*$B$4/100*O12/365,2) | G12: =IF(3=1,F12,G11+F12) | H12: =C12-F12 | I12: =I11-H12 | J12: =ROUND($B$3/$H$3,2) | K12: =K11-J12 | L12: =$H$4-G12 | M12: =ROUND($H$5-SUM($D$10:D12),2) | O12: =B12-B11
A13: 4 | B13: =EOMONTH($E$5,4) | C13: =IF(4=$B$5,I12+F13,$E$4) | D13: =ROUND(C13*$E$3/100,2) | E13: =C13+D13 | F13: =ROUND(I12*$B$4/100*O13/365,2) | G13: =IF(4=1,F13,G12+F13) | H13: =C13-F13 | I13: =I12-H13 | J13: =ROUND($B$3/$H$3,2) | K13: =K12-J13 | L13: =$H$4-G13 | M13: =ROUND($H$5-SUM($D$10:D13),2) | O13: =B13-B12
A14: 5 | B14: =EOMONTH($E$5,5) | C14: =IF(5=$B$5,I13+F14,$E$4) | D14: =ROUND(C14*$E$3/100,2) | E14: =C14+D14 | F14: =ROUND(I13*$B$4/100*O14/365,2) | G14: =IF(5=1,F14,G13+F14) | H14: =C14-F14 | I14: =I13-H14 | J14: =ROUND($B$3/$H$3,2) | K14: =K13-J14 | L14: =$H$4-G14 | M14: =ROUND($H$5-SUM($D$10:D14),2) | O14: =B14-B13
A15: 6 | B15: =EOMONTH($E$5,6) | C15: =IF(6=$B$5,I14+F15,$E$4) | D15: =ROUND(C15*$E$3/100,2) | E15: =C15+D15 | F15: =ROUND(I14*$B$4/100*O15/365,2) | G15: =IF(6=1,F15,G14+F15) | H15: =C15-F15 | I15: =I14-H15 | J15: =ROUND($B$3/$H$3,2) | K15: =K14-J15 | L15: =$H$4-G15 | M15: =ROUND($H$5-SUM($D$10:D15),2) | O15: =B15-B14
A16: 7 | B16: =EOMONTH($E$5,7) | C16: =IF(7=$B$5,I15+F16,$E$4) | D16: =ROUND(C16*$E$3/100,2) | E16: =C16+D16 | F16: =ROUND(I15*$B$4/100*O16/365,2) | G16: =IF(7=1,F16,G15+F16) | H16: =C16-F16 | I16: =I15-H16 | J16: =ROUND($B$3/$H$3,2) | K16: =K15-J16 | L16: =$H$4-G16 | M16: =ROUND($H$5-SUM($D$10:D16),2) | O16: =B16-B15
A17: 8 | B17: =EOMONTH($E$5,8) | C17: =IF(8=$B$5,I16+F17,$E$4) | D17: =ROUND(C17*$E$3/100,2) | E17: =C17+D17 | F17: =ROUND(I16*$B$4/100*O17/365,2) | G17: =IF(8=1,F17,G16+F17) | H17: =C17-F17 | I17: =I16-H17 | J17: =ROUND($B$3/$H$3,2) | K17: =K16-J17 | L17: =$H$4-G17 | M17: =ROUND($H$5-SUM($D$10:D17),2) | O17: =B17-B16
A18: 9 | B18: =EOMONTH($E$5,9) | C18: =IF(9=$B$5,I17+F18,$E$4) | D18: =ROUND(C18*$E$3/100,2) | E18: =C18+D18 | F18: =ROUND(I17*$B$4/100*O18/365,2) | G18: =IF(9=1,F18,G17+F18) | H18: =C18-F18 | I18: =I17-H18 | J18: =ROUND($B$3/$H$3,2) | K18: =K17-J18 | L18: =$H$4-G18 | M18: =ROUND($H$5-SUM($D$10:D18),2) | O18: =B18-B17
A19: 10 | B19: =EOMONTH($E$5,10) | C19: =IF(10=$B$5,I18+F19,$E$4) | D19: =ROUND(C19*$E$3/100,2) | E19: =C19+D19 | F19: =ROUND(I18*$B$4/100*O19/365,2) | G19: =IF(10=1,F19,G18+F19) | H19: =C19-F19 | I19: =I18-H19 | J19: =ROUND($B$3/$H$3,2) | K19: =K18-J19 | L19: =$H$4-G19 | M19: =ROUND($H$5-SUM($D$10:D19),2) | O19: =B19-B18
A20: 11 | B20: =EOMONTH($E$5,11) | C20: =IF(11=$B$5,I19+F20,$E$4) | D20: =ROUND(C20*$E$3/100,2) | E20: =C20+D20 | F20: =ROUND(I19*$B$4/100*O20/365,2) | G20: =IF(11=1,F20,G19+F20) | H20: =C20-F20 | I20: =I19-H20 | J20: =ROUND($B$3/$H$3,2) | K20: =K19-J20 | L20: =$H$4-G20 | M20: =ROUND($H$5-SUM($D$10:D20),2) | O20: =B20-B19
A21: 12 | B21: =EOMONTH($E$5,12) | C21: =IF(12=$B$5,I20+F21,$E$4) | D21: =ROUND(C21*$E$3/100,2) | E21: =C21+D21 | F21: =ROUND(I20*$B$4/100*O21/365,2) | G21: =IF(12=1,F21,G20+F21) | H21: =C21-F21 | I21: =I20-H21 | J21: =ROUND($B$3/$H$3,2) | K21: =K20-J21 | L21: =$H$4-G21 | M21: =ROUND($H$5-SUM($D$10:D21),2) | O21: =B21-B20
A22: 13 | B22: =EOMONTH($E$5,13) | C22: =IF(13=$B$5,I21+F22,$E$4) | D22: =ROUND(C22*$E$3/100,2) | E22: =C22+D22 | F22: =ROUND(I21*$B$4/100*O22/365,2) | G22: =IF(13=1,F22,G21+F22) | H22: =C22-F22 | I22: =I21-H22 | J22: =ROUND($B$3/$H$3,2) | K22: =K21-J22 | L22: =$H$4-G22 | M22: =ROUND($H$5-SUM($D$10:D22),2) | O22: =B22-B21
A23: 14 | B23: =EOMONTH($E$5,14) | C23: =IF(14=$B$5,I22+F23,$E$4) | D23: =ROUND(C23*$E$3/100,2) | E23: =C23+D23 | F23: =ROUND(I22*$B$4/100*O23/365,2) | G23: =IF(14=1,F23,G22+F23) | H23: =C23-F23 | I23: =I22-H23 | J23: =ROUND($B$3/$H$3,2) | K23: =K22-J23 | L23: =$H$4-G23 | M23: =ROUND($H$5-SUM($D$10:D23),2) | O23: =B23-B22
A24: 15 | B24: =EOMONTH($E$5,15) | C24: =IF(15=$B$5,I23+F24,$E$4) | D24: =ROUND(C24*$E$3/100,2) | E24: =C24+D24 | F24: =ROUND(I23*$B$4/100*O24/365,2) | G24: =IF(15=1,F24,G23+F24) | H24: =C24-F24 | I24: =I23-H24 | J24: =ROUND($B$3/$H$3,2) | K24: =K23-J24 | L24: =$H$4-G24 | M24: =ROUND($H$5-SUM($D$10:D24),2) | O24: =B24-B23
A25: 16 | B25: =EOMONTH($E$5,16) | C25: =IF(16=$B$5,I24+F25,$E$4) | D25: =ROUND(C25*$E$3/100,2) | E25: =C25+D25 | F25: =ROUND(I24*$B$4/100*O25/365,2) | G25: =IF(16=1,F25,G24+F25) | H25: =C25-F25 | I25: =I24-H25 | J25: =ROUND($B$3/$H$3,2) | K25: =K24-J25 | L25: =$H$4-G25 | M25: =ROUND($H$5-SUM($D$10:D25),2) | O25: =B25-B24
A26: 17 | B26: =EOMONTH($E$5,17) | C26: =IF(17=$B$5,I25+F26,$E$4) | D26: =ROUND(C26*$E$3/100,2) | E26: =C26+D26 | F26: =ROUND(I25*$B$4/100*O26/365,2) | G26: =IF(17=1,F26,G25+F26) | H26: =C26-F26 | I26: =I25-H26 | J26: =ROUND($B$3/$H$3,2) | K26: =K25-J26 | L26: =$H$4-G26 | M26: =ROUND($H$5-SUM($D$10:D26),2) | O26: =B26-B25
A27: 18 | B27: =EOMONTH($E$5,18) | C27: =IF(18=$B$5,I26+F27,$E$4) | D27: =ROUND(C27*$E$3/100,2) | E27: =C27+D27 | F27: =ROUND(I26*$B$4/100*O27/365,2) | G27: =IF(18=1,F27,G26+F27) | H27: =C27-F27 | I27: =I26-H27 | J27: =ROUND($B$3/$H$3,2) | K27: =K26-J27 | L27: =$H$4-G27 | M27: =ROUND($H$5-SUM($D$10:D27),2) | O27: =B27-B26
A28: 19 | B28: =EOMONTH($E$5,19) | C28: =IF(19=$B$5,I27+F28,$E$4) | D28: =ROUND(C28*$E$3/100,2) | E28: =C28+D28 | F28: =ROUND(I27*$B$4/100*O28/365,2) | G28: =IF(19=1,F28,G27+F28) | H28: =C28-F28 | I28: =I27-H28 | J28: =ROUND($B$3/$H$3,2) | K28: =K27-J28 | L28: =$H$4-G28 | M28: =ROUND($H$5-SUM($D$10:D28),2) | O28: =B28-B27
A29: 20 | B29: =EOMONTH($E$5,20) | C29: =IF(20=$B$5,I28+F29,$E$4) | D29: =ROUND(C29*$E$3/100,2) | E29: =C29+D29 | F29: =ROUND(I28*$B$4/100*O29/365,2) | G29: =IF(20=1,F29,G28+F29) | H29: =C29-F29 | I29: =I28-H29 | J29: =ROUND($B$3/$H$3,2) | K29: =K28-J29 | L29: =$H$4-G29 | M29: =ROUND($H$5-SUM($D$10:D29),2) | O29: =B29-B28
A30: 21 | B30: =EOMONTH($E$5,21) | C30: =IF(21=$B$5,I29+F30,$E$4) | D30: =ROUND(C30*$E$3/100,2) | E30: =C30+D30 | F30: =ROUND(I29*$B$4/100*O30/365,2) | G30: =IF(21=1,F30,G29+F30) | H30: =C30-F30 | I30: =I29-H30 | J30: =ROUND($B$3/$H$3,2) | K30: =K29-J30 | L30: =$H$4-G30 | M30: =ROUND($H$5-SUM($D$10:D30),2) | O30: =B30-B29
A31: 22 | B31: =EOMONTH($E$5,22) | C31: =IF(22=$B$5,I30+F31,$E$4) | D31: =ROUND(C31*$E$3/100,2) | E31: =C31+D31 | F31: =ROUND(I30*$B$4/100*O31/365,2) | G31: =IF(22=1,F31,G30+F31) | H31: =C31-F31 | I31: =I30-H31 | J31: =ROUND($B$3/$H$3,2) | K31: =K30-J31 | L31: =$H$4-G31 | M31: =ROUND($H$5-SUM($D$10:D31),2) | O31: =B31-B30
A32: 23 | B32: =EOMONTH($E$5,23) | C32: =IF(23=$B$5,I31+F32,$E$4) | D32: =ROUND(C32*$E$3/100,2) | E32: =C32+D32 | F32: =ROUND(I31*$B$4/100*O32/365,2) | G32: =IF(23=1,F32,G31+F32) | H32: =C32-F32 | I32: =I31-H32 | J32: =ROUND($B$3/$H$3,2) | K32: =K31-J32 | L32: =$H$4-G32 | M32: =ROUND($H$5-SUM($D$10:D32),2) | O32: =B32-B31
A33: 24 | B33: =EOMONTH($E$5,24) | C33: =IF(24=$B$5,I32+F33,$E$4) | D33: =ROUND(C33*$E$3/100,2) | E33: =C33+D33 | F33: =ROUND(I32*$B$4/100*O33/365,2) | G33: =IF(24=1,F33,G32+F33) | H33: =C33-F33 | I33: =I32-H33 | J33: =ROUND($B$3/$H$3,2) | K33: =K32-J33 | L33: =$H$4-G33 | M33: =ROUND($H$5-SUM($D$10:D33),2) | O33: =B33-B32
A34: 25 | B34: =EOMONTH($E$5,25) | C34: =IF(25=$B$5,I33+F34,$E$4) | D34: =ROUND(C34*$E$3/100,2) | E34: =C34+D34 | F34: =ROUND(I33*$B$4/100*O34/365,2) | G34: =IF(25=1,F34,G33+F34) | H34: =C34-F34 | I34: =I33-H34 | J34: =ROUND($B$3/$H$3,2) | K34: =K33-J34 | L34: =$H$4-G34 | M34: =ROUND($H$5-SUM($D$10:D34),2) | O34: =B34-B33
A35: 26 | B35: =EOMONTH($E$5,26) | C35: =IF(26=$B$5,I34+F35,$E$4) | D35: =ROUND(C35*$E$3/100,2) | E35: =C35+D35 | F35: =ROUND(I34*$B$4/100*O35/365,2) | G35: =IF(26=1,F35,G34+F35) | H35: =C35-F35 | I35: =I34-H35 | J35: =ROUND($B$3/$H$3,2) | K35: =K34-J35 | L35: =$H$4-G35 | M35: =ROUND($H$5-SUM($D$10:D35),2) | O35: =B35-B34
A36: 27 | B36: =EOMONTH($E$5,27) | C36: =IF(27=$B$5,I35+F36,$E$4) | D36: =ROUND(C36*$E$3/100,2) | E36: =C36+D36 | F36: =ROUND(I35*$B$4/100*O36/365,2) | G36: =IF(27=1,F36,G35+F36) | H36: =C36-F36 | I36: =I35-H36 | J36: =ROUND($B$3/$H$3,2) | K36: =K35-J36 | L36: =$H$4-G36 | M36: =ROUND($H$5-SUM($D$10:D36),2) | O36: =B36-B35
A37: 28 | B37: =EOMONTH($E$5,28) | C37: =IF(28=$B$5,I36+F37,$E$4) | D37: =ROUND(C37*$E$3/100,2) | E37: =C37+D37 | F37: =ROUND(I36*$B$4/100*O37/365,2) | G37: =IF(28=1,F37,G36+F37) | H37: =C37-F37 | I37: =I36-H37 | J37: =ROUND($B$3/$H$3,2) | K37: =K36-J37 | L37: =$H$4-G37 | M37: =ROUND($H$5-SUM($D$10:D37),2) | O37: =B37-B36
A38: 29 | B38: =EOMONTH($E$5,29) | C38: =IF(29=$B$5,I37+F38,$E$4) | D38: =ROUND(C38*$E$3/100,2) | E38: =C38+D38 | F38: =ROUND(I37*$B$4/100*O38/365,2) | G38: =IF(29=1,F38,G37+F38) | H38: =C38-F38 | I38: =I37-H38 | J38: =ROUND($B$3/$H$3,2) | K38: =K37-J38 | L38: =$H$4-G38 | M38: =ROUND($H$5-SUM($D$10:D38),2) | O38: =B38-B37
A39: 30 | B39: =EOMONTH($E$5,30) | C39: =IF(30=$B$5,I38+F39,$E$4) | D39: =ROUND(C39*$E$3/100,2) | E39: =C39+D39 | F39: =ROUND(I38*$B$4/100*O39/365,2) | G39: =IF(30=1,F39,G38+F39) | H39: =C39-F39 | I39: =I38-H39 | J39: =ROUND($B$3/$H$3,2) | K39: =K38-J39 | L39: =$H$4-G39 | M39: =ROUND($H$5-SUM($D$10:D39),2) | O39: =B39-B38
A40: 31 | B40: =EOMONTH($E$5,31) | C40: =IF(31=$B$5,I39+F40,$E$4) | D40: =ROUND(C40*$E$3/100,2) | E40: =C40+D40 | F40: =ROUND(I39*$B$4/100*O40/365,2) | G40: =IF(31=1,F40,G39+F40) | H40: =C40-F40 | I40: =I39-H40 | J40: =ROUND($B$3/$H$3,2) | K40: =K39-J40 | L40: =$H$4-G40 | M40: =ROUND($H$5-SUM($D$10:D40),2) | O40: =B40-B39
A41: 32 | B41: =EOMONTH($E$5,32) | C41: =IF(32=$B$5,I40+F41,$E$4) | D41: =ROUND(C41*$E$3/100,2) | E41: =C41+D41 | F41: =ROUND(I40*$B$4/100*O41/365,2) | G41: =IF(32=1,F41,G40+F41) | H41: =C41-F41 | I41: =I40-H41 | J41: =ROUND($B$3/$H$3,2) | K41: =K40-J41 | L41: =$H$4-G41 | M41: =ROUND($H$5-SUM($D$10:D41),2) | O41: =B41-B40
A42: 33 | B42: =EOMONTH($E$5,33) | C42: =IF(33=$B$5,I41+F42,$E$4) | D42: =ROUND(C42*$E$3/100,2) | E42: =C42+D42 | F42: =ROUND(I41*$B$4/100*O42/365,2) | G42: =IF(33=1,F42,G41+F42) | H42: =C42-F42 | I42: =I41-H42 | J42: =ROUND($B$3/$H$3,2) | K42: =K41-J42 | L42: =$H$4-G42 | M42: =ROUND($H$5-SUM($D$10:D42),2) | O42: =B42-B41
A43: 34 | B43: =EOMONTH($E$5,34) | C43: =IF(34=$B$5,I42+F43,$E$4) | D43: =ROUND(C43*$E$3/100,2) | E43: =C43+D43 | F43: =ROUND(I42*$B$4/100*O43/365,2) | G43: =IF(34=1,F43,G42+F43) | H43: =C43-F43 | I43: =I42-H43 | J43: =ROUND($B$3/$H$3,2) | K43: =K42-J43 | L43: =$H$4-G43 | M43: =ROUND($H$5-SUM($D$10:D43),2) | O43: =B43-B42
A44: 35 | B44: =EOMONTH($E$5,35) | C44: =IF(35=$B$5,I43+F44,$E$4) | D44: =ROUND(C44*$E$3/100,2) | E44: =C44+D44 | F44: =ROUND(I43*$B$4/100*O44/365,2) | G44: =IF(35=1,F44,G43+F44) | H44: =C44-F44 | I44: =I43-H44 | J44: =ROUND($B$3/$H$3,2) | K44: =K43-J44 | L44: =$H$4-G44 | M44: =ROUND($H$5-SUM($D$10:D44),2) | O44: =B44-B43
...

Sheet Maturity Profile
A1: HP-DEMO-001 — Maturity Profile (GL Classification / TFRS16)
A3: GL Classification — Aging (Current vs Non-current) | D3: ที่มา / วิธีคิด (อ้างอิงแท็บ Amortization)
A4: Current Portion (≤ 12 เดือน) = เงินต้น (AMORTISATION) งวด 1-12 | C4: =SUM(Amortization!H10:H21) | D4: รวม "เงินต้นตัดต่องวด" (คอลัมน์ AMORTISATION — ตัวเลขสีเขียว ในแท็บ Amortization) ของงวดที่ 1–12
A5: Non-current (> 12 เดือน) = เงินต้น งวด 13-48 | C5: =SUM(Amortization!H22:H57) | D5: รวม "เงินต้นตัดต่องวด" (AMORTISATION สีเขียว) ของงวดที่ 13–48 (หรือ Total ลบ Current)
A6: Total Principal | C6: =Amortization!$B$3 | D6: เงินต้นตั้งต้น — ช่อง PRINCIPAL (มุมบนซ้ายแท็บ Amortization) = 1,000,000
A8: ภาระผูกพันตามสัญญาเช่าในอนาคต — แยกช่วงเวลา (รวมเงินต้น + ดอกเบี้ย ยังไม่คิดลด) | D8: ที่มา / วิธีคิด
A9: ภายใน 1 ปี = (AMORTISATION+INTEREST) งวด 1-12 | C9: =SUMPRODUCT((Amortization!A10:A57<=12)*(Amortization!H10:H57+Amortization!F10:F57)) | D9: รวม "เงินต้นตัดต่องวด (AMORTISATION สีเขียว)" + "ดอกเบี้ย (INTEREST สีส้ม)" ของงวดที่ 1–12
A10: 1 - 5 ปี = งวด 13-60 | C10: =SUMPRODUCT((Amortization!A10:A57>12)*(Amortization!A10:A57<=60)*(Amortization!H10:H57+Amortization!F10:F57)) | D10: รวม AMORTISATION (สีเขียว) + INTEREST (สีส้ม) ของงวดที่ 13–48
A11: มากกว่า 5 ปี = งวด > 60 | C11: =SUMPRODUCT((Amortization!A10:A57>60)*(Amortization!H10:H57+Amortization!F10:F57)) | D11: รวม AMORTISATION + INTEREST ของงวดที่เกิน 60 เดือน — สัญญามี 48 งวด จึงไม่มี = 0
A12: Total Future Cash Flow = เงินต้น + ดอกเบี้ยรวม | C12: =Amortization!$B$3+Amortization!$H$4 | D12: ช่อง PRINCIPAL (1,000,000) บวก "ดอกเบี้ยรวมทั้งสัญญา" (INTEREST สีส้มรวมทุกงวด = 105,506.84)
A14: Lease Classification: Finance
