Workbook

Sheet Leasing
A1: LEASE-DEMO-001 — Leasing (เช่ารถระยะยาว · net/ROU)
A3: PRINCIPAL / ROU (NPV) | B3: 800000 | D3: ROU LIFE (เดือน) | E3: 36
A4: RATE / YEAR (%) | B4: 4 | D4: PAYMENT START DATE | E4: 46295 | G4: INSTALLMENT = PMT (แก้เป็นค่าระบบได้) | H4: =ROUND(-PMT($B$4/100/12,$B$5,$B$3),2)
A5: TERM (MONTHS) | B5: 36 | D5: UPFRONT (จ่ายล่วงหน้าวันแรก) | E5: 0 | G5: ดอกเบี้ยรวมทั้งสัญญา | H5: =SUM(D10:D45)
A9: # | B9: PAYMENT DATE | C9: INSTALLMENT | D9: INTEREST | E9: PRINCIPAL (ตัดต้น) | F9: LIABILITY BALANCE | G9: DEPRECIATION | H9: ROU BALANCE
A10: 1 | B10: =EOMONTH($E$5,1) | C10: =IF(1=$B$5,F9+D10,$H$4) | D10: =ROUND($B$3*$B$4/100*J10/365,2) | E10: =C10-D10 | F10: =$B$3-E10 | G10: =ROUND(($B$3+$E$5)/$E$3,2) | H10: =($B$3+$E$5)-G10 | I10: =B10-$E$5 | J10: =B10-$E$5
A11: 2 | B11: =EOMONTH($E$5,2) | C11: =IF(2=$B$5,F10+D11,$H$4) | D11: =ROUND(F10*$B$4/100*J11/365,2) | E11: =C11-D11 | F11: =F10-E11 | G11: =ROUND(($B$3+$E$5)/$E$3,2) | H11: =H10-G11 | I11: =B11-B10 | J11: =B11-B10
A12: 3 | B12: =EOMONTH($E$5,3) | C12: =IF(3=$B$5,F11+D12,$H$4) | D12: =ROUND(F11*$B$4/100*J12/365,2) | E12: =C12-D12 | F12: =F11-E12 | G12: =ROUND(($B$3+$E$5)/$E$3,2) | H12: =H11-G12 | I12: =B12-B11 | J12: =B12-B11
A13: 4 | B13: =EOMONTH($E$5,4) | C13: =IF(4=$B$5,F12+D13,$H$4) | D13: =ROUND(F12*$B$4/100*J13/365,2) | E13: =C13-D13 | F13: =F12-E13 | G13: =ROUND(($B$3+$E$5)/$E$3,2) | H13: =H12-G13 | I13: =B13-B12 | J13: =B13-B12
A14: 5 | B14: =EOMONTH($E$5,5) | C14: =IF(5=$B$5,F13+D14,$H$4) | D14: =ROUND(F13*$B$4/100*J14/365,2) | E14: =C14-D14 | F14: =F13-E14 | G14: =ROUND(($B$3+$E$5)/$E$3,2) | H14: =H13-G14 | I14: =B14-B13 | J14: =B14-B13
A15: 6 | B15: =EOMONTH($E$5,6) | C15: =IF(6=$B$5,F14+D15,$H$4) | D15: =ROUND(F14*$B$4/100*J15/365,2) | E15: =C15-D15 | F15: =F14-E15 | G15: =ROUND(($B$3+$E$5)/$E$3,2) | H15: =H14-G15 | I15: =B15-B14 | J15: =B15-B14
A16: 7 | B16: =EOMONTH($E$5,7) | C16: =IF(7=$B$5,F15+D16,$H$4) | D16: =ROUND(F15*$B$4/100*J16/365,2) | E16: =C16-D16 | F16: =F15-E16 | G16: =ROUND(($B$3+$E$5)/$E$3,2) | H16: =H15-G16 | I16: =B16-B15 | J16: =B16-B15
A17: 8 | B17: =EOMONTH($E$5,8) | C17: =IF(8=$B$5,F16+D17,$H$4) | D17: =ROUND(F16*$B$4/100*J17/365,2) | E17: =C17-D17 | F17: =F16-E17 | G17: =ROUND(($B$3+$E$5)/$E$3,2) | H17: =H16-G17 | I17: =B17-B16 | J17: =B17-B16
A18: 9 | B18: =EOMONTH($E$5,9) | C18: =IF(9=$B$5,F17+D18,$H$4) | D18: =ROUND(F17*$B$4/100*J18/365,2) | E18: =C18-D18 | F18: =F17-E18 | G18: =ROUND(($B$3+$E$5)/$E$3,2) | H18: =H17-G18 | I18: =B18-B17 | J18: =B18-B17
A19: 10 | B19: =EOMONTH($E$5,10) | C19: =IF(10=$B$5,F18+D19,$H$4) | D19: =ROUND(F18*$B$4/100*J19/365,2) | E19: =C19-D19 | F19: =F18-E19 | G19: =ROUND(($B$3+$E$5)/$E$3,2) | H19: =H18-G19 | I19: =B19-B18 | J19: =B19-B18
A20: 11 | B20: =EOMONTH($E$5,11) | C20: =IF(11=$B$5,F19+D20,$H$4) | D20: =ROUND(F19*$B$4/100*J20/365,2) | E20: =C20-D20 | F20: =F19-E20 | G20: =ROUND(($B$3+$E$5)/$E$3,2) | H20: =H19-G20 | I20: =B20-B19 | J20: =B20-B19
A21: 12 | B21: =EOMONTH($E$5,12) | C21: =IF(12=$B$5,F20+D21,$H$4) | D21: =ROUND(F20*$B$4/100*J21/365,2) | E21: =C21-D21 | F21: =F20-E21 | G21: =ROUND(($B$3+$E$5)/$E$3,2) | H21: =H20-G21 | I21: =B21-B20 | J21: =B21-B20
A22: 13 | B22: =EOMONTH($E$5,13) | C22: =IF(13=$B$5,F21+D22,$H$4) | D22: =ROUND(F21*$B$4/100*J22/365,2) | E22: =C22-D22 | F22: =F21-E22 | G22: =ROUND(($B$3+$E$5)/$E$3,2) | H22: =H21-G22 | I22: =B22-B21 | J22: =B22-B21
A23: 14 | B23: =EOMONTH($E$5,14) | C23: =IF(14=$B$5,F22+D23,$H$4) | D23: =ROUND(F22*$B$4/100*J23/365,2) | E23: =C23-D23 | F23: =F22-E23 | G23: =ROUND(($B$3+$E$5)/$E$3,2) | H23: =H22-G23 | I23: =B23-B22 | J23: =B23-B22
A24: 15 | B24: =EOMONTH($E$5,15) | C24: =IF(15=$B$5,F23+D24,$H$4) | D24: =ROUND(F23*$B$4/100*J24/365,2) | E24: =C24-D24 | F24: =F23-E24 | G24: =ROUND(($B$3+$E$5)/$E$3,2) | H24: =H23-G24 | I24: =B24-B23 | J24: =B24-B23
A25: 16 | B25: =EOMONTH($E$5,16) | C25: =IF(16=$B$5,F24+D25,$H$4) | D25: =ROUND(F24*$B$4/100*J25/365,2) | E25: =C25-D25 | F25: =F24-E25 | G25: =ROUND(($B$3+$E$5)/$E$3,2) | H25: =H24-G25 | I25: =B25-B24 | J25: =B25-B24
A26: 17 | B26: =EOMONTH($E$5,17) | C26: =IF(17=$B$5,F25+D26,$H$4) | D26: =ROUND(F25*$B$4/100*J26/365,2) | E26: =C26-D26 | F26: =F25-E26 | G26: =ROUND(($B$3+$E$5)/$E$3,2) | H26: =H25-G26 | I26: =B26-B25 | J26: =B26-B25
A27: 18 | B27: =EOMONTH($E$5,18) | C27: =IF(18=$B$5,F26+D27,$H$4) | D27: =ROUND(F26*$B$4/100*J27/365,2) | E27: =C27-D27 | F27: =F26-E27 | G27: =ROUND(($B$3+$E$5)/$E$3,2) | H27: =H26-G27 | I27: =B27-B26 | J27: =B27-B26
A28: 19 | B28: =EOMONTH($E$5,19) | C28: =IF(19=$B$5,F27+D28,$H$4) | D28: =ROUND(F27*$B$4/100*J28/365,2) | E28: =C28-D28 | F28: =F27-E28 | G28: =ROUND(($B$3+$E$5)/$E$3,2) | H28: =H27-G28 | I28: =B28-B27 | J28: =B28-B27
A29: 20 | B29: =EOMONTH($E$5,20) | C29: =IF(20=$B$5,F28+D29,$H$4) | D29: =ROUND(F28*$B$4/100*J29/365,2) | E29: =C29-D29 | F29: =F28-E29 | G29: =ROUND(($B$3+$E$5)/$E$3,2) | H29: =H28-G29 | I29: =B29-B28 | J29: =B29-B28
A30: 21 | B30: =EOMONTH($E$5,21) | C30: =IF(21=$B$5,F29+D30,$H$4) | D30: =ROUND(F29*$B$4/100*J30/365,2) | E30: =C30-D30 | F30: =F29-E30 | G30: =ROUND(($B$3+$E$5)/$E$3,2) | H30: =H29-G30 | I30: =B30-B29 | J30: =B30-B29
A31: 22 | B31: =EOMONTH($E$5,22) | C31: =IF(22=$B$5,F30+D31,$H$4) | D31: =ROUND(F30*$B$4/100*J31/365,2) | E31: =C31-D31 | F31: =F30-E31 | G31: =ROUND(($B$3+$E$5)/$E$3,2) | H31: =H30-G31 | I31: =B31-B30 | J31: =B31-B30
A32: 23 | B32: =EOMONTH($E$5,23) | C32: =IF(23=$B$5,F31+D32,$H$4) | D32: =ROUND(F31*$B$4/100*J32/365,2) | E32: =C32-D32 | F32: =F31-E32 | G32: =ROUND(($B$3+$E$5)/$E$3,2) | H32: =H31-G32 | I32: =B32-B31 | J32: =B32-B31
A33: 24 | B33: =EOMONTH($E$5,24) | C33: =IF(24=$B$5,F32+D33,$H$4) | D33: =ROUND(F32*$B$4/100*J33/365,2) | E33: =C33-D33 | F33: =F32-E33 | G33: =ROUND(($B$3+$E$5)/$E$3,2) | H33: =H32-G33 | I33: =B33-B32 | J33: =B33-B32
A34: 25 | B34: =EOMONTH($E$5,25) | C34: =IF(25=$B$5,F33+D34,$H$4) | D34: =ROUND(F33*$B$4/100*J34/365,2) | E34: =C34-D34 | F34: =F33-E34 | G34: =ROUND(($B$3+$E$5)/$E$3,2) | H34: =H33-G34 | I34: =B34-B33 | J34: =B34-B33
A35: 26 | B35: =EOMONTH($E$5,26) | C35: =IF(26=$B$5,F34+D35,$H$4) | D35: =ROUND(F34*$B$4/100*J35/365,2) | E35: =C35-D35 | F35: =F34-E35 | G35: =ROUND(($B$3+$E$5)/$E$3,2) | H35: =H34-G35 | I35: =B35-B34 | J35: =B35-B34
A36: 27 | B36: =EOMONTH($E$5,27) | C36: =IF(27=$B$5,F35+D36,$H$4) | D36: =ROUND(F35*$B$4/100*J36/365,2) | E36: =C36-D36 | F36: =F35-E36 | G36: =ROUND(($B$3+$E$5)/$E$3,2) | H36: =H35-G36 | I36: =B36-B35 | J36: =B36-B35
A37: 28 | B37: =EOMONTH($E$5,28) | C37: =IF(28=$B$5,F36+D37,$H$4) | D37: =ROUND(F36*$B$4/100*J37/365,2) | E37: =C37-D37 | F37: =F36-E37 | G37: =ROUND(($B$3+$E$5)/$E$3,2) | H37: =H36-G37 | I37: =B37-B36 | J37: =B37-B36
A38: 29 | B38: =EOMONTH($E$5,29) | C38: =IF(29=$B$5,F37+D38,$H$4) | D38: =ROUND(F37*$B$4/100*J38/365,2) | E38: =C38-D38 | F38: =F37-E38 | G38: =ROUND(($B$3+$E$5)/$E$3,2) | H38: =H37-G38 | I38: =B38-B37 | J38: =B38-B37
A39: 30 | B39: =EOMONTH($E$5,30) | C39: =IF(30=$B$5,F38+D39,$H$4) | D39: =ROUND(F38*$B$4/100*J39/365,2) | E39: =C39-D39 | F39: =F38-E39 | G39: =ROUND(($B$3+$E$5)/$E$3,2) | H39: =H38-G39 | I39: =B39-B38 | J39: =B39-B38
A40: 31 | B40: =EOMONTH($E$5,31) | C40: =IF(31=$B$5,F39+D40,$H$4) | D40: =ROUND(F39*$B$4/100*J40/365,2) | E40: =C40-D40 | F40: =F39-E40 | G40: =ROUND(($B$3+$E$5)/$E$3,2) | H40: =H39-G40 | I40: =B40-B39 | J40: =B40-B39
A41: 32 | B41: =EOMONTH($E$5,32) | C41: =IF(32=$B$5,F40+D41,$H$4) | D41: =ROUND(F40*$B$4/100*J41/365,2) | E41: =C41-D41 | F41: =F40-E41 | G41: =ROUND(($B$3+$E$5)/$E$3,2) | H41: =H40-G41 | I41: =B41-B40 | J41: =B41-B40
A42: 33 | B42: =EOMONTH($E$5,33) | C42: =IF(33=$B$5,F41+D42,$H$4) | D42: =ROUND(F41*$B$4/100*J42/365,2) | E42: =C42-D42 | F42: =F41-E42 | G42: =ROUND(($B$3+$E$5)/$E$3,2) | H42: =H41-G42 | I42: =B42-B41 | J42: =B42-B41
A43: 34 | B43: =EOMONTH($E$5,34) | C43: =IF(34=$B$5,F42+D43,$H$4) | D43: =ROUND(F42*$B$4/100*J43/365,2) | E43: =C43-D43 | F43: =F42-E43 | G43: =ROUND(($B$3+$E$5)/$E$3,2) | H43: =H42-G43 | I43: =B43-B42 | J43: =B43-B42
A44: 35 | B44: =EOMONTH($E$5,35) | C44: =IF(35=$B$5,F43+D44,$H$4) | D44: =ROUND(F43*$B$4/100*J44/365,2) | E44: =C44-D44 | F44: =F43-E44 | G44: =ROUND(($B$3+$E$5)/$E$3,2) | H44: =H43-G44 | I44: =B44-B43 | J44: =B44-B43
...

Sheet Leasing Maturity
A1: LEASE-DEMO-001 — Maturity Profile
A3: GL Classification — Aging | D3: ที่มา / วิธีคิด (อ้างอิงแท็บ schedule)
A4: Current Portion (≤ 12 เดือน) | C4: =SUM(Leasing!E10:E21) | D4: รวม "เงินต้นตัดต่องวด" (คอลัมน์ PRINCIPAL (ตัดต้น) — ตัวเลขสีเขียว) ของงวดที่ 1–12
A5: Non-current (> 12 เดือน) | C5: =SUM(Leasing!E22:E45) | D5: รวม "เงินต้นตัดต่องวด" (PRINCIPAL สีเขียว) ของงวดที่ 13–36 (หรือ Total ลบ Current)
A6: Total Principal | C6: =Leasing!$B$3 | D6: เงินต้นตั้งต้น — ช่อง PRINCIPAL / ROU (มุมบนซ้ายของแท็บ schedule)
A8: ภาระผูกพันในอนาคต (เงินต้น + ดอกเบี้ย ยังไม่คิดลด) | D8: ที่มา / วิธีคิด
A9: ภายใน 1 ปี | C9: =SUMPRODUCT((Leasing!A10:A45<=12)*(Leasing!E10:E45+Leasing!D10:D45)) | D9: รวม "เงินต้นตัดต่องวด (PRINCIPAL สีเขียว)" + "ดอกเบี้ย (INTEREST สีส้ม)" ของงวดที่ 1–12 (เงินสดที่จะจ่ายใน 1 ปีข้างหน้า)
A10: 1 - 5 ปี | C10: =SUMPRODUCT((Leasing!A10:A45>12)*(Leasing!A10:A45<=60)*(Leasing!E10:E45+Leasing!D10:D45)) | D10: รวม PRINCIPAL (สีเขียว) + INTEREST (สีส้ม) ของงวดที่ 13–60
A11: มากกว่า 5 ปี | C11: =SUMPRODUCT((Leasing!A10:A45>60)*(Leasing!E10:E45+Leasing!D10:D45)) | D11: รวม PRINCIPAL + INTEREST ของงวดที่เกิน 60 เดือน — สัญญามี 36 งวด จึงไม่มี = 0
A12: Total Future Cash Flow | C12: =Leasing!$B$3+Leasing!$H$5 | D12: ช่อง PRINCIPAL บวก "ดอกเบี้ยรวมทั้งสัญญา" (INTEREST สีส้มรวมทุกงวด) (กระแสเงินสดอนาคตทั้งหมด ยังไม่คิดลด)
A14: Lease Classification: Finance (net/ROU · TFRS16)

Sheet Lease Other
A1: LSO-DEMO-001 — Lease Other (เช่าอาคาร · net/ROU)
A3: PRINCIPAL / ROU (NPV) | B3: 900000 | D3: ROU LIFE (เดือน) | E3: 60
A4: RATE / YEAR (%) | B4: 3.5 | D4: PAYMENT START DATE | E4: 46295 | G4: INSTALLMENT = PMT (แก้เป็นค่าระบบได้) | H4: =ROUND(-PMT($B$4/100/12,$B$5,$B$3),2)
A5: TERM (MONTHS) | B5: 60 | D5: UPFRONT (จ่ายล่วงหน้าวันแรก) | E5: 50000 | G5: ดอกเบี้ยรวมทั้งสัญญา | H5: =SUM(D10:D69)
A9: # | B9: PAYMENT DATE | C9: INSTALLMENT | D9: INTEREST | E9: PRINCIPAL (ตัดต้น) | F9: LIABILITY BALANCE | G9: DEPRECIATION | H9: ROU BALANCE
A10: 1 | B10: =EOMONTH($E$5,1) | C10: =IF(1=$B$5,F9+D10,$H$4) | D10: =ROUND($B$3*$B$4/100*J10/365,2) | E10: =C10-D10 | F10: =$B$3-E10 | G10: =ROUND(($B$3+$E$5)/$E$3,2) | H10: =($B$3+$E$5)-G10 | I10: =B10-$E$5 | J10: =B10-$E$5
A11: 2 | B11: =EOMONTH($E$5,2) | C11: =IF(2=$B$5,F10+D11,$H$4) | D11: =ROUND(F10*$B$4/100*J11/365,2) | E11: =C11-D11 | F11: =F10-E11 | G11: =ROUND(($B$3+$E$5)/$E$3,2) | H11: =H10-G11 | I11: =B11-B10 | J11: =B11-B10
A12: 3 | B12: =EOMONTH($E$5,3) | C12: =IF(3=$B$5,F11+D12,$H$4) | D12: =ROUND(F11*$B$4/100*J12/365,2) | E12: =C12-D12 | F12: =F11-E12 | G12: =ROUND(($B$3+$E$5)/$E$3,2) | H12: =H11-G12 | I12: =B12-B11 | J12: =B12-B11
A13: 4 | B13: =EOMONTH($E$5,4) | C13: =IF(4=$B$5,F12+D13,$H$4) | D13: =ROUND(F12*$B$4/100*J13/365,2) | E13: =C13-D13 | F13: =F12-E13 | G13: =ROUND(($B$3+$E$5)/$E$3,2) | H13: =H12-G13 | I13: =B13-B12 | J13: =B13-B12
A14: 5 | B14: =EOMONTH($E$5,5) | C14: =IF(5=$B$5,F13+D14,$H$4) | D14: =ROUND(F13*$B$4/100*J14/365,2) | E14: =C14-D14 | F14: =F13-E14 | G14: =ROUND(($B$3+$E$5)/$E$3,2) | H14: =H13-G14 | I14: =B14-B13 | J14: =B14-B13
A15: 6 | B15: =EOMONTH($E$5,6) | C15: =IF(6=$B$5,F14+D15,$H$4) | D15: =ROUND(F14*$B$4/100*J15/365,2) | E15: =C15-D15 | F15: =F14-E15 | G15: =ROUND(($B$3+$E$5)/$E$3,2) | H15: =H14-G15 | I15: =B15-B14 | J15: =B15-B14
A16: 7 | B16: =EOMONTH($E$5,7) | C16: =IF(7=$B$5,F15+D16,$H$4) | D16: =ROUND(F15*$B$4/100*J16/365,2) | E16: =C16-D16 | F16: =F15-E16 | G16: =ROUND(($B$3+$E$5)/$E$3,2) | H16: =H15-G16 | I16: =B16-B15 | J16: =B16-B15
A17: 8 | B17: =EOMONTH($E$5,8) | C17: =IF(8=$B$5,F16+D17,$H$4) | D17: =ROUND(F16*$B$4/100*J17/365,2) | E17: =C17-D17 | F17: =F16-E17 | G17: =ROUND(($B$3+$E$5)/$E$3,2) | H17: =H16-G17 | I17: =B17-B16 | J17: =B17-B16
A18: 9 | B18: =EOMONTH($E$5,9) | C18: =IF(9=$B$5,F17+D18,$H$4) | D18: =ROUND(F17*$B$4/100*J18/365,2) | E18: =C18-D18 | F18: =F17-E18 | G18: =ROUND(($B$3+$E$5)/$E$3,2) | H18: =H17-G18 | I18: =B18-B17 | J18: =B18-B17
A19: 10 | B19: =EOMONTH($E$5,10) | C19: =IF(10=$B$5,F18+D19,$H$4) | D19: =ROUND(F18*$B$4/100*J19/365,2) | E19: =C19-D19 | F19: =F18-E19 | G19: =ROUND(($B$3+$E$5)/$E$3,2) | H19: =H18-G19 | I19: =B19-B18 | J19: =B19-B18
A20: 11 | B20: =EOMONTH($E$5,11) | C20: =IF(11=$B$5,F19+D20,$H$4) | D20: =ROUND(F19*$B$4/100*J20/365,2) | E20: =C20-D20 | F20: =F19-E20 | G20: =ROUND(($B$3+$E$5)/$E$3,2) | H20: =H19-G20 | I20: =B20-B19 | J20: =B20-B19
A21: 12 | B21: =EOMONTH($E$5,12) | C21: =IF(12=$B$5,F20+D21,$H$4) | D21: =ROUND(F20*$B$4/100*J21/365,2) | E21: =C21-D21 | F21: =F20-E21 | G21: =ROUND(($B$3+$E$5)/$E$3,2) | H21: =H20-G21 | I21: =B21-B20 | J21: =B21-B20
A22: 13 | B22: =EOMONTH($E$5,13) | C22: =IF(13=$B$5,F21+D22,$H$4) | D22: =ROUND(F21*$B$4/100*J22/365,2) | E22: =C22-D22 | F22: =F21-E22 | G22: =ROUND(($B$3+$E$5)/$E$3,2) | H22: =H21-G22 | I22: =B22-B21 | J22: =B22-B21
A23: 14 | B23: =EOMONTH($E$5,14) | C23: =IF(14=$B$5,F22+D23,$H$4) | D23: =ROUND(F22*$B$4/100*J23/365,2) | E23: =C23-D23 | F23: =F22-E23 | G23: =ROUND(($B$3+$E$5)/$E$3,2) | H23: =H22-G23 | I23: =B23-B22 | J23: =B23-B22
A24: 15 | B24: =EOMONTH($E$5,15) | C24: =IF(15=$B$5,F23+D24,$H$4) | D24: =ROUND(F23*$B$4/100*J24/365,2) | E24: =C24-D24 | F24: =F23-E24 | G24: =ROUND(($B$3+$E$5)/$E$3,2) | H24: =H23-G24 | I24: =B24-B23 | J24: =B24-B23
A25: 16 | B25: =EOMONTH($E$5,16) | C25: =IF(16=$B$5,F24+D25,$H$4) | D25: =ROUND(F24*$B$4/100*J25/365,2) | E25: =C25-D25 | F25: =F24-E25 | G25: =ROUND(($B$3+$E$5)/$E$3,2) | H25: =H24-G25 | I25: =B25-B24 | J25: =B25-B24
A26: 17 | B26: =EOMONTH($E$5,17) | C26: =IF(17=$B$5,F25+D26,$H$4) | D26: =ROUND(F25*$B$4/100*J26/365,2) | E26: =C26-D26 | F26: =F25-E26 | G26: =ROUND(($B$3+$E$5)/$E$3,2) | H26: =H25-G26 | I26: =B26-B25 | J26: =B26-B25
A27: 18 | B27: =EOMONTH($E$5,18) | C27: =IF(18=$B$5,F26+D27,$H$4) | D27: =ROUND(F26*$B$4/100*J27/365,2) | E27: =C27-D27 | F27: =F26-E27 | G27: =ROUND(($B$3+$E$5)/$E$3,2) | H27: =H26-G27 | I27: =B27-B26 | J27: =B27-B26
A28: 19 | B28: =EOMONTH($E$5,19) | C28: =IF(19=$B$5,F27+D28,$H$4) | D28: =ROUND(F27*$B$4/100*J28/365,2) | E28: =C28-D28 | F28: =F27-E28 | G28: =ROUND(($B$3+$E$5)/$E$3,2) | H28: =H27-G28 | I28: =B28-B27 | J28: =B28-B27
A29: 20 | B29: =EOMONTH($E$5,20) | C29: =IF(20=$B$5,F28+D29,$H$4) | D29: =ROUND(F28*$B$4/100*J29/365,2) | E29: =C29-D29 | F29: =F28-E29 | G29: =ROUND(($B$3+$E$5)/$E$3,2) | H29: =H28-G29 | I29: =B29-B28 | J29: =B29-B28
A30: 21 | B30: =EOMONTH($E$5,21) | C30: =IF(21=$B$5,F29+D30,$H$4) | D30: =ROUND(F29*$B$4/100*J30/365,2) | E30: =C30-D30 | F30: =F29-E30 | G30: =ROUND(($B$3+$E$5)/$E$3,2) | H30: =H29-G30 | I30: =B30-B29 | J30: =B30-B29
A31: 22 | B31: =EOMONTH($E$5,22) | C31: =IF(22=$B$5,F30+D31,$H$4) | D31: =ROUND(F30*$B$4/100*J31/365,2) | E31: =C31-D31 | F31: =F30-E31 | G31: =ROUND(($B$3+$E$5)/$E$3,2) | H31: =H30-G31 | I31: =B31-B30 | J31: =B31-B30
A32: 23 | B32: =EOMONTH($E$5,23) | C32: =IF(23=$B$5,F31+D32,$H$4) | D32: =ROUND(F31*$B$4/100*J32/365,2) | E32: =C32-D32 | F32: =F31-E32 | G32: =ROUND(($B$3+$E$5)/$E$3,2) | H32: =H31-G32 | I32: =B32-B31 | J32: =B32-B31
A33: 24 | B33: =EOMONTH($E$5,24) | C33: =IF(24=$B$5,F32+D33,$H$4) | D33: =ROUND(F32*$B$4/100*J33/365,2) | E33: =C33-D33 | F33: =F32-E33 | G33: =ROUND(($B$3+$E$5)/$E$3,2) | H33: =H32-G33 | I33: =B33-B32 | J33: =B33-B32
A34: 25 | B34: =EOMONTH($E$5,25) | C34: =IF(25=$B$5,F33+D34,$H$4) | D34: =ROUND(F33*$B$4/100*J34/365,2) | E34: =C34-D34 | F34: =F33-E34 | G34: =ROUND(($B$3+$E$5)/$E$3,2) | H34: =H33-G34 | I34: =B34-B33 | J34: =B34-B33
A35: 26 | B35: =EOMONTH($E$5,26) | C35: =IF(26=$B$5,F34+D35,$H$4) | D35: =ROUND(F34*$B$4/100*J35/365,2) | E35: =C35-D35 | F35: =F34-E35 | G35: =ROUND(($B$3+$E$5)/$E$3,2) | H35: =H34-G35 | I35: =B35-B34 | J35: =B35-B34
A36: 27 | B36: =EOMONTH($E$5,27) | C36: =IF(27=$B$5,F35+D36,$H$4) | D36: =ROUND(F35*$B$4/100*J36/365,2) | E36: =C36-D36 | F36: =F35-E36 | G36: =ROUND(($B$3+$E$5)/$E$3,2) | H36: =H35-G36 | I36: =B36-B35 | J36: =B36-B35
A37: 28 | B37: =EOMONTH($E$5,28) | C37: =IF(28=$B$5,F36+D37,$H$4) | D37: =ROUND(F36*$B$4/100*J37/365,2) | E37: =C37-D37 | F37: =F36-E37 | G37: =ROUND(($B$3+$E$5)/$E$3,2) | H37: =H36-G37 | I37: =B37-B36 | J37: =B37-B36
A38: 29 | B38: =EOMONTH($E$5,29) | C38: =IF(29=$B$5,F37+D38,$H$4) | D38: =ROUND(F37*$B$4/100*J38/365,2) | E38: =C38-D38 | F38: =F37-E38 | G38: =ROUND(($B$3+$E$5)/$E$3,2) | H38: =H37-G38 | I38: =B38-B37 | J38: =B38-B37
A39: 30 | B39: =EOMONTH($E$5,30) | C39: =IF(30=$B$5,F38+D39,$H$4) | D39: =ROUND(F38*$B$4/100*J39/365,2) | E39: =C39-D39 | F39: =F38-E39 | G39: =ROUND(($B$3+$E$5)/$E$3,2) | H39: =H38-G39 | I39: =B39-B38 | J39: =B39-B38
A40: 31 | B40: =EOMONTH($E$5,31) | C40: =IF(31=$B$5,F39+D40,$H$4) | D40: =ROUND(F39*$B$4/100*J40/365,2) | E40: =C40-D40 | F40: =F39-E40 | G40: =ROUND(($B$3+$E$5)/$E$3,2) | H40: =H39-G40 | I40: =B40-B39 | J40: =B40-B39
A41: 32 | B41: =EOMONTH($E$5,32) | C41: =IF(32=$B$5,F40+D41,$H$4) | D41: =ROUND(F40*$B$4/100*J41/365,2) | E41: =C41-D41 | F41: =F40-E41 | G41: =ROUND(($B$3+$E$5)/$E$3,2) | H41: =H40-G41 | I41: =B41-B40 | J41: =B41-B40
A42: 33 | B42: =EOMONTH($E$5,33) | C42: =IF(33=$B$5,F41+D42,$H$4) | D42: =ROUND(F41*$B$4/100*J42/365,2) | E42: =C42-D42 | F42: =F41-E42 | G42: =ROUND(($B$3+$E$5)/$E$3,2) | H42: =H41-G42 | I42: =B42-B41 | J42: =B42-B41
A43: 34 | B43: =EOMONTH($E$5,34) | C43: =IF(34=$B$5,F42+D43,$H$4) | D43: =ROUND(F42*$B$4/100*J43/365,2) | E43: =C43-D43 | F43: =F42-E43 | G43: =ROUND(($B$3+$E$5)/$E$3,2) | H43: =H42-G43 | I43: =B43-B42 | J43: =B43-B42
A44: 35 | B44: =EOMONTH($E$5,35) | C44: =IF(35=$B$5,F43+D44,$H$4) | D44: =ROUND(F43*$B$4/100*J44/365,2) | E44: =C44-D44 | F44: =F43-E44 | G44: =ROUND(($B$3+$E$5)/$E$3,2) | H44: =H43-G44 | I44: =B44-B43 | J44: =B44-B43
...

Sheet Lease Other Maturity
A1: LSO-DEMO-001 — Maturity Profile
A3: GL Classification — Aging | D3: ที่มา / วิธีคิด (อ้างอิงแท็บ schedule)
A4: Current Portion (≤ 12 เดือน) | C4: =SUM('Lease Other'!E10:E21) | D4: รวม "เงินต้นตัดต่องวด" (คอลัมน์ PRINCIPAL (ตัดต้น) — ตัวเลขสีเขียว) ของงวดที่ 1–12
A5: Non-current (> 12 เดือน) | C5: =SUM('Lease Other'!E22:E69) | D5: รวม "เงินต้นตัดต่องวด" (PRINCIPAL สีเขียว) ของงวดที่ 13–60 (หรือ Total ลบ Current)
A6: Total Principal | C6: ='Lease Other'!$B$3 | D6: เงินต้นตั้งต้น — ช่อง PRINCIPAL / ROU (มุมบนซ้ายของแท็บ schedule)
A8: ภาระผูกพันในอนาคต (เงินต้น + ดอกเบี้ย ยังไม่คิดลด) | D8: ที่มา / วิธีคิด
A9: ภายใน 1 ปี | C9: =SUMPRODUCT(('Lease Other'!A10:A69<=12)*('Lease Other'!E10:E69+'Lease Other'!D10:D69)) | D9: รวม "เงินต้นตัดต่องวด (PRINCIPAL สีเขียว)" + "ดอกเบี้ย (INTEREST สีส้ม)" ของงวดที่ 1–12 (เงินสดที่จะจ่ายใน 1 ปีข้างหน้า)
A10: 1 - 5 ปี | C10: =SUMPRODUCT(('Lease Other'!A10:A69>12)*('Lease Other'!A10:A69<=60)*('Lease Other'!E10:E69+'Lease Other'!D10:D69)) | D10: รวม PRINCIPAL (สีเขียว) + INTEREST (สีส้ม) ของงวดที่ 13–60
A11: มากกว่า 5 ปี | C11: =SUMPRODUCT(('Lease Other'!A10:A69>60)*('Lease Other'!E10:E69+'Lease Other'!D10:D69)) | D11: รวม PRINCIPAL + INTEREST ของงวดที่เกิน 60 เดือน — สัญญามี 60 งวด จึงไม่มี = 0
A12: Total Future Cash Flow | C12: ='Lease Other'!$B$3+'Lease Other'!$H$5 | D12: ช่อง PRINCIPAL บวก "ดอกเบี้ยรวมทั้งสัญญา" (INTEREST สีส้มรวมทุกงวด) (กระแสเงินสดอนาคตทั้งหมด ยังไม่คิดลด)
A14: Lease Classification: Finance (net/ROU · TFRS16)
