Workbook

Sheet HP Amortization
A1: HP-DEMO-001 — Amortization Schedule (เช่าซื้อรถ วิธี gross)
A3: PRINCIPAL | B3: 1000000 | D3: VAT (%) | E3: 7 | G3: ROU LIFE (เดือน) | H3: 48
A4: RATE / YEAR (%) | B4: 5 | D4: INSTALLMENT (จากระบบ) | E4: 23029.29 | G4: ดอกเบี้ยรวมทั้งสัญญา | H4: =SUM(F10:F57) -> 105506.84
A5: TERM (MONTHS) | B5: 48 | D5: PAYMENT START DATE | E5: 46295 | G5: VAT รวมทั้งสัญญา | H5: =SUM(D10:D57) -> 77385.46
A9: # | B9: PAYMENT DATE | C9: INSTALLMENT | D9: VAT | E9: TOTAL INC. VAT | F9: INTEREST | G9: ACCUM. INTEREST | H9: AMORTISATION | I9: BALANCE | J9: DEPRECIATION | K9: ROU BALANCE | L9: DEFERRED INT. BAL | M9: VAT BALANCE
A10: 1 | B10: =EOMONTH($E$5,1) -> 46326 | C10: =IF(1=$B$5,I9+F10,$E$4) -> 23029.29 | D10: =ROUND(C10*$E$3/100,2) -> 1612.05 | E10: =C10+D10 -> 24641.34 | F10: =ROUND($B$3*$B$4/100*O10/365,2) -> 4246.58 | G10: =IF(1=1,F10,G9+F10) -> 4246.58 | H10: =C10-F10 -> 18782.71 | I10: =$B$3-H10 -> 981217.29 | J10: =ROUND($B$3/$H$3,2) -> 20833.33 | K10: =$B$3-J10 -> 979166.67 | L10: =$H$4-G10 -> 101260.26 | M10: =ROUND($H$5-SUM($D$10:D10),2) -> 75773.41 | O10: =B10-$E$5 -> 31
A11: 2 | B11: =EOMONTH($E$5,2) -> 46356 | C11: =IF(2=$B$5,I10+F11,$E$4) -> 23029.29 | D11: =ROUND(C11*$E$3/100,2) -> 1612.05 | E11: =C11+D11 -> 24641.34 | F11: =ROUND(I10*$B$4/100*O11/365,2) -> 4032.4 | G11: =IF(2=1,F11,G10+F11) -> 8278.98 | H11: =C11-F11 -> 18996.89 | I11: =I10-H11 -> 962220.4 | J11: =ROUND($B$3/$H$3,2) -> 20833.33 | K11: =K10-J11 -> 958333.34 | L11: =$H$4-G11 -> 97227.86 | M11: =ROUND($H$5-SUM($D$10:D11),2) -> 74161.36 | O11: =B11-B10 -> 30
A12: 3 | B12: =EOMONTH($E$5,3) -> 46387 | C12: =IF(3=$B$5,I11+F12,$E$4) -> 23029.29 | D12: =ROUND(C12*$E$3/100,2) -> 1612.05 | E12: =C12+D12 -> 24641.34 | F12: =ROUND(I11*$B$4/100*O12/365,2) -> 4086.14 | G12: =IF(3=1,F12,G11+F12) -> 12365.12 | H12: =C12-F12 -> 18943.15 | I12: =I11-H12 -> 943277.25 | J12: =ROUND($B$3/$H$3,2) -> 20833.33 | K12: =K11-J12 -> 937500.01 | L12: =$H$4-G12 -> 93141.72 | M12: =ROUND($H$5-SUM($D$10:D12),2) -> 72549.31 | O12: =B12-B11 -> 31
A13: 4 | B13: =EOMONTH($E$5,4) -> 46418 | C13: =IF(4=$B$5,I12+F13,$E$4) -> 23029.29 | D13: =ROUND(C13*$E$3/100,2) -> 1612.05 | E13: =C13+D13 -> 24641.34 | F13: =ROUND(I12*$B$4/100*O13/365,2) -> 4005.7 | G13: =IF(4=1,F13,G12+F13) -> 16370.82 | H13: =C13-F13 -> 19023.59 | I13: =I12-H13 -> 924253.66 | J13: =ROUND($B$3/$H$3,2) -> 20833.33 | K13: =K12-J13 -> 916666.68 | L13: =$H$4-G13 -> 89136.02 | M13: =ROUND($H$5-SUM($D$10:D13),2) -> 70937.26 | O13: =B13-B12 -> 31
A14: 5 | B14: =EOMONTH($E$5,5) -> 46446 | C14: =IF(5=$B$5,I13+F14,$E$4) -> 23029.29 | D14: =ROUND(C14*$E$3/100,2) -> 1612.05 | E14: =C14+D14 -> 24641.34 | F14: =ROUND(I13*$B$4/100*O14/365,2) -> 3545.08 | G14: =IF(5=1,F14,G13+F14) -> 19915.9 | H14: =C14-F14 -> 19484.21 | I14: =I13-H14 -> 904769.45 | J14: =ROUND($B$3/$H$3,2) -> 20833.33 | K14: =K13-J14 -> 895833.35 | L14: =$H$4-G14 -> 85590.94 | M14: =ROUND($H$5-SUM($D$10:D14),2) -> 69325.21 | O14: =B14-B13 -> 28
A15: 6 | B15: =EOMONTH($E$5,6) -> 46477 | C15: =IF(6=$B$5,I14+F15,$E$4) -> 23029.29 | D15: =ROUND(C15*$E$3/100,2) -> 1612.05 | E15: =C15+D15 -> 24641.34 | F15: =ROUND(I14*$B$4/100*O15/365,2) -> 3842.17 | G15: =IF(6=1,F15,G14+F15) -> 23758.07 | H15: =C15-F15 -> 19187.12 | I15: =I14-H15 -> 885582.33 | J15: =ROUND($B$3/$H$3,2) -> 20833.33 | K15: =K14-J15 -> 875000.02 | L15: =$H$4-G15 -> 81748.77 | M15: =ROUND($H$5-SUM($D$10:D15),2) -> 67713.16 | O15: =B15-B14 -> 31
A16: 7 | B16: =EOMONTH($E$5,7) -> 46507 | C16: =IF(7=$B$5,I15+F16,$E$4) -> 23029.29 | D16: =ROUND(C16*$E$3/100,2) -> 1612.05 | E16: =C16+D16 -> 24641.34 | F16: =ROUND(I15*$B$4/100*O16/365,2) -> 3639.38 | G16: =IF(7=1,F16,G15+F16) -> 27397.45 | H16: =C16-F16 -> 19389.91 | I16: =I15-H16 -> 866192.42 | J16: =ROUND($B$3/$H$3,2) -> 20833.33 | K16: =K15-J16 -> 854166.69 | L16: =$H$4-G16 -> 78109.39 | M16: =ROUND($H$5-SUM($D$10:D16),2) -> 66101.11 | O16: =B16-B15 -> 30
A17: 8 | B17: =EOMONTH($E$5,8) -> 46538 | C17: =IF(8=$B$5,I16+F17,$E$4) -> 23029.29 | D17: =ROUND(C17*$E$3/100,2) -> 1612.05 | E17: =C17+D17 -> 24641.34 | F17: =ROUND(I16*$B$4/100*O17/365,2) -> 3678.35 | G17: =IF(8=1,F17,G16+F17) -> 31075.8 | H17: =C17-F17 -> 19350.94 | I17: =I16-H17 -> 846841.48 | J17: =ROUND($B$3/$H$3,2) -> 20833.33 | K17: =K16-J17 -> 833333.36 | L17: =$H$4-G17 -> 74431.04 | M17: =ROUND($H$5-SUM($D$10:D17),2) -> 64489.06 | O17: =B17-B16 -> 31
A18: 9 | B18: =EOMONTH($E$5,9) -> 46568 | C18: =IF(9=$B$5,I17+F18,$E$4) -> 23029.29 | D18: =ROUND(C18*$E$3/100,2) -> 1612.05 | E18: =C18+D18 -> 24641.34 | F18: =ROUND(I17*$B$4/100*O18/365,2) -> 3480.17 | G18: =IF(9=1,F18,G17+F18) -> 34555.97 | H18: =C18-F18 -> 19549.12 | I18: =I17-H18 -> 827292.36 | J18: =ROUND($B$3/$H$3,2) -> 20833.33 | K18: =K17-J18 -> 812500.03 | L18: =$H$4-G18 -> 70950.87 | M18: =ROUND($H$5-SUM($D$10:D18),2) -> 62877.01 | O18: =B18-B17 -> 30
A19: 10 | B19: =EOMONTH($E$5,10) -> 46599 | C19: =IF(10=$B$5,I18+F19,$E$4) -> 23029.29 | D19: =ROUND(C19*$E$3/100,2) -> 1612.05 | E19: =C19+D19 -> 24641.34 | F19: =ROUND(I18*$B$4/100*O19/365,2) -> 3513.16 | G19: =IF(10=1,F19,G18+F19) -> 38069.13 | H19: =C19-F19 -> 19516.13 | I19: =I18-H19 -> 807776.23 | J19: =ROUND($B$3/$H$3,2) -> 20833.33 | K19: =K18-J19 -> 791666.7 | L19: =$H$4-G19 -> 67437.71 | M19: =ROUND($H$5-SUM($D$10:D19),2) -> 61264.96 | O19: =B19-B18 -> 31
A20: 11 | B20: =EOMONTH($E$5,11) -> 46630 | C20: =IF(11=$B$5,I19+F20,$E$4) -> 23029.29 | D20: =ROUND(C20*$E$3/100,2) -> 1612.05 | E20: =C20+D20 -> 24641.34 | F20: =ROUND(I19*$B$4/100*O20/365,2) -> 3430.28 | G20: =IF(11=1,F20,G19+F20) -> 41499.41 | H20: =C20-F20 -> 19599.01 | I20: =I19-H20 -> 788177.22 | J20: =ROUND($B$3/$H$3,2) -> 20833.33 | K20: =K19-J20 -> 770833.37 | L20: =$H$4-G20 -> 64007.43 | M20: =ROUND($H$5-SUM($D$10:D20),2) -> 59652.91 | O20: =B20-B19 -> 31
A21: 12 | B21: =EOMONTH($E$5,12) -> 46660 | C21: =IF(12=$B$5,I20+F21,$E$4) -> 23029.29 | D21: =ROUND(C21*$E$3/100,2) -> 1612.05 | E21: =C21+D21 -> 24641.34 | F21: =ROUND(I20*$B$4/100*O21/365,2) -> 3239.08 | G21: =IF(12=1,F21,G20+F21) -> 44738.49 | H21: =C21-F21 -> 19790.21 | I21: =I20-H21 -> 768387.01 | J21: =ROUND($B$3/$H$3,2) -> 20833.33 | K21: =K20-J21 -> 750000.04 | L21: =$H$4-G21 -> 60768.35 | M21: =ROUND($H$5-SUM($D$10:D21),2) -> 58040.86 | O21: =B21-B20 -> 30
A22: 13 | B22: =EOMONTH($E$5,13) -> 46691 | C22: =IF(13=$B$5,I21+F22,$E$4) -> 23029.29 | D22: =ROUND(C22*$E$3/100,2) -> 1612.05 | E22: =C22+D22 -> 24641.34 | F22: =ROUND(I21*$B$4/100*O22/365,2) -> 3263.01 | G22: =IF(13=1,F22,G21+F22) -> 48001.5 | H22: =C22-F22 -> 19766.28 | I22: =I21-H22 -> 748620.73 | J22: =ROUND($B$3/$H$3,2) -> 20833.33 | K22: =K21-J22 -> 729166.71 | L22: =$H$4-G22 -> 57505.34 | M22: =ROUND($H$5-SUM($D$10:D22),2) -> 56428.81 | O22: =B22-B21 -> 31
A23: 14 | B23: =EOMONTH($E$5,14) -> 46721 | C23: =IF(14=$B$5,I22+F23,$E$4) -> 23029.29 | D23: =ROUND(C23*$E$3/100,2) -> 1612.05 | E23: =C23+D23 -> 24641.34 | F23: =ROUND(I22*$B$4/100*O23/365,2) -> 3076.52 | G23: =IF(14=1,F23,G22+F23) -> 51078.02 | H23: =C23-F23 -> 19952.77 | I23: =I22-H23 -> 728667.96 | J23: =ROUND($B$3/$H$3,2) -> 20833.33 | K23: =K22-J23 -> 708333.38 | L23: =$H$4-G23 -> 54428.82 | M23: =ROUND($H$5-SUM($D$10:D23),2) -> 54816.76 | O23: =B23-B22 -> 30
A24: 15 | B24: =EOMONTH($E$5,15) -> 46752 | C24: =IF(15=$B$5,I23+F24,$E$4) -> 23029.29 | D24: =ROUND(C24*$E$3/100,2) -> 1612.05 | E24: =C24+D24 -> 24641.34 | F24: =ROUND(I23*$B$4/100*O24/365,2) -> 3094.34 | G24: =IF(15=1,F24,G23+F24) -> 54172.36 | H24: =C24-F24 -> 19934.95 | I24: =I23-H24 -> 708733.01 | J24: =ROUND($B$3/$H$3,2) -> 20833.33 | K24: =K23-J24 -> 687500.05 | L24: =$H$4-G24 -> 51334.48 | M24: =ROUND($H$5-SUM($D$10:D24),2) -> 53204.71 | O24: =B24-B23 -> 31
A25: 16 | B25: =EOMONTH($E$5,16) -> 46783 | C25: =IF(16=$B$5,I24+F25,$E$4) -> 23029.29 | D25: =ROUND(C25*$E$3/100,2) -> 1612.05 | E25: =C25+D25 -> 24641.34 | F25: =ROUND(I24*$B$4/100*O25/365,2) -> 3009.69 | G25: =IF(16=1,F25,G24+F25) -> 57182.05 | H25: =C25-F25 -> 20019.6 | I25: =I24-H25 -> 688713.41 | J25: =ROUND($B$3/$H$3,2) -> 20833.33 | K25: =K24-J25 -> 666666.72 | L25: =$H$4-G25 -> 48324.79 | M25: =ROUND($H$5-SUM($D$10:D25),2) -> 51592.66 | O25: =B25-B24 -> 31
A26: 17 | B26: =EOMONTH($E$5,17) -> 46812 | C26: =IF(17=$B$5,I25+F26,$E$4) -> 23029.29 | D26: =ROUND(C26*$E$3/100,2) -> 1612.05 | E26: =C26+D26 -> 24641.34 | F26: =ROUND(I25*$B$4/100*O26/365,2) -> 2735.98 | G26: =IF(17=1,F26,G25+F26) -> 59918.03 | H26: =C26-F26 -> 20293.31 | I26: =I25-H26 -> 668420.1 | J26: =ROUND($B$3/$H$3,2) -> 20833.33 | K26: =K25-J26 -> 645833.39 | L26: =$H$4-G26 -> 45588.81 | M26: =ROUND($H$5-SUM($D$10:D26),2) -> 49980.61 | O26: =B26-B25 -> 29
A27: 18 | B27: =EOMONTH($E$5,18) -> 46843 | C27: =IF(18=$B$5,I26+F27,$E$4) -> 23029.29 | D27: =ROUND(C27*$E$3/100,2) -> 1612.05 | E27: =C27+D27 -> 24641.34 | F27: =ROUND(I26*$B$4/100*O27/365,2) -> 2838.5 | G27: =IF(18=1,F27,G26+F27) -> 62756.53 | H27: =C27-F27 -> 20190.79 | I27: =I26-H27 -> 648229.31 | J27: =ROUND($B$3/$H$3,2) -> 20833.33 | K27: =K26-J27 -> 625000.06 | L27: =$H$4-G27 -> 42750.31 | M27: =ROUND($H$5-SUM($D$10:D27),2) -> 48368.56 | O27: =B27-B26 -> 31
A28: 19 | B28: =EOMONTH($E$5,19) -> 46873 | C28: =IF(19=$B$5,I27+F28,$E$4) -> 23029.29 | D28: =ROUND(C28*$E$3/100,2) -> 1612.05 | E28: =C28+D28 -> 24641.34 | F28: =ROUND(I27*$B$4/100*O28/365,2) -> 2663.96 | G28: =IF(19=1,F28,G27+F28) -> 65420.49 | H28: =C28-F28 -> 20365.33 | I28: =I27-H28 -> 627863.98 | J28: =ROUND($B$3/$H$3,2) -> 20833.33 | K28: =K27-J28 -> 604166.73 | L28: =$H$4-G28 -> 40086.35 | M28: =ROUND($H$5-SUM($D$10:D28),2) -> 46756.51 | O28: =B28-B27 -> 30
A29: 20 | B29: =EOMONTH($E$5,20) -> 46904 | C29: =IF(20=$B$5,I28+F29,$E$4) -> 23029.29 | D29: =ROUND(C29*$E$3/100,2) -> 1612.05 | E29: =C29+D29 -> 24641.34 | F29: =ROUND(I28*$B$4/100*O29/365,2) -> 2666.27 | G29: =IF(20=1,F29,G28+F29) -> 68086.76 | H29: =C29-F29 -> 20363.02 | I29: =I28-H29 -> 607500.96 | J29: =ROUND($B$3/$H$3,2) -> 20833.33 | K29: =K28-J29 -> 583333.4 | L29: =$H$4-G29 -> 37420.08 | M29: =ROUND($H$5-SUM($D$10:D29),2) -> 45144.46 | O29: =B29-B28 -> 31
A30: 21 | B30: =EOMONTH($E$5,21) -> 46934 | C30: =IF(21=$B$5,I29+F30,$E$4) -> 23029.29 | D30: =ROUND(C30*$E$3/100,2) -> 1612.05 | E30: =C30+D30 -> 24641.34 | F30: =ROUND(I29*$B$4/100*O30/365,2) -> 2496.58 | G30: =IF(21=1,F30,G29+F30) -> 70583.34 | H30: =C30-F30 -> 20532.71 | I30: =I29-H30 -> 586968.25 | J30: =ROUND($B$3/$H$3,2) -> 20833.33 | K30: =K29-J30 -> 562500.07 | L30: =$H$4-G30 -> 34923.5 | M30: =ROUND($H$5-SUM($D$10:D30),2) -> 43532.41 | O30: =B30-B29 -> 30
A31: 22 | B31: =EOMONTH($E$5,22) -> 46965 | C31: =IF(22=$B$5,I30+F31,$E$4) -> 23029.29 | D31: =ROUND(C31*$E$3/100,2) -> 1612.05 | E31: =C31+D31 -> 24641.34 | F31: =ROUND(I30*$B$4/100*O31/365,2) -> 2492.6 | G31: =IF(22=1,F31,G30+F31) -> 73075.94 | H31: =C31-F31 -> 20536.69 | I31: =I30-H31 -> 566431.56 | J31: =ROUND($B$3/$H$3,2) -> 20833.33 | K31: =K30-J31 -> 541666.74 | L31: =$H$4-G31 -> 32430.9 | M31: =ROUND($H$5-SUM($D$10:D31),2) -> 41920.36 | O31: =B31-B30 -> 31
A32: 23 | B32: =EOMONTH($E$5,23) -> 46996 | C32: =IF(23=$B$5,I31+F32,$E$4) -> 23029.29 | D32: =ROUND(C32*$E$3/100,2) -> 1612.05 | E32: =C32+D32 -> 24641.34 | F32: =ROUND(I31*$B$4/100*O32/365,2) -> 2405.39 | G32: =IF(23=1,F32,G31+F32) -> 75481.33 | H32: =C32-F32 -> 20623.9 | I32: =I31-H32 -> 545807.66 | J32: =ROUND($B$3/$H$3,2) -> 20833.33 | K32: =K31-J32 -> 520833.41 | L32: =$H$4-G32 -> 30025.51 | M32: =ROUND($H$5-SUM($D$10:D32),2) -> 40308.31 | O32: =B32-B31 -> 31
A33: 24 | B33: =EOMONTH($E$5,24) -> 47026 | C33: =IF(24=$B$5,I32+F33,$E$4) -> 23029.29 | D33: =ROUND(C33*$E$3/100,2) -> 1612.05 | E33: =C33+D33 -> 24641.34 | F33: =ROUND(I32*$B$4/100*O33/365,2) -> 2243.05 | G33: =IF(24=1,F33,G32+F33) -> 77724.38 | H33: =C33-F33 -> 20786.24 | I33: =I32-H33 -> 525021.42 | J33: =ROUND($B$3/$H$3,2) -> 20833.33 | K33: =K32-J33 -> 500000.08 | L33: =$H$4-G33 -> 27782.46 | M33: =ROUND($H$5-SUM($D$10:D33),2) -> 38696.26 | O33: =B33-B32 -> 30
A34: 25 | B34: =EOMONTH($E$5,25) -> 47057 | C34: =IF(25=$B$5,I33+F34,$E$4) -> 23029.29 | D34: =ROUND(C34*$E$3/100,2) -> 1612.05 | E34: =C34+D34 -> 24641.34 | F34: =ROUND(I33*$B$4/100*O34/365,2) -> 2229.54 | G34: =IF(25=1,F34,G33+F34) -> 79953.92 | H34: =C34-F34 -> 20799.75 | I34: =I33-H34 -> 504221.67 | J34: =ROUND($B$3/$H$3,2) -> 20833.33 | K34: =K33-J34 -> 479166.75 | L34: =$H$4-G34 -> 25552.92 | M34: =ROUND($H$5-SUM($D$10:D34),2) -> 37084.21 | O34: =B34-B33 -> 31
A35: 26 | B35: =EOMONTH($E$5,26) -> 47087 | C35: =IF(26=$B$5,I34+F35,$E$4) -> 23029.29 | D35: =ROUND(C35*$E$3/100,2) -> 1612.05 | E35: =C35+D35 -> 24641.34 | F35: =ROUND(I34*$B$4/100*O35/365,2) -> 2072.14 | G35: =IF(26=1,F35,G34+F35) -> 82026.06 | H35: =C35-F35 -> 20957.15 | I35: =I34-H35 -> 483264.52 | J35: =ROUND($B$3/$H$3,2) -> 20833.33 | K35: =K34-J35 -> 458333.42 | L35: =$H$4-G35 -> 23480.78 | M35: =ROUND($H$5-SUM($D$10:D35),2) -> 35472.16 | O35: =B35-B34 -> 30
A36: 27 | B36: =EOMONTH($E$5,27) -> 47118 | C36: =IF(27=$B$5,I35+F36,$E$4) -> 23029.29 | D36: =ROUND(C36*$E$3/100,2) -> 1612.05 | E36: =C36+D36 -> 24641.34 | F36: =ROUND(I35*$B$4/100*O36/365,2) -> 2052.22 | G36: =IF(27=1,F36,G35+F36) -> 84078.28 | H36: =C36-F36 -> 20977.07 | I36: =I35-H36 -> 462287.45 | J36: =ROUND($B$3/$H$3,2) -> 20833.33 | K36: =K35-J36 -> 437500.09 | L36: =$H$4-G36 -> 21428.56 | M36: =ROUND($H$5-SUM($D$10:D36),2) -> 33860.11 | O36: =B36-B35 -> 31
A37: 28 | B37: =EOMONTH($E$5,28) -> 47149 | C37: =IF(28=$B$5,I36+F37,$E$4) -> 23029.29 | D37: =ROUND(C37*$E$3/100,2) -> 1612.05 | E37: =C37+D37 -> 24641.34 | F37: =ROUND(I36*$B$4/100*O37/365,2) -> 1963.14 | G37: =IF(28=1,F37,G36+F37) -> 86041.42 | H37: =C37-F37 -> 21066.15 | I37: =I36-H37 -> 441221.3 | J37: =ROUND($B$3/$H$3,2) -> 20833.33 | K37: =K36-J37 -> 416666.76 | L37: =$H$4-G37 -> 19465.42 | M37: =ROUND($H$5-SUM($D$10:D37),2) -> 32248.06 | O37: =B37-B36 -> 31
A38: 29 | B38: =EOMONTH($E$5,29) -> 47177 | C38: =IF(29=$B$5,I37+F38,$E$4) -> 23029.29 | D38: =ROUND(C38*$E$3/100,2) -> 1612.05 | E38: =C38+D38 -> 24641.34 | F38: =ROUND(I37*$B$4/100*O38/365,2) -> 1692.36 | G38: =IF(29=1,F38,G37+F38) -> 87733.78 | H38: =C38-F38 -> 21336.93 | I38: =I37-H38 -> 419884.37 | J38: =ROUND($B$3/$H$3,2) -> 20833.33 | K38: =K37-J38 -> 395833.43 | L38: =$H$4-G38 -> 17773.06 | M38: =ROUND($H$5-SUM($D$10:D38),2) -> 30636.01 | O38: =B38-B37 -> 28
A39: 30 | B39: =EOMONTH($E$5,30) -> 47208 | C39: =IF(30=$B$5,I38+F39,$E$4) -> 23029.29 | D39: =ROUND(C39*$E$3/100,2) -> 1612.05 | E39: =C39+D39 -> 24641.34 | F39: =ROUND(I38*$B$4/100*O39/365,2) -> 1783.07 | G39: =IF(30=1,F39,G38+F39) -> 89516.85 | H39: =C39-F39 -> 21246.22 | I39: =I38-H39 -> 398638.15 | J39: =ROUND($B$3/$H$3,2) -> 20833.33 | K39: =K38-J39 -> 375000.1 | L39: =$H$4-G39 -> 15989.99 | M39: =ROUND($H$5-SUM($D$10:D39),2) -> 29023.96 | O39: =B39-B38 -> 31
A40: 31 | B40: =EOMONTH($E$5,31) -> 47238 | C40: =IF(31=$B$5,I39+F40,$E$4) -> 23029.29 | D40: =ROUND(C40*$E$3/100,2) -> 1612.05 | E40: =C40+D40 -> 24641.34 | F40: =ROUND(I39*$B$4/100*O40/365,2) -> 1638.24 | G40: =IF(31=1,F40,G39+F40) -> 91155.09 | H40: =C40-F40 -> 21391.05 | I40: =I39-H40 -> 377247.1 | J40: =ROUND($B$3/$H$3,2) -> 20833.33 | K40: =K39-J40 -> 354166.77 | L40: =$H$4-G40 -> 14351.75 | M40: =ROUND($H$5-SUM($D$10:D40),2) -> 27411.91 | O40: =B40-B39 -> 30
A41: 32 | B41: =EOMONTH($E$5,32) -> 47269 | C41: =IF(32=$B$5,I40+F41,$E$4) -> 23029.29 | D41: =ROUND(C41*$E$3/100,2) -> 1612.05 | E41: =C41+D41 -> 24641.34 | F41: =ROUND(I40*$B$4/100*O41/365,2) -> 1602.01 | G41: =IF(32=1,F41,G40+F41) -> 92757.1 | H41: =C41-F41 -> 21427.28 | I41: =I40-H41 -> 355819.82 | J41: =ROUND($B$3/$H$3,2) -> 20833.33 | K41: =K40-J41 -> 333333.44 | L41: =$H$4-G41 -> 12749.74 | M41: =ROUND($H$5-SUM($D$10:D41),2) -> 25799.86 | O41: =B41-B40 -> 31
A42: 33 | B42: =EOMONTH($E$5,33) -> 47299 | C42: =IF(33=$B$5,I41+F42,$E$4) -> 23029.29 | D42: =ROUND(C42*$E$3/100,2) -> 1612.05 | E42: =C42+D42 -> 24641.34 | F42: =ROUND(I41*$B$4/100*O42/365,2) -> 1462.27 | G42: =IF(33=1,F42,G41+F42) -> 94219.37 | H42: =C42-F42 -> 21567.02 | I42: =I41-H42 -> 334252.8 | J42: =ROUND($B$3/$H$3,2) -> 20833.33 | K42: =K41-J42 -> 312500.11 | L42: =$H$4-G42 -> 11287.47 | M42: =ROUND($H$5-SUM($D$10:D42),2) -> 24187.81 | O42: =B42-B41 -> 30
A43: 34 | B43: =EOMONTH($E$5,34) -> 47330 | C43: =IF(34=$B$5,I42+F43,$E$4) -> 23029.29 | D43: =ROUND(C43*$E$3/100,2) -> 1612.05 | E43: =C43+D43 -> 24641.34 | F43: =ROUND(I42*$B$4/100*O43/365,2) -> 1419.43 | G43: =IF(34=1,F43,G42+F43) -> 95638.8 | H43: =C43-F43 -> 21609.86 | I43: =I42-H43 -> 312642.94 | J43: =ROUND($B$3/$H$3,2) -> 20833.33 | K43: =K42-J43 -> 291666.78 | L43: =$H$4-G43 -> 9868.04 | M43: =ROUND($H$5-SUM($D$10:D43),2) -> 22575.76 | O43: =B43-B42 -> 31
A44: 35 | B44: =EOMONTH($E$5,35) -> 47361 | C44: =IF(35=$B$5,I43+F44,$E$4) -> 23029.29 | D44: =ROUND(C44*$E$3/100,2) -> 1612.05 | E44: =C44+D44 -> 24641.34 | F44: =ROUND(I43*$B$4/100*O44/365,2) -> 1327.66 | G44: =IF(35=1,F44,G43+F44) -> 96966.46 | H44: =C44-F44 -> 21701.63 | I44: =I43-H44 -> 290941.31 | J44: =ROUND($B$3/$H$3,2) -> 20833.33 | K44: =K43-J44 -> 270833.45 | L44: =$H$4-G44 -> 8540.38 | M44: =ROUND($H$5-SUM($D$10:D44),2) -> 20963.71 | O44: =B44-B43 -> 31
...

Sheet HP Maturity
A1: HP-DEMO-001 — Maturity Profile (GL Classification / TFRS16)
A3: GL Classification — Aging (Current vs Non-current) | D3: ที่มา / วิธีคิด (อ้างอิงแท็บ HP Amortization)
A4: Current Portion (≤ 12 เดือน) | C4: =SUM('HP Amortization'!H10:H21) -> 231612.99 | D4: รวม "เงินต้นตัดต่องวด" (คอลัมน์ AMORTISATION สีเขียว) งวดที่ 1–12
A5: Non-current (> 12 เดือน) | C5: =SUM('HP Amortization'!H22:H57) -> 768387.01 | D5: รวม AMORTISATION (สีเขียว) งวดที่ 13–48 (หรือ Total ลบ Current)
A6: Total Principal | C6: ='HP Amortization'!$B$3 -> 1000000 | D6: เงินต้นตั้งต้น — ช่อง PRINCIPAL
A8: ภาระผูกพันในอนาคต (เงินต้น + ดอกเบี้ย ยังไม่คิดลด) | D8: ที่มา / วิธีคิด
A9: ภายใน 1 ปี | C9: =SUMPRODUCT(('HP Amortization'!A10:A57<=12)*('HP Amortization'!H10:H57+'HP Amortization'!F10:F57)) -> 276351.48 | D9: รวม AMORTISATION (สีเขียว) + INTEREST (สีส้ม) งวดที่ 1–12
A10: 1 - 5 ปี | C10: =SUMPRODUCT(('HP Amortization'!A10:A57>12)*('HP Amortization'!A10:A57<=60)*('HP Amortization'!H10:H57+'HP Amortization'!F10:F57)) -> 829155.36 | D10: รวม AMORTISATION + INTEREST งวดที่ 13–48
A11: มากกว่า 5 ปี | C11: =SUMPRODUCT(('HP Amortization'!A10:A57>60)*('HP Amortization'!H10:H57+'HP Amortization'!F10:F57)) -> 0 | D11: งวดเกิน 60 เดือน — มี 48 งวด จึง = 0
A12: Total Future Cash Flow | C12: ='HP Amortization'!$B$3+'HP Amortization'!$H$4 -> 1105506.8 | D12: ช่อง PRINCIPAL + ดอกเบี้ยรวมทั้งสัญญา (INTEREST สีส้มรวมทุกงวด)
A14: Lease Classification: Finance (gross · HP)

Sheet Leasing
A1: LEASE-DEMO-001 — Leasing (เช่ารถระยะยาว · net/ROU)
A3: PRINCIPAL / ROU (NPV) | B3: 800000 | D3: ROU LIFE (เดือน) | E3: 36
A4: RATE / YEAR (%) | B4: 4 | D4: PAYMENT START DATE | E4: 46295 | G4: INSTALLMENT = PMT (แก้เป็นค่าระบบได้) | H4: =ROUND(-PMT($B$4/100/12,$B$5,$B$3),2) -> 23619.19
A5: TERM (MONTHS) | B5: 36 | D5: UPFRONT (จ่ายล่วงหน้า) | E5: 0 | G5: ดอกเบี้ยรวมทั้งสัญญา | H5: =SUM(D10:D45) -> 50310.92
A9: # | B9: PAYMENT DATE | C9: INSTALLMENT | D9: INTEREST | E9: PRINCIPAL (ตัดต้น) | F9: LIABILITY BALANCE | G9: DEPRECIATION | H9: ROU BALANCE
A10: 1 | B10: =EOMONTH($E$5,1) -> 32 | C10: =IF(1=$B$5,F9+D10,$H$4) -> 23619.19 | D10: =ROUND($B$3*$B$4/100*J10/365,2) -> 2805.48 | E10: =C10-D10 -> 20813.71 | F10: =$B$3-E10 -> 779186.29 | G10: =ROUND(($B$3+$E$5)/$E$3,2) -> 22222.22 | H10: =($B$3+$E$5)-G10 -> 777777.78 | J10: =B10-$E$5 -> 32
A11: 2 | B11: =EOMONTH($E$5,2) -> 60 | C11: =IF(2=$B$5,F10+D11,$H$4) -> 23619.19 | D11: =ROUND(F10*$B$4/100*J11/365,2) -> 2390.93 | E11: =C11-D11 -> 21228.26 | F11: =F10-E11 -> 757958.03 | G11: =ROUND(($B$3+$E$5)/$E$3,2) -> 22222.22 | H11: =H10-G11 -> 755555.56 | J11: =B11-B10 -> 28
A12: 3 | B12: =EOMONTH($E$5,3) -> 91 | C12: =IF(3=$B$5,F11+D12,$H$4) -> 23619.19 | D12: =ROUND(F11*$B$4/100*J12/365,2) -> 2574.98 | E12: =C12-D12 -> 21044.21 | F12: =F11-E12 -> 736913.82 | G12: =ROUND(($B$3+$E$5)/$E$3,2) -> 22222.22 | H12: =H11-G12 -> 733333.34 | J12: =B12-B11 -> 31
A13: 4 | B13: =EOMONTH($E$5,4) -> 121 | C13: =IF(4=$B$5,F12+D13,$H$4) -> 23619.19 | D13: =ROUND(F12*$B$4/100*J13/365,2) -> 2422.73 | E13: =C13-D13 -> 21196.46 | F13: =F12-E13 -> 715717.36 | G13: =ROUND(($B$3+$E$5)/$E$3,2) -> 22222.22 | H13: =H12-G13 -> 711111.12 | J13: =B13-B12 -> 30
A14: 5 | B14: =EOMONTH($E$5,5) -> 152 | C14: =IF(5=$B$5,F13+D14,$H$4) -> 23619.19 | D14: =ROUND(F13*$B$4/100*J14/365,2) -> 2431.48 | E14: =C14-D14 -> 21187.71 | F14: =F13-E14 -> 694529.65 | G14: =ROUND(($B$3+$E$5)/$E$3,2) -> 22222.22 | H14: =H13-G14 -> 688888.9 | J14: =B14-B13 -> 31
A15: 6 | B15: =EOMONTH($E$5,6) -> 182 | C15: =IF(6=$B$5,F14+D15,$H$4) -> 23619.19 | D15: =ROUND(F14*$B$4/100*J15/365,2) -> 2283.39 | E15: =C15-D15 -> 21335.8 | F15: =F14-E15 -> 673193.85 | G15: =ROUND(($B$3+$E$5)/$E$3,2) -> 22222.22 | H15: =H14-G15 -> 666666.68 | J15: =B15-B14 -> 30
A16: 7 | B16: =EOMONTH($E$5,7) -> 213 | C16: =IF(7=$B$5,F15+D16,$H$4) -> 23619.19 | D16: =ROUND(F15*$B$4/100*J16/365,2) -> 2287.01 | E16: =C16-D16 -> 21332.18 | F16: =F15-E16 -> 651861.67 | G16: =ROUND(($B$3+$E$5)/$E$3,2) -> 22222.22 | H16: =H15-G16 -> 644444.46 | J16: =B16-B15 -> 31
A17: 8 | B17: =EOMONTH($E$5,8) -> 244 | C17: =IF(8=$B$5,F16+D17,$H$4) -> 23619.19 | D17: =ROUND(F16*$B$4/100*J17/365,2) -> 2214.54 | E17: =C17-D17 -> 21404.65 | F17: =F16-E17 -> 630457.02 | G17: =ROUND(($B$3+$E$5)/$E$3,2) -> 22222.22 | H17: =H16-G17 -> 622222.24 | J17: =B17-B16 -> 31
A18: 9 | B18: =EOMONTH($E$5,9) -> 274 | C18: =IF(9=$B$5,F17+D18,$H$4) -> 23619.19 | D18: =ROUND(F17*$B$4/100*J18/365,2) -> 2072.74 | E18: =C18-D18 -> 21546.45 | F18: =F17-E18 -> 608910.57 | G18: =ROUND(($B$3+$E$5)/$E$3,2) -> 22222.22 | H18: =H17-G18 -> 600000.02 | J18: =B18-B17 -> 30
A19: 10 | B19: =EOMONTH($E$5,10) -> 305 | C19: =IF(10=$B$5,F18+D19,$H$4) -> 23619.19 | D19: =ROUND(F18*$B$4/100*J19/365,2) -> 2068.63 | E19: =C19-D19 -> 21550.56 | F19: =F18-E19 -> 587360.01 | G19: =ROUND(($B$3+$E$5)/$E$3,2) -> 22222.22 | H19: =H18-G19 -> 577777.8 | J19: =B19-B18 -> 31
A20: 11 | B20: =EOMONTH($E$5,11) -> 335 | C20: =IF(11=$B$5,F19+D20,$H$4) -> 23619.19 | D20: =ROUND(F19*$B$4/100*J20/365,2) -> 1931.05 | E20: =C20-D20 -> 21688.14 | F20: =F19-E20 -> 565671.87 | G20: =ROUND(($B$3+$E$5)/$E$3,2) -> 22222.22 | H20: =H19-G20 -> 555555.58 | J20: =B20-B19 -> 30
A21: 12 | B21: =EOMONTH($E$5,12) -> 366 | C21: =IF(12=$B$5,F20+D21,$H$4) -> 23619.19 | D21: =ROUND(F20*$B$4/100*J21/365,2) -> 1921.73 | E21: =C21-D21 -> 21697.46 | F21: =F20-E21 -> 543974.41 | G21: =ROUND(($B$3+$E$5)/$E$3,2) -> 22222.22 | H21: =H20-G21 -> 533333.36 | J21: =B21-B20 -> 31
A22: 13 | B22: =EOMONTH($E$5,13) -> 397 | C22: =IF(13=$B$5,F21+D22,$H$4) -> 23619.19 | D22: =ROUND(F21*$B$4/100*J22/365,2) -> 1848.02 | E22: =C22-D22 -> 21771.17 | F22: =F21-E22 -> 522203.24 | G22: =ROUND(($B$3+$E$5)/$E$3,2) -> 22222.22 | H22: =H21-G22 -> 511111.14 | J22: =B22-B21 -> 31
A23: 14 | B23: =EOMONTH($E$5,14) -> 425 | C23: =IF(14=$B$5,F22+D23,$H$4) -> 23619.19 | D23: =ROUND(F22*$B$4/100*J23/365,2) -> 1602.38 | E23: =C23-D23 -> 22016.81 | F23: =F22-E23 -> 500186.43 | G23: =ROUND(($B$3+$E$5)/$E$3,2) -> 22222.22 | H23: =H22-G23 -> 488888.92 | J23: =B23-B22 -> 28
A24: 15 | B24: =EOMONTH($E$5,15) -> 456 | C24: =IF(15=$B$5,F23+D24,$H$4) -> 23619.19 | D24: =ROUND(F23*$B$4/100*J24/365,2) -> 1699.26 | E24: =C24-D24 -> 21919.93 | F24: =F23-E24 -> 478266.5 | G24: =ROUND(($B$3+$E$5)/$E$3,2) -> 22222.22 | H24: =H23-G24 -> 466666.7 | J24: =B24-B23 -> 31
A25: 16 | B25: =EOMONTH($E$5,16) -> 486 | C25: =IF(16=$B$5,F24+D25,$H$4) -> 23619.19 | D25: =ROUND(F24*$B$4/100*J25/365,2) -> 1572.38 | E25: =C25-D25 -> 22046.81 | F25: =F24-E25 -> 456219.69 | G25: =ROUND(($B$3+$E$5)/$E$3,2) -> 22222.22 | H25: =H24-G25 -> 444444.48 | J25: =B25-B24 -> 30
A26: 17 | B26: =EOMONTH($E$5,17) -> 517 | C26: =IF(17=$B$5,F25+D26,$H$4) -> 23619.19 | D26: =ROUND(F25*$B$4/100*J26/365,2) -> 1549.9 | E26: =C26-D26 -> 22069.29 | F26: =F25-E26 -> 434150.4 | G26: =ROUND(($B$3+$E$5)/$E$3,2) -> 22222.22 | H26: =H25-G26 -> 422222.26 | J26: =B26-B25 -> 31
A27: 18 | B27: =EOMONTH($E$5,18) -> 547 | C27: =IF(18=$B$5,F26+D27,$H$4) -> 23619.19 | D27: =ROUND(F26*$B$4/100*J27/365,2) -> 1427.34 | E27: =C27-D27 -> 22191.85 | F27: =F26-E27 -> 411958.55 | G27: =ROUND(($B$3+$E$5)/$E$3,2) -> 22222.22 | H27: =H26-G27 -> 400000.04 | J27: =B27-B26 -> 30
A28: 19 | B28: =EOMONTH($E$5,19) -> 578 | C28: =IF(19=$B$5,F27+D28,$H$4) -> 23619.19 | D28: =ROUND(F27*$B$4/100*J28/365,2) -> 1399.53 | E28: =C28-D28 -> 22219.66 | F28: =F27-E28 -> 389738.89 | G28: =ROUND(($B$3+$E$5)/$E$3,2) -> 22222.22 | H28: =H27-G28 -> 377777.82 | J28: =B28-B27 -> 31
A29: 20 | B29: =EOMONTH($E$5,20) -> 609 | C29: =IF(20=$B$5,F28+D29,$H$4) -> 23619.19 | D29: =ROUND(F28*$B$4/100*J29/365,2) -> 1324.04 | E29: =C29-D29 -> 22295.15 | F29: =F28-E29 -> 367443.74 | G29: =ROUND(($B$3+$E$5)/$E$3,2) -> 22222.22 | H29: =H28-G29 -> 355555.6 | J29: =B29-B28 -> 31
A30: 21 | B30: =EOMONTH($E$5,21) -> 639 | C30: =IF(21=$B$5,F29+D30,$H$4) -> 23619.19 | D30: =ROUND(F29*$B$4/100*J30/365,2) -> 1208.03 | E30: =C30-D30 -> 22411.16 | F30: =F29-E30 -> 345032.58 | G30: =ROUND(($B$3+$E$5)/$E$3,2) -> 22222.22 | H30: =H29-G30 -> 333333.38 | J30: =B30-B29 -> 30
A31: 22 | B31: =EOMONTH($E$5,22) -> 670 | C31: =IF(22=$B$5,F30+D31,$H$4) -> 23619.19 | D31: =ROUND(F30*$B$4/100*J31/365,2) -> 1172.17 | E31: =C31-D31 -> 22447.02 | F31: =F30-E31 -> 322585.56 | G31: =ROUND(($B$3+$E$5)/$E$3,2) -> 22222.22 | H31: =H30-G31 -> 311111.16 | J31: =B31-B30 -> 31
A32: 23 | B32: =EOMONTH($E$5,23) -> 700 | C32: =IF(23=$B$5,F31+D32,$H$4) -> 23619.19 | D32: =ROUND(F31*$B$4/100*J32/365,2) -> 1060.56 | E32: =C32-D32 -> 22558.63 | F32: =F31-E32 -> 300026.93 | G32: =ROUND(($B$3+$E$5)/$E$3,2) -> 22222.22 | H32: =H31-G32 -> 288888.94 | J32: =B32-B31 -> 30
A33: 24 | B33: =EOMONTH($E$5,24) -> 731 | C33: =IF(24=$B$5,F32+D33,$H$4) -> 23619.19 | D33: =ROUND(F32*$B$4/100*J33/365,2) -> 1019.27 | E33: =C33-D33 -> 22599.92 | F33: =F32-E33 -> 277427.01 | G33: =ROUND(($B$3+$E$5)/$E$3,2) -> 22222.22 | H33: =H32-G33 -> 266666.72 | J33: =B33-B32 -> 31
A34: 25 | B34: =EOMONTH($E$5,25) -> 762 | C34: =IF(25=$B$5,F33+D34,$H$4) -> 23619.19 | D34: =ROUND(F33*$B$4/100*J34/365,2) -> 942.49 | E34: =C34-D34 -> 22676.7 | F34: =F33-E34 -> 254750.31 | G34: =ROUND(($B$3+$E$5)/$E$3,2) -> 22222.22 | H34: =H33-G34 -> 244444.5 | J34: =B34-B33 -> 31
A35: 26 | B35: =EOMONTH($E$5,26) -> 790 | C35: =IF(26=$B$5,F34+D35,$H$4) -> 23619.19 | D35: =ROUND(F34*$B$4/100*J35/365,2) -> 781.7 | E35: =C35-D35 -> 22837.49 | F35: =F34-E35 -> 231912.82 | G35: =ROUND(($B$3+$E$5)/$E$3,2) -> 22222.22 | H35: =H34-G35 -> 222222.28 | J35: =B35-B34 -> 28
A36: 27 | B36: =EOMONTH($E$5,27) -> 821 | C36: =IF(27=$B$5,F35+D36,$H$4) -> 23619.19 | D36: =ROUND(F35*$B$4/100*J36/365,2) -> 787.87 | E36: =C36-D36 -> 22831.32 | F36: =F35-E36 -> 209081.5 | G36: =ROUND(($B$3+$E$5)/$E$3,2) -> 22222.22 | H36: =H35-G36 -> 200000.06 | J36: =B36-B35 -> 31
A37: 28 | B37: =EOMONTH($E$5,28) -> 851 | C37: =IF(28=$B$5,F36+D37,$H$4) -> 23619.19 | D37: =ROUND(F36*$B$4/100*J37/365,2) -> 687.39 | E37: =C37-D37 -> 22931.8 | F37: =F36-E37 -> 186149.7 | G37: =ROUND(($B$3+$E$5)/$E$3,2) -> 22222.22 | H37: =H36-G37 -> 177777.84 | J37: =B37-B36 -> 30
A38: 29 | B38: =EOMONTH($E$5,29) -> 882 | C38: =IF(29=$B$5,F37+D38,$H$4) -> 23619.19 | D38: =ROUND(F37*$B$4/100*J38/365,2) -> 632.4 | E38: =C38-D38 -> 22986.79 | F38: =F37-E38 -> 163162.91 | G38: =ROUND(($B$3+$E$5)/$E$3,2) -> 22222.22 | H38: =H37-G38 -> 155555.62 | J38: =B38-B37 -> 31
A39: 30 | B39: =EOMONTH($E$5,30) -> 912 | C39: =IF(30=$B$5,F38+D39,$H$4) -> 23619.19 | D39: =ROUND(F38*$B$4/100*J39/365,2) -> 536.43 | E39: =C39-D39 -> 23082.76 | F39: =F38-E39 -> 140080.15 | G39: =ROUND(($B$3+$E$5)/$E$3,2) -> 22222.22 | H39: =H38-G39 -> 133333.4 | J39: =B39-B38 -> 30
A40: 31 | B40: =EOMONTH($E$5,31) -> 943 | C40: =IF(31=$B$5,F39+D40,$H$4) -> 23619.19 | D40: =ROUND(F39*$B$4/100*J40/365,2) -> 475.89 | E40: =C40-D40 -> 23143.3 | F40: =F39-E40 -> 116936.85 | G40: =ROUND(($B$3+$E$5)/$E$3,2) -> 22222.22 | H40: =H39-G40 -> 111111.18 | J40: =B40-B39 -> 31
A41: 32 | B41: =EOMONTH($E$5,32) -> 974 | C41: =IF(32=$B$5,F40+D41,$H$4) -> 23619.19 | D41: =ROUND(F40*$B$4/100*J41/365,2) -> 397.26 | E41: =C41-D41 -> 23221.93 | F41: =F40-E41 -> 93714.92 | G41: =ROUND(($B$3+$E$5)/$E$3,2) -> 22222.22 | H41: =H40-G41 -> 88888.96 | J41: =B41-B40 -> 31
A42: 33 | B42: =EOMONTH($E$5,33) -> 1004 | C42: =IF(33=$B$5,F41+D42,$H$4) -> 23619.19 | D42: =ROUND(F41*$B$4/100*J42/365,2) -> 308.1 | E42: =C42-D42 -> 23311.09 | F42: =F41-E42 -> 70403.83 | G42: =ROUND(($B$3+$E$5)/$E$3,2) -> 22222.22 | H42: =H41-G42 -> 66666.74 | J42: =B42-B41 -> 30
A43: 34 | B43: =EOMONTH($E$5,34) -> 1035 | C43: =IF(34=$B$5,F42+D43,$H$4) -> 23619.19 | D43: =ROUND(F42*$B$4/100*J43/365,2) -> 239.18 | E43: =C43-D43 -> 23380.01 | F43: =F42-E43 -> 47023.82 | G43: =ROUND(($B$3+$E$5)/$E$3,2) -> 22222.22 | H43: =H42-G43 -> 44444.52 | J43: =B43-B42 -> 31
A44: 35 | B44: =EOMONTH($E$5,35) -> 1065 | C44: =IF(35=$B$5,F43+D44,$H$4) -> 23619.19 | D44: =ROUND(F43*$B$4/100*J44/365,2) -> 154.6 | E44: =C44-D44 -> 23464.59 | F44: =F43-E44 -> 23559.23 | G44: =ROUND(($B$3+$E$5)/$E$3,2) -> 22222.22 | H44: =H43-G44 -> 22222.3 | J44: =B44-B43 -> 30
...

Sheet Leasing Maturity
A1: LEASE-DEMO-001 — Maturity Profile
A3: GL Classification — Aging | D3: ที่มา / วิธีคิด (อ้างอิงแท็บ schedule)
A4: Current Portion (≤ 12 เดือน) | C4: =SUM(Leasing!E10:E21) -> 256025.59 | D4: รวม "เงินต้นตัดต่องวด" (PRINCIPAL (ตัดต้น) สีเขียว) งวดที่ 1–12
A5: Non-current (> 12 เดือน) | C5: =SUM(Leasing!E22:E45) -> 543974.41 | D5: รวม PRINCIPAL (สีเขียว) งวดที่ 13–36 (หรือ Total ลบ Current)
A6: Total Principal | C6: =Leasing!$B$3 -> 800000 | D6: เงินต้นตั้งต้น — ช่อง PRINCIPAL / ROU
A8: ภาระผูกพันในอนาคต (เงินต้น + ดอกเบี้ย ยังไม่คิดลด) | D8: ที่มา / วิธีคิด
A9: ภายใน 1 ปี | C9: =SUMPRODUCT((Leasing!A10:A45<=12)*(Leasing!E10:E45+Leasing!D10:D45)) -> 283430.28 | D9: รวม PRINCIPAL (สีเขียว) + INTEREST (สีส้ม) งวดที่ 1–12
A10: 1 - 5 ปี | C10: =SUMPRODUCT((Leasing!A10:A45>12)*(Leasing!A10:A45<=60)*(Leasing!E10:E45+Leasing!D10:D45)) -> 566880.64 | D10: รวม PRINCIPAL + INTEREST งวดที่ 13–60
A11: มากกว่า 5 ปี | C11: =SUMPRODUCT((Leasing!A10:A45>60)*(Leasing!E10:E45+Leasing!D10:D45)) -> 0 | D11: งวดเกิน 60 เดือน — มี 36 งวด จึง = 0
A12: Total Future Cash Flow | C12: =Leasing!$B$3+Leasing!$H$5 -> 850310.92 | D12: ช่อง PRINCIPAL + ดอกเบี้ยรวมทั้งสัญญา (INTEREST สีส้มรวมทุกงวด)
A14: Lease Classification: Finance (net/ROU · TFRS16)

Sheet Lease Other
A1: LSO-DEMO-001 — Lease Other (เช่าอาคาร · net/ROU)
A3: PRINCIPAL / ROU (NPV) | B3: 900000 | D3: ROU LIFE (เดือน) | E3: 60
A4: RATE / YEAR (%) | B4: 3.5 | D4: PAYMENT START DATE | E4: 46295 | G4: INSTALLMENT = PMT (แก้เป็นค่าระบบได้) | H4: =ROUND(-PMT($B$4/100/12,$B$5,$B$3),2) -> 16372.57
A5: TERM (MONTHS) | B5: 60 | D5: UPFRONT (จ่ายล่วงหน้า) | E5: 50000 | G5: ดอกเบี้ยรวมทั้งสัญญา | H5: =SUM(D10:D69) -> 83290.65
A9: # | B9: PAYMENT DATE | C9: INSTALLMENT | D9: INTEREST | E9: PRINCIPAL (ตัดต้น) | F9: LIABILITY BALANCE | G9: DEPRECIATION | H9: ROU BALANCE
A10: 1 | B10: =EOMONTH($E$5,1) -> 50040 | C10: =IF(1=$B$5,F9+D10,$H$4) -> 16372.57 | D10: =ROUND($B$3*$B$4/100*J10/365,2) -> 3452.05 | E10: =C10-D10 -> 12920.52 | F10: =$B$3-E10 -> 887079.48 | G10: =ROUND(($B$3+$E$5)/$E$3,2) -> 15833.33 | H10: =($B$3+$E$5)-G10 -> 934166.67 | J10: =B10-$E$5 -> 40
A11: 2 | B11: =EOMONTH($E$5,2) -> 50071 | C11: =IF(2=$B$5,F10+D11,$H$4) -> 16372.57 | D11: =ROUND(F10*$B$4/100*J11/365,2) -> 2636.93 | E11: =C11-D11 -> 13735.64 | F11: =F10-E11 -> 873343.84 | G11: =ROUND(($B$3+$E$5)/$E$3,2) -> 15833.33 | H11: =H10-G11 -> 918333.34 | J11: =B11-B10 -> 31
A12: 3 | B12: =EOMONTH($E$5,3) -> 50099 | C12: =IF(3=$B$5,F11+D12,$H$4) -> 16372.57 | D12: =ROUND(F11*$B$4/100*J12/365,2) -> 2344.87 | E12: =C12-D12 -> 14027.7 | F12: =F11-E12 -> 859316.14 | G12: =ROUND(($B$3+$E$5)/$E$3,2) -> 15833.33 | H12: =H11-G12 -> 902500.01 | J12: =B12-B11 -> 28
A13: 4 | B13: =EOMONTH($E$5,4) -> 50130 | C13: =IF(4=$B$5,F12+D13,$H$4) -> 16372.57 | D13: =ROUND(F12*$B$4/100*J13/365,2) -> 2554.41 | E13: =C13-D13 -> 13818.16 | F13: =F12-E13 -> 845497.98 | G13: =ROUND(($B$3+$E$5)/$E$3,2) -> 15833.33 | H13: =H12-G13 -> 886666.68 | J13: =B13-B12 -> 31
A14: 5 | B14: =EOMONTH($E$5,5) -> 50160 | C14: =IF(5=$B$5,F13+D14,$H$4) -> 16372.57 | D14: =ROUND(F13*$B$4/100*J14/365,2) -> 2432.25 | E14: =C14-D14 -> 13940.32 | F14: =F13-E14 -> 831557.66 | G14: =ROUND(($B$3+$E$5)/$E$3,2) -> 15833.33 | H14: =H13-G14 -> 870833.35 | J14: =B14-B13 -> 30
A15: 6 | B15: =EOMONTH($E$5,6) -> 50191 | C15: =IF(6=$B$5,F14+D15,$H$4) -> 16372.57 | D15: =ROUND(F14*$B$4/100*J15/365,2) -> 2471.89 | E15: =C15-D15 -> 13900.68 | F15: =F14-E15 -> 817656.98 | G15: =ROUND(($B$3+$E$5)/$E$3,2) -> 15833.33 | H15: =H14-G15 -> 855000.02 | J15: =B15-B14 -> 31
A16: 7 | B16: =EOMONTH($E$5,7) -> 50221 | C16: =IF(7=$B$5,F15+D16,$H$4) -> 16372.57 | D16: =ROUND(F15*$B$4/100*J16/365,2) -> 2352.16 | E16: =C16-D16 -> 14020.41 | F16: =F15-E16 -> 803636.57 | G16: =ROUND(($B$3+$E$5)/$E$3,2) -> 15833.33 | H16: =H15-G16 -> 839166.69 | J16: =B16-B15 -> 30
A17: 8 | B17: =EOMONTH($E$5,8) -> 50252 | C17: =IF(8=$B$5,F16+D17,$H$4) -> 16372.57 | D17: =ROUND(F16*$B$4/100*J17/365,2) -> 2388.89 | E17: =C17-D17 -> 13983.68 | F17: =F16-E17 -> 789652.89 | G17: =ROUND(($B$3+$E$5)/$E$3,2) -> 15833.33 | H17: =H16-G17 -> 823333.36 | J17: =B17-B16 -> 31
A18: 9 | B18: =EOMONTH($E$5,9) -> 50283 | C18: =IF(9=$B$5,F17+D18,$H$4) -> 16372.57 | D18: =ROUND(F17*$B$4/100*J18/365,2) -> 2347.32 | E18: =C18-D18 -> 14025.25 | F18: =F17-E18 -> 775627.64 | G18: =ROUND(($B$3+$E$5)/$E$3,2) -> 15833.33 | H18: =H17-G18 -> 807500.03 | J18: =B18-B17 -> 31
A19: 10 | B19: =EOMONTH($E$5,10) -> 50313 | C19: =IF(10=$B$5,F18+D19,$H$4) -> 16372.57 | D19: =ROUND(F18*$B$4/100*J19/365,2) -> 2231.26 | E19: =C19-D19 -> 14141.31 | F19: =F18-E19 -> 761486.33 | G19: =ROUND(($B$3+$E$5)/$E$3,2) -> 15833.33 | H19: =H18-G19 -> 791666.7 | J19: =B19-B18 -> 30
A20: 11 | B20: =EOMONTH($E$5,11) -> 50344 | C20: =IF(11=$B$5,F19+D20,$H$4) -> 16372.57 | D20: =ROUND(F19*$B$4/100*J20/365,2) -> 2263.6 | E20: =C20-D20 -> 14108.97 | F20: =F19-E20 -> 747377.36 | G20: =ROUND(($B$3+$E$5)/$E$3,2) -> 15833.33 | H20: =H19-G20 -> 775833.37 | J20: =B20-B19 -> 31
A21: 12 | B21: =EOMONTH($E$5,12) -> 50374 | C21: =IF(12=$B$5,F20+D21,$H$4) -> 16372.57 | D21: =ROUND(F20*$B$4/100*J21/365,2) -> 2149.99 | E21: =C21-D21 -> 14222.58 | F21: =F20-E21 -> 733154.78 | G21: =ROUND(($B$3+$E$5)/$E$3,2) -> 15833.33 | H21: =H20-G21 -> 760000.04 | J21: =B21-B20 -> 30
A22: 13 | B22: =EOMONTH($E$5,13) -> 50405 | C22: =IF(13=$B$5,F21+D22,$H$4) -> 16372.57 | D22: =ROUND(F21*$B$4/100*J22/365,2) -> 2179.38 | E22: =C22-D22 -> 14193.19 | F22: =F21-E22 -> 718961.59 | G22: =ROUND(($B$3+$E$5)/$E$3,2) -> 15833.33 | H22: =H21-G22 -> 744166.71 | J22: =B22-B21 -> 31
A23: 14 | B23: =EOMONTH($E$5,14) -> 50436 | C23: =IF(14=$B$5,F22+D23,$H$4) -> 16372.57 | D23: =ROUND(F22*$B$4/100*J23/365,2) -> 2137.19 | E23: =C23-D23 -> 14235.38 | F23: =F22-E23 -> 704726.21 | G23: =ROUND(($B$3+$E$5)/$E$3,2) -> 15833.33 | H23: =H22-G23 -> 728333.38 | J23: =B23-B22 -> 31
A24: 15 | B24: =EOMONTH($E$5,15) -> 50464 | C24: =IF(15=$B$5,F23+D24,$H$4) -> 16372.57 | D24: =ROUND(F23*$B$4/100*J24/365,2) -> 1892.14 | E24: =C24-D24 -> 14480.43 | F24: =F23-E24 -> 690245.78 | G24: =ROUND(($B$3+$E$5)/$E$3,2) -> 15833.33 | H24: =H23-G24 -> 712500.05 | J24: =B24-B23 -> 28
A25: 16 | B25: =EOMONTH($E$5,16) -> 50495 | C25: =IF(16=$B$5,F24+D25,$H$4) -> 16372.57 | D25: =ROUND(F24*$B$4/100*J25/365,2) -> 2051.83 | E25: =C25-D25 -> 14320.74 | F25: =F24-E25 -> 675925.04 | G25: =ROUND(($B$3+$E$5)/$E$3,2) -> 15833.33 | H25: =H24-G25 -> 696666.72 | J25: =B25-B24 -> 31
A26: 17 | B26: =EOMONTH($E$5,17) -> 50525 | C26: =IF(17=$B$5,F25+D26,$H$4) -> 16372.57 | D26: =ROUND(F25*$B$4/100*J26/365,2) -> 1944.44 | E26: =C26-D26 -> 14428.13 | F26: =F25-E26 -> 661496.91 | G26: =ROUND(($B$3+$E$5)/$E$3,2) -> 15833.33 | H26: =H25-G26 -> 680833.39 | J26: =B26-B25 -> 30
A27: 18 | B27: =EOMONTH($E$5,18) -> 50556 | C27: =IF(18=$B$5,F26+D27,$H$4) -> 16372.57 | D27: =ROUND(F26*$B$4/100*J27/365,2) -> 1966.37 | E27: =C27-D27 -> 14406.2 | F27: =F26-E27 -> 647090.71 | G27: =ROUND(($B$3+$E$5)/$E$3,2) -> 15833.33 | H27: =H26-G27 -> 665000.06 | J27: =B27-B26 -> 31
A28: 19 | B28: =EOMONTH($E$5,19) -> 50586 | C28: =IF(19=$B$5,F27+D28,$H$4) -> 16372.57 | D28: =ROUND(F27*$B$4/100*J28/365,2) -> 1861.49 | E28: =C28-D28 -> 14511.08 | F28: =F27-E28 -> 632579.63 | G28: =ROUND(($B$3+$E$5)/$E$3,2) -> 15833.33 | H28: =H27-G28 -> 649166.73 | J28: =B28-B27 -> 30
A29: 20 | B29: =EOMONTH($E$5,20) -> 50617 | C29: =IF(20=$B$5,F28+D29,$H$4) -> 16372.57 | D29: =ROUND(F28*$B$4/100*J29/365,2) -> 1880.41 | E29: =C29-D29 -> 14492.16 | F29: =F28-E29 -> 618087.47 | G29: =ROUND(($B$3+$E$5)/$E$3,2) -> 15833.33 | H29: =H28-G29 -> 633333.4 | J29: =B29-B28 -> 31
A30: 21 | B30: =EOMONTH($E$5,21) -> 50648 | C30: =IF(21=$B$5,F29+D30,$H$4) -> 16372.57 | D30: =ROUND(F29*$B$4/100*J30/365,2) -> 1837.33 | E30: =C30-D30 -> 14535.24 | F30: =F29-E30 -> 603552.23 | G30: =ROUND(($B$3+$E$5)/$E$3,2) -> 15833.33 | H30: =H29-G30 -> 617500.07 | J30: =B30-B29 -> 31
A31: 22 | B31: =EOMONTH($E$5,22) -> 50678 | C31: =IF(22=$B$5,F30+D31,$H$4) -> 16372.57 | D31: =ROUND(F30*$B$4/100*J31/365,2) -> 1736.25 | E31: =C31-D31 -> 14636.32 | F31: =F30-E31 -> 588915.91 | G31: =ROUND(($B$3+$E$5)/$E$3,2) -> 15833.33 | H31: =H30-G31 -> 601666.74 | J31: =B31-B30 -> 30
A32: 23 | B32: =EOMONTH($E$5,23) -> 50709 | C32: =IF(23=$B$5,F31+D32,$H$4) -> 16372.57 | D32: =ROUND(F31*$B$4/100*J32/365,2) -> 1750.61 | E32: =C32-D32 -> 14621.96 | F32: =F31-E32 -> 574293.95 | G32: =ROUND(($B$3+$E$5)/$E$3,2) -> 15833.33 | H32: =H31-G32 -> 585833.41 | J32: =B32-B31 -> 31
A33: 24 | B33: =EOMONTH($E$5,24) -> 50739 | C33: =IF(24=$B$5,F32+D33,$H$4) -> 16372.57 | D33: =ROUND(F32*$B$4/100*J33/365,2) -> 1652.08 | E33: =C33-D33 -> 14720.49 | F33: =F32-E33 -> 559573.46 | G33: =ROUND(($B$3+$E$5)/$E$3,2) -> 15833.33 | H33: =H32-G33 -> 570000.08 | J33: =B33-B32 -> 30
A34: 25 | B34: =EOMONTH($E$5,25) -> 50770 | C34: =IF(25=$B$5,F33+D34,$H$4) -> 16372.57 | D34: =ROUND(F33*$B$4/100*J34/365,2) -> 1663.39 | E34: =C34-D34 -> 14709.18 | F34: =F33-E34 -> 544864.28 | G34: =ROUND(($B$3+$E$5)/$E$3,2) -> 15833.33 | H34: =H33-G34 -> 554166.75 | J34: =B34-B33 -> 31
A35: 26 | B35: =EOMONTH($E$5,26) -> 50801 | C35: =IF(26=$B$5,F34+D35,$H$4) -> 16372.57 | D35: =ROUND(F34*$B$4/100*J35/365,2) -> 1619.67 | E35: =C35-D35 -> 14752.9 | F35: =F34-E35 -> 530111.38 | G35: =ROUND(($B$3+$E$5)/$E$3,2) -> 15833.33 | H35: =H34-G35 -> 538333.42 | J35: =B35-B34 -> 31
A36: 27 | B36: =EOMONTH($E$5,27) -> 50829 | C36: =IF(27=$B$5,F35+D36,$H$4) -> 16372.57 | D36: =ROUND(F35*$B$4/100*J36/365,2) -> 1423.31 | E36: =C36-D36 -> 14949.26 | F36: =F35-E36 -> 515162.12 | G36: =ROUND(($B$3+$E$5)/$E$3,2) -> 15833.33 | H36: =H35-G36 -> 522500.09 | J36: =B36-B35 -> 28
A37: 28 | B37: =EOMONTH($E$5,28) -> 50860 | C37: =IF(28=$B$5,F36+D37,$H$4) -> 16372.57 | D37: =ROUND(F36*$B$4/100*J37/365,2) -> 1531.37 | E37: =C37-D37 -> 14841.2 | F37: =F36-E37 -> 500320.92 | G37: =ROUND(($B$3+$E$5)/$E$3,2) -> 15833.33 | H37: =H36-G37 -> 506666.76 | J37: =B37-B36 -> 31
A38: 29 | B38: =EOMONTH($E$5,29) -> 50890 | C38: =IF(29=$B$5,F37+D38,$H$4) -> 16372.57 | D38: =ROUND(F37*$B$4/100*J38/365,2) -> 1439.28 | E38: =C38-D38 -> 14933.29 | F38: =F37-E38 -> 485387.63 | G38: =ROUND(($B$3+$E$5)/$E$3,2) -> 15833.33 | H38: =H37-G38 -> 490833.43 | J38: =B38-B37 -> 30
A39: 30 | B39: =EOMONTH($E$5,30) -> 50921 | C39: =IF(30=$B$5,F38+D39,$H$4) -> 16372.57 | D39: =ROUND(F38*$B$4/100*J39/365,2) -> 1442.86 | E39: =C39-D39 -> 14929.71 | F39: =F38-E39 -> 470457.92 | G39: =ROUND(($B$3+$E$5)/$E$3,2) -> 15833.33 | H39: =H38-G39 -> 475000.1 | J39: =B39-B38 -> 31
A40: 31 | B40: =EOMONTH($E$5,31) -> 50951 | C40: =IF(31=$B$5,F39+D40,$H$4) -> 16372.57 | D40: =ROUND(F39*$B$4/100*J40/365,2) -> 1353.37 | E40: =C40-D40 -> 15019.2 | F40: =F39-E40 -> 455438.72 | G40: =ROUND(($B$3+$E$5)/$E$3,2) -> 15833.33 | H40: =H39-G40 -> 459166.77 | J40: =B40-B39 -> 30
A41: 32 | B41: =EOMONTH($E$5,32) -> 50982 | C41: =IF(32=$B$5,F40+D41,$H$4) -> 16372.57 | D41: =ROUND(F40*$B$4/100*J41/365,2) -> 1353.84 | E41: =C41-D41 -> 15018.73 | F41: =F40-E41 -> 440419.99 | G41: =ROUND(($B$3+$E$5)/$E$3,2) -> 15833.33 | H41: =H40-G41 -> 443333.44 | J41: =B41-B40 -> 31
A42: 33 | B42: =EOMONTH($E$5,33) -> 51013 | C42: =IF(33=$B$5,F41+D42,$H$4) -> 16372.57 | D42: =ROUND(F41*$B$4/100*J42/365,2) -> 1309.19 | E42: =C42-D42 -> 15063.38 | F42: =F41-E42 -> 425356.61 | G42: =ROUND(($B$3+$E$5)/$E$3,2) -> 15833.33 | H42: =H41-G42 -> 427500.11 | J42: =B42-B41 -> 31
A43: 34 | B43: =EOMONTH($E$5,34) -> 51043 | C43: =IF(34=$B$5,F42+D43,$H$4) -> 16372.57 | D43: =ROUND(F42*$B$4/100*J43/365,2) -> 1223.63 | E43: =C43-D43 -> 15148.94 | F43: =F42-E43 -> 410207.67 | G43: =ROUND(($B$3+$E$5)/$E$3,2) -> 15833.33 | H43: =H42-G43 -> 411666.78 | J43: =B43-B42 -> 30
A44: 35 | B44: =EOMONTH($E$5,35) -> 51074 | C44: =IF(35=$B$5,F43+D44,$H$4) -> 16372.57 | D44: =ROUND(F43*$B$4/100*J44/365,2) -> 1219.38 | E44: =C44-D44 -> 15153.19 | F44: =F43-E44 -> 395054.48 | G44: =ROUND(($B$3+$E$5)/$E$3,2) -> 15833.33 | H44: =H43-G44 -> 395833.45 | J44: =B44-B43 -> 31
...

Sheet Lease Other Maturity
A1: LSO-DEMO-001 — Maturity Profile
A3: GL Classification — Aging | D3: ที่มา / วิธีคิด (อ้างอิงแท็บ schedule)
A4: Current Portion (≤ 12 เดือน) | C4: =SUM('Lease Other'!E10:E21) -> 166845.22 | D4: รวม "เงินต้นตัดต่องวด" (PRINCIPAL (ตัดต้น) สีเขียว) งวดที่ 1–12
A5: Non-current (> 12 เดือน) | C5: =SUM('Lease Other'!E22:E69) -> 733154.78 | D5: รวม PRINCIPAL (สีเขียว) งวดที่ 13–60 (หรือ Total ลบ Current)
A6: Total Principal | C6: ='Lease Other'!$B$3 -> 900000 | D6: เงินต้นตั้งต้น — ช่อง PRINCIPAL / ROU
A8: ภาระผูกพันในอนาคต (เงินต้น + ดอกเบี้ย ยังไม่คิดลด) | D8: ที่มา / วิธีคิด
A9: ภายใน 1 ปี | C9: =SUMPRODUCT(('Lease Other'!A10:A69<=12)*('Lease Other'!E10:E69+'Lease Other'!D10:D69)) -> 196470.84 | D9: รวม PRINCIPAL (สีเขียว) + INTEREST (สีส้ม) งวดที่ 1–12
A10: 1 - 5 ปี | C10: =SUMPRODUCT(('Lease Other'!A10:A69>12)*('Lease Other'!A10:A69<=60)*('Lease Other'!E10:E69+'Lease Other'!D10:D69)) -> 786819.81 | D10: รวม PRINCIPAL + INTEREST งวดที่ 13–60
A11: มากกว่า 5 ปี | C11: =SUMPRODUCT(('Lease Other'!A10:A69>60)*('Lease Other'!E10:E69+'Lease Other'!D10:D69)) -> 0 | D11: งวดเกิน 60 เดือน — มี 60 งวด จึง = 0
A12: Total Future Cash Flow | C12: ='Lease Other'!$B$3+'Lease Other'!$H$5 -> 983290.65 | D12: ช่อง PRINCIPAL + ดอกเบี้ยรวมทั้งสัญญา (INTEREST สีส้มรวมทุกงวด)
A14: Lease Classification: Finance (net/ROU · TFRS16)

Sheet FP Schedule
A1: FP-DEMO-001 — Schedule Calculate (label ตรงระบบ)
A3: PRINCIPAL (รวมรถในสต๊อก) | B3: 5000000 | D3: Curtailment | E3: Day | F3: % | G3: Due Date
A4: RATE / YEAR (%) | B4: 5 | D4: Tier 1 | E4: 90 | F4: 10 | G4: =$B$5+E4 -> 46356
A5: TRANSACTION DATE | B5: 46266 | D5: Tier 2 | E5: 180 | F5: 10 | G5: =$B$5+E5 -> 46446
A6: MATURITY DATE | B6: 46386 | D6: Tier 3 | E6: 270 | F6: 80 | G6: =$B$5+E6 -> 46536
A9: Period | B9: Start Date | C9: End Date | D9: Day | E9: Due Curtailment | F9: Curtailment | G9: Interest Rate | H9: Interest | I9: Principal Balance | J9: Interest Balance
A10: 0 | B10: =$B$5 -> 46266 | C10: =$B$5 -> 46266 | D10: 0 | G10: =$B$4 -> 5 | H10: 0 | I10: =$B$3 -> 5000000 | J10: =ROUND($B$3*$B$4/100*($B$6-$B$5)/365,2) -> 82191.78
A11: =IF(C10>=$B$6,"",1) -> 1 | B11: =IF(C10>=$B$6,"",C10) -> 46266 | C11: =IF(C10>=$B$6,"",MIN(EOMONTH($B$5,0),$B$6)) -> 46295 | D11: =IF(C10>=$B$6,"",C11-B11) -> 29 | E11: =IF(C10>=$B$6,"",IF(SUMPRODUCT(($G$4:$G$6>B11)*($G$4:$G$6<=C11)*$F$4:$F$6)=0,"",SUMPRODUCT(($G$4:$G$6>B11)*($G$4:$G$6<=C11)*$F$4:$F$6)&"%")) | F11: =IF(C10>=$B$6,"",ROUND($B$3*SUMPRODUCT(($G$4:$G$6>B11)*($G$4:$G$6<=C11)*$F$4:$F$6)/100,2)) -> 0 | G11: =IF(C10>=$B$6,"",$B$4) -> 5 | H11: =IF(C10>=$B$6,"",ROUND(I10*$B$4/100*D11/365,2)) -> 19863.01 | I11: =IF(C10>=$B$6,"",I10-F11) -> 5000000 | J11: =IF(C10>=$B$6,"",MAX(0,J10-H11)) -> 62328.77
A12: =IF(C11>=$B$6,"",2) -> 2 | B12: =IF(C11>=$B$6,"",C11) -> 46295 | C12: =IF(C11>=$B$6,"",MIN(EOMONTH($B$5,1),$B$6)) -> 46326 | D12: =IF(C11>=$B$6,"",C12-B12) -> 31 | E12: =IF(C11>=$B$6,"",IF(SUMPRODUCT(($G$4:$G$6>B12)*($G$4:$G$6<=C12)*$F$4:$F$6)=0,"",SUMPRODUCT(($G$4:$G$6>B12)*($G$4:$G$6<=C12)*$F$4:$F$6)&"%")) | F12: =IF(C11>=$B$6,"",ROUND($B$3*SUMPRODUCT(($G$4:$G$6>B12)*($G$4:$G$6<=C12)*$F$4:$F$6)/100,2)) -> 0 | G12: =IF(C11>=$B$6,"",$B$4) -> 5 | H12: =IF(C11>=$B$6,"",ROUND(I11*$B$4/100*D12/365,2)) -> 21232.88 | I12: =IF(C11>=$B$6,"",I11-F12) -> 5000000 | J12: =IF(C11>=$B$6,"",MAX(0,J11-H12)) -> 41095.89
A13: =IF(C12>=$B$6,"",3) -> 3 | B13: =IF(C12>=$B$6,"",C12) -> 46326 | C13: =IF(C12>=$B$6,"",MIN(EOMONTH($B$5,2),$B$6)) -> 46356 | D13: =IF(C12>=$B$6,"",C13-B13) -> 30 | E13: =IF(C12>=$B$6,"",IF(SUMPRODUCT(($G$4:$G$6>B13)*($G$4:$G$6<=C13)*$F$4:$F$6)=0,"",SUMPRODUCT(($G$4:$G$6>B13)*($G$4:$G$6<=C13)*$F$4:$F$6)&"%")) -> 10% | F13: =IF(C12>=$B$6,"",ROUND($B$3*SUMPRODUCT(($G$4:$G$6>B13)*($G$4:$G$6<=C13)*$F$4:$F$6)/100,2)) -> 500000 | G13: =IF(C12>=$B$6,"",$B$4) -> 5 | H13: =IF(C12>=$B$6,"",ROUND(I12*$B$4/100*D13/365,2)) -> 20547.95 | I13: =IF(C12>=$B$6,"",I12-F13) -> 4500000 | J13: =IF(C12>=$B$6,"",MAX(0,J12-H13)) -> 20547.94
A14: =IF(C13>=$B$6,"",4) -> 4 | B14: =IF(C13>=$B$6,"",C13) -> 46356 | C14: =IF(C13>=$B$6,"",MIN(EOMONTH($B$5,3),$B$6)) -> 46386 | D14: =IF(C13>=$B$6,"",C14-B14) -> 30 | E14: =IF(C13>=$B$6,"",IF(SUMPRODUCT(($G$4:$G$6>B14)*($G$4:$G$6<=C14)*$F$4:$F$6)=0,"",SUMPRODUCT(($G$4:$G$6>B14)*($G$4:$G$6<=C14)*$F$4:$F$6)&"%")) | F14: =IF(C13>=$B$6,"",ROUND($B$3*SUMPRODUCT(($G$4:$G$6>B14)*($G$4:$G$6<=C14)*$F$4:$F$6)/100,2)) -> 0 | G14: =IF(C13>=$B$6,"",$B$4) -> 5 | H14: =IF(C13>=$B$6,"",ROUND(I13*$B$4/100*D14/365,2)) -> 18493.15 | I14: =IF(C13>=$B$6,"",I13-F14) -> 4500000 | J14: =IF(C13>=$B$6,"",MAX(0,J13-H14)) -> 2054.79
A15: =IF(C14>=$B$6,"",5) | B15: =IF(C14>=$B$6,"",C14) | C15: =IF(C14>=$B$6,"",MIN(EOMONTH($B$5,4),$B$6)) | D15: =IF(C14>=$B$6,"",C15-B15) | E15: =IF(C14>=$B$6,"",IF(SUMPRODUCT(($G$4:$G$6>B15)*($G$4:$G$6<=C15)*$F$4:$F$6)=0,"",SUMPRODUCT(($G$4:$G$6>B15)*($G$4:$G$6<=C15)*$F$4:$F$6)&"%")) | F15: =IF(C14>=$B$6,"",ROUND($B$3*SUMPRODUCT(($G$4:$G$6>B15)*($G$4:$G$6<=C15)*$F$4:$F$6)/100,2)) | G15: =IF(C14>=$B$6,"",$B$4) | H15: =IF(C14>=$B$6,"",ROUND(I14*$B$4/100*D15/365,2)) | I15: =IF(C14>=$B$6,"",I14-F15) | J15: =IF(C14>=$B$6,"",MAX(0,J14-H15))
A16: =IF(C15>=$B$6,"",6) | B16: =IF(C15>=$B$6,"",C15) | C16: =IF(C15>=$B$6,"",MIN(EOMONTH($B$5,5),$B$6)) | D16: =IF(C15>=$B$6,"",C16-B16) | E16: =IF(C15>=$B$6,"",IF(SUMPRODUCT(($G$4:$G$6>B16)*($G$4:$G$6<=C16)*$F$4:$F$6)=0,"",SUMPRODUCT(($G$4:$G$6>B16)*($G$4:$G$6<=C16)*$F$4:$F$6)&"%")) | F16: =IF(C15>=$B$6,"",ROUND($B$3*SUMPRODUCT(($G$4:$G$6>B16)*($G$4:$G$6<=C16)*$F$4:$F$6)/100,2)) | G16: =IF(C15>=$B$6,"",$B$4) | H16: =IF(C15>=$B$6,"",ROUND(I15*$B$4/100*D16/365,2)) | I16: =IF(C15>=$B$6,"",I15-F16) | J16: =IF(C15>=$B$6,"",MAX(0,J15-H16))
A17: =IF(C16>=$B$6,"",7) | B17: =IF(C16>=$B$6,"",C16) | C17: =IF(C16>=$B$6,"",MIN(EOMONTH($B$5,6),$B$6)) | D17: =IF(C16>=$B$6,"",C17-B17) | E17: =IF(C16>=$B$6,"",IF(SUMPRODUCT(($G$4:$G$6>B17)*($G$4:$G$6<=C17)*$F$4:$F$6)=0,"",SUMPRODUCT(($G$4:$G$6>B17)*($G$4:$G$6<=C17)*$F$4:$F$6)&"%")) | F17: =IF(C16>=$B$6,"",ROUND($B$3*SUMPRODUCT(($G$4:$G$6>B17)*($G$4:$G$6<=C17)*$F$4:$F$6)/100,2)) | G17: =IF(C16>=$B$6,"",$B$4) | H17: =IF(C16>=$B$6,"",ROUND(I16*$B$4/100*D17/365,2)) | I17: =IF(C16>=$B$6,"",I16-F17) | J17: =IF(C16>=$B$6,"",MAX(0,J16-H17))
A18: =IF(C17>=$B$6,"",8) | B18: =IF(C17>=$B$6,"",C17) | C18: =IF(C17>=$B$6,"",MIN(EOMONTH($B$5,7),$B$6)) | D18: =IF(C17>=$B$6,"",C18-B18) | E18: =IF(C17>=$B$6,"",IF(SUMPRODUCT(($G$4:$G$6>B18)*($G$4:$G$6<=C18)*$F$4:$F$6)=0,"",SUMPRODUCT(($G$4:$G$6>B18)*($G$4:$G$6<=C18)*$F$4:$F$6)&"%")) | F18: =IF(C17>=$B$6,"",ROUND($B$3*SUMPRODUCT(($G$4:$G$6>B18)*($G$4:$G$6<=C18)*$F$4:$F$6)/100,2)) | G18: =IF(C17>=$B$6,"",$B$4) | H18: =IF(C17>=$B$6,"",ROUND(I17*$B$4/100*D18/365,2)) | I18: =IF(C17>=$B$6,"",I17-F18) | J18: =IF(C17>=$B$6,"",MAX(0,J17-H18))
F19: =SUM(F11:F18) -> 500000 | G19: รวม | H19: =SUM(H11:H18) -> 80136.99
A21: label ตรงระบบ: Period · Start/End Date · Day · Due Curtailment (%) · Curtailment (บาท) · Interest Rate · Interest · Principal Balance · Interest Balance · (ระบบมี JE ด้วย)

Sheet OD Bank Transaction
A1: OD-DEMO-001 — Bank Transaction (ข้อมูลต้นทาง feed เข้า Schedule Calculate)
A3: DATE | B3: TIME | C3: TXN CODE | D3: DEBIT | E3: CREDIT | F3: BALANCE | G3: SOURCE | H3: STATEMENT
A4: 46203 | B4: 10:15 | C4: TRANSFER | D4: 1017123.3 | E4: — | F4: -1017123.3 | G4: Manual | H4: 2026-07
A5: 46239 | B5: — | C5: — | D5: 92958.9 | E5: — | F5: 0 | G5: Manual | H5: 2026-08
A6: 46244 | B6: — | C6: — | D6: 18750 | E6: — | F6: 0 | G6: Manual | H6: 2026-08
A7: 46263 | B7: 10:20 | C7: TRANSFER | D7: 2002286.3 | E7: — | F7: -3019409.6 | G7: Manual | H7: 2026-07
A8: 46323 | B8: 10:25 | C8: TRANSFER | D8: 3313923.3 | E8: — | F8: -6333332.9 | G8: Manual | H8: 2026-07
A10: หมายเหตุ: BALANCE = ยอดคงเหลือ ณ รายการนั้น (Manual/Import) · ยอดติดลบ = เบิกเกิน (overdraft) → ยอดนี้ถูกส่งเข้าคอลัมน์ ENDING BALANCE ในแท็บ OD Schedule เพื่อคิดดอกเบี้ย

Sheet OD Schedule
A1: OD-DEMO-001 — Schedule Calculate (Overdraft · ดอกเบี้ยรายวัน)
A3: INTEREST RATE / YEAR (%) | B3: 6
A4: FACILITY LIMIT (วงเงิน) | B4: 3000000
A6: DATE | B6: DAYS | C6: ENDING BALANCE | D6: INTEREST RATE | E6: INTEREST | F6: STATUS
A7: 46203 | B7: 1 | C7: -1017123.3 | D7: =$B$3 -> 6 | E7: =ROUND(IF(C7<0,-C7*$B$3/100*B7/365,0),2) -> 167.2 | F7: =IF(C7>=0,"—",IF(-C7>$B$4,"Over Limit","Within Limit")) -> Within Limit
A8: 46239 | B8: 5 | C8: 0 | D8: =$B$3 -> 6 | E8: =ROUND(IF(C8<0,-C8*$B$3/100*B8/365,0),2) -> 0 | F8: =IF(C8>=0,"—",IF(-C8>$B$4,"Over Limit","Within Limit")) -> —
A9: 46244 | B9: 19 | C9: 0 | D9: =$B$3 -> 6 | E9: =ROUND(IF(C9<0,-C9*$B$3/100*B9/365,0),2) -> 0 | F9: =IF(C9>=0,"—",IF(-C9>$B$4,"Over Limit","Within Limit")) -> —
A10: 46263 | B10: 3 | C10: -3019409.6 | D10: =$B$3 -> 6 | E10: =ROUND(IF(C10<0,-C10*$B$3/100*B10/365,0),2) -> 1489.02 | F10: =IF(C10>=0,"—",IF(-C10>$B$4,"Over Limit","Within Limit")) -> Over Limit
A11: 46323 | B11: 1 | C11: -6333332.9 | D11: =$B$3 -> 6 | E11: =ROUND(IF(C11<0,-C11*$B$3/100*B11/365,0),2) -> 1041.1 | F11: =IF(C11>=0,"—",IF(-C11>$B$4,"Over Limit","Within Limit")) -> Over Limit
D12: Interest Expense (Outstanding) | E12: =SUM(E7:E11) -> 2697.32
D13: Ending Balance | E13: =C11 -> -6333332.9
D14: Total Ending Balance | E14: =E13-E12 -> -6336030.2
A16: สูตร: INTEREST = |ยอดคงเหลือติดลบ| × RATE% ÷ 100 × DAYS ÷ 365 (คิดเฉพาะวันที่ยอดติดลบ = เบิกเกิน) · STATUS: |ยอด| > วงเงิน = Over Limit · Total Ending Balance = Ending Balance − Interest

Sheet TR Schedule
A1: TR-DEMO-001 — Schedule Calculate (Trust Receipt · bullet ไม่มี curtailment)
A3: PRINCIPAL | B3: 3500000
A4: INTEREST RATE / YEAR (%) | B4: 5
A5: TRANSACTION DATE | B5: 46266
A6: MATURITY DATE | B6: 46356
A8: PERIOD | B8: START DATE | C8: END DATE | D8: DAY | E8: INTEREST RATE | F8: INTEREST | G8: PRINCIPAL BALANCE | H8: INTEREST BALANCE
A9: 0 | B9: =$B$5 -> 46266 | C9: =$B$5 -> 46266 | D9: — | E9: — | F9: — | G9: =$B$3 -> 3500000 | H9: =ROUND($B$3*$B$4/100*($B$6-$B$5)/365,2) -> 43150.68
A10: =IF(C9>=$B$6,"",1) -> 1 | B10: =IF(C9>=$B$6,"",C9) -> 46266 | C10: =IF(C9>=$B$6,"",MIN(EOMONTH($B$5,0),$B$6)) -> 46295 | D10: =IF(C9>=$B$6,"",C10-B10) -> 29 | E10: =IF(C9>=$B$6,"",$B$4) -> 5 | F10: =IF(C9>=$B$6,"",ROUND($B$3*$B$4/100*D10/365,2)) -> 13904.11 | G10: =IF(C9>=$B$6,"",$B$3) -> 3500000 | H10: =IF(C9>=$B$6,"",MAX(0,H9-F10)) -> 29246.57
A11: =IF(C10>=$B$6,"",2) -> 2 | B11: =IF(C10>=$B$6,"",C10) -> 46295 | C11: =IF(C10>=$B$6,"",MIN(EOMONTH($B$5,1),$B$6)) -> 46326 | D11: =IF(C10>=$B$6,"",C11-B11) -> 31 | E11: =IF(C10>=$B$6,"",$B$4) -> 5 | F11: =IF(C10>=$B$6,"",ROUND($B$3*$B$4/100*D11/365,2)) -> 14863.01 | G11: =IF(C10>=$B$6,"",$B$3) -> 3500000 | H11: =IF(C10>=$B$6,"",MAX(0,H10-F11)) -> 14383.56
A12: =IF(C11>=$B$6,"",3) -> 3 | B12: =IF(C11>=$B$6,"",C11) -> 46326 | C12: =IF(C11>=$B$6,"",MIN(EOMONTH($B$5,2),$B$6)) -> 46356 | D12: =IF(C11>=$B$6,"",C12-B12) -> 30 | E12: =IF(C11>=$B$6,"",$B$4) -> 5 | F12: =IF(C11>=$B$6,"",ROUND($B$3*$B$4/100*D12/365,2)) -> 14383.56 | G12: =IF(C11>=$B$6,"",$B$3) -> 3500000 | H12: =IF(C11>=$B$6,"",MAX(0,H11-F12)) -> 0
A13: =IF(C12>=$B$6,"",4) | B13: =IF(C12>=$B$6,"",C12) | C13: =IF(C12>=$B$6,"",MIN(EOMONTH($B$5,3),$B$6)) | D13: =IF(C12>=$B$6,"",C13-B13) | E13: =IF(C12>=$B$6,"",$B$4) | F13: =IF(C12>=$B$6,"",ROUND($B$3*$B$4/100*D13/365,2)) | G13: =IF(C12>=$B$6,"",$B$3) | H13: =IF(C12>=$B$6,"",MAX(0,H12-F13))
A14: =IF(C13>=$B$6,"",5) | B14: =IF(C13>=$B$6,"",C13) | C14: =IF(C13>=$B$6,"",MIN(EOMONTH($B$5,4),$B$6)) | D14: =IF(C13>=$B$6,"",C14-B14) | E14: =IF(C13>=$B$6,"",$B$4) | F14: =IF(C13>=$B$6,"",ROUND($B$3*$B$4/100*D14/365,2)) | G14: =IF(C13>=$B$6,"",$B$3) | H14: =IF(C13>=$B$6,"",MAX(0,H13-F14))
A15: =IF(C14>=$B$6,"",6) | B15: =IF(C14>=$B$6,"",C14) | C15: =IF(C14>=$B$6,"",MIN(EOMONTH($B$5,5),$B$6)) | D15: =IF(C14>=$B$6,"",C15-B15) | E15: =IF(C14>=$B$6,"",$B$4) | F15: =IF(C14>=$B$6,"",ROUND($B$3*$B$4/100*D15/365,2)) | G15: =IF(C14>=$B$6,"",$B$3) | H15: =IF(C14>=$B$6,"",MAX(0,H14-F15))
A16: =IF(C15>=$B$6,"",7) | B16: =IF(C15>=$B$6,"",C15) | C16: =IF(C15>=$B$6,"",MIN(EOMONTH($B$5,6),$B$6)) | D16: =IF(C15>=$B$6,"",C16-B16) | E16: =IF(C15>=$B$6,"",$B$4) | F16: =IF(C15>=$B$6,"",ROUND($B$3*$B$4/100*D16/365,2)) | G16: =IF(C15>=$B$6,"",$B$3) | H16: =IF(C15>=$B$6,"",MAX(0,H15-F16))
A17: =IF(C16>=$B$6,"",8) | B17: =IF(C16>=$B$6,"",C16) | C17: =IF(C16>=$B$6,"",MIN(EOMONTH($B$5,7),$B$6)) | D17: =IF(C16>=$B$6,"",C17-B17) | E17: =IF(C16>=$B$6,"",$B$4) | F17: =IF(C16>=$B$6,"",ROUND($B$3*$B$4/100*D17/365,2)) | G17: =IF(C16>=$B$6,"",$B$3) | H17: =IF(C16>=$B$6,"",MAX(0,H16-F17))
C18: Total | D18: =SUM(D10:D17) -> 90 | F18: =SUM(F10:F17) -> 43150.68
A20: สูตร: INTEREST = PRINCIPAL × RATE% ÷ 100 × DAY ÷ 365 · PRINCIPAL BALANCE คงที่ (bullet จ่ายก้อนเดียวตอนครบ) · INTEREST BALANCE = ดอกเบี้ยประมาณทั้งสัญญา − ดอกสะสม · งวดแบ่งตามสิ้นเดือน

Sheet FXF Fair Value
A1: FXF-DEMO-001 — Fair Value (label ตรงระบบ)
A3: NOTIONAL (จำนวนเงิน ตปท.) | B3: 100000
A4: CONTRACT RATE (forward) | B4: 35.5
A5: DIRECTION (Buy / Sell) | B5: Buy
A6: NOTIONAL THB (ยอดตามสัญญา) = NOTIONAL × CONTRACT RATE | B6: =ROUND($B$3*$B$4,2) -> 3550000
A8: ACCOUNTING PERIOD | B8: SPOT RATE (ณ สิ้นงวด) | C8: FAIR VALUE (auto) | D8: UNREALIZED GAIN/LOSS (auto) | E8: JE (Dr/Cr)
A9: 46295 | B9: 36 | C9: =ROUND($B$3*B9,2) -> 3600000 | D9: =ROUND(IF($B$5="Sell",$B$6-C9,C9-$B$6),2) -> 50000 | E9: =IF(D9>0,"Dr สินทรัพย์ FXF / Cr FX Gain (4929103)",IF(D9<0,"Dr FX Loss (5439907) / Cr หนี้สิน FXF","ไม่มีผลต่าง")) -> Dr สินทรัพย์ FXF / Cr FX Gain (4929103)
A10: 46326 | B10: 35.2 | C10: =ROUND($B$3*B10,2) -> 3520000 | D10: =ROUND(IF($B$5="Sell",$B$6-C10,C10-$B$6),2) -> -30000 | E10: =IF(D10>0,"Dr สินทรัพย์ FXF / Cr FX Gain (4929103)",IF(D10<0,"Dr FX Loss (5439907) / Cr หนี้สิน FXF","ไม่มีผลต่าง")) -> Dr FX Loss (5439907) / Cr หนี้สิน FXF
A11: 46356 | B11: 35.8 | C11: =ROUND($B$3*B11,2) -> 3580000 | D11: =ROUND(IF($B$5="Sell",$B$6-C11,C11-$B$6),2) -> 30000 | E11: =IF(D11>0,"Dr สินทรัพย์ FXF / Cr FX Gain (4929103)",IF(D11<0,"Dr FX Loss (5439907) / Cr หนี้สิน FXF","ไม่มีผลต่าง")) -> Dr สินทรัพย์ FXF / Cr FX Gain (4929103)
A13: สูตร (label ระบบ): FAIR VALUE (auto) = NOTIONAL × SPOT RATE (ณ สิ้นงวด) · UNREALIZED GAIN/LOSS (auto) = FAIR VALUE − NOTIONAL THB (ซื้อ) / NOTIONAL THB − FAIR VALUE (ขาย)
A14: บวก = กำไร · ลบ = ขาดทุน · ปุ่ม "ตีราคาสิ้นเดือนทั้งพอร์ต" = รันสูตรนี้ทุกสัญญา FXF ที่ Active พร้อมกัน (batch) ตามอัตรา spot per currency

Sheet FXF Portfolio MTM
A1: FX Forward — Monthly Valuation (MTM) · ตีราคาทั้งพอร์ต (label ตรง dialog)
A3: Valuation Date (สิ้นเดือน) | B3: 46295 | D3: Spot Rates per Currency
D4: USD | E4: 35.6
D5: JPY | E5: 0.24
D6: EUR | E6: 38.5
A8: FXF | B8: CCY | C8: DIRECTION | D8: NOTIONAL | E8: CONTRACT RATE | F8: MONTH-END RATE | G8: MTM (THB) | H8: STATUS
A9: FXF-2026-003 | B9: USD | C9: Buy | D9: 250000 | E9: 35.4 | F9: =VLOOKUP(B9,$D$4:$E$6,2,FALSE()) -> 35.6 | G9: =ROUND(IF(C9="Sell",D9*(E9-F9),D9*(F9-E9)),2) -> 50000 | H9: =IF(F9>0,"ready","—") -> ready
A10: FXF-DEMO-001 | B10: USD | C10: Buy | D10: 100000 | E10: 35.5 | F10: =VLOOKUP(B10,$D$4:$E$6,2,FALSE()) -> 35.6 | G10: =ROUND(IF(C10="Sell",D10*(E10-F10),D10*(F10-E10)),2) -> 10000 | H10: =IF(F10>0,"ready","—") -> ready
A11: FXF-2026-010 | B11: EUR | C11: Sell | D11: 50000 | E11: 38.8 | F11: =VLOOKUP(B11,$D$4:$E$6,2,FALSE()) -> 38.5 | G11: =ROUND(IF(C11="Sell",D11*(E11-F11),D11*(F11-E11)),2) -> 15000 | H11: =IF(F11>0,"ready","—") -> ready
F12: รวม MTM ทั้งพอร์ต | G12: =SUM(G9:G11) -> 75000
A14: สูตร MTM (THB) = NOTIONAL × (MONTH-END RATE − CONTRACT RATE) [Buy] · NOTIONAL × (CONTRACT − MONTH-END) [Sell] · MONTH-END RATE ดึงตาม CCY จากตาราง Spot · กด "ลงบัญชีทั้งหมด" = post ทุกแถวพร้อมกัน

Sheet LC Fee
A1: LC-DEMO-001 — Fee (label ตรงระบบ · 2 โหมด)
A3: L/C AMOUNT (THB) | B3: 3500000
A4: FEE RATE (%) | B4: 1
A5: FEE MODE (Full-term / Engagement+Pro-rated) | B5: Full-term
A6: ENGAGEMENT FEE (THB) | B6: 0
A7: TERM DAYS (สำหรับ pro-rated) | B7: 90
A9: L/C Amount (THB) | B9: =$B$3 -> 3500000
A10: Rate Component (Fee Rate %) | B10: =ROUND($B$3*$B$4/100,2) -> 35000
A11: Pro-rated (TERM DAYS / 365) | B11: =ROUND(B10*$B$7/365,2) -> 8630.14
A12: Engagement Fee | B12: =$B$6 -> 0
A13: 💰 Total Fee | B13: =IF(ISNUMBER(SEARCH("Engagement",$B$5)),B11+B12,B10) -> 35000
A15: สูตร: Full-term → Total Fee = L/C Amount × Fee Rate% · Engagement+Pro-rated → (Rate Component × TERM DAYS ÷ 365) + Engagement Fee
A17: วิธีสลับ: คลิกช่อง B5 (FEE MODE) → จะมีลูกศร dropdown ให้เลือก "Full-term" หรือ "Engagement+Pro-rated" → Total Fee เปลี่ยนตามทันที

Sheet LC Schedule
A1: LC-DEMO-001 — Schedule Calculate (Prepaid L/C Fee · daily-prorated รายเดือน)
A3: TOTAL FEE (ลิงก์จากแท็บ LC Fee) | B3: ='LC Fee'!B13 -> 35000
A4: ISSUE DATE | B4: 46266
A5: EXPIRY DATE | B5: 46401
A6: Total Days = Expiry − Issue | B6: =$B$5-$B$4 -> 135
A7: Daily Rate = Total Fee ÷ Total Days | B7: =$B$3/B6 -> 259.25926
A9: PERIOD | B9: PAYMENT DATE | C9: START | D9: END | E9: DAYS | F9: FEE AMOUNT | G9: REMAINING
A10: จ่าย | B10: =$B$4 -> 46266 | C10: — | D10: — | E10: — | F10: =$B$3 -> 35000 | G10: =$B$3 -> 35000
A11: =IF(FALSE(),"",1) -> 1 | B11: =IF(FALSE(),"","—") -> — | C11: =IF(FALSE(),"",$B$4) -> 46266 | D11: =IF(FALSE(),"",MIN(EOMONTH(C11,0),$B$5)) -> 46295 | E11: =IF(FALSE(),"",IF(1=1,D11-$B$4,D11-C11+1)) -> 29 | F11: =IF(FALSE(),"",IF(D11>=$B$5,G10,ROUND($B$7*E11,2))) -> 7518.52 | G11: =IF(FALSE(),"",G10-F11) -> 27481.48
A12: =IF(D11>=$B$5,"",2) -> 2 | B12: =IF(D11>=$B$5,"","—") -> — | C12: =IF(D11>=$B$5,"",D11+1) -> 46296 | D12: =IF(D11>=$B$5,"",MIN(EOMONTH(C12,0),$B$5)) -> 46326 | E12: =IF(D11>=$B$5,"",IF(2=1,D12-$B$4,D12-C12+1)) -> 31 | F12: =IF(D11>=$B$5,"",IF(D12>=$B$5,G11,ROUND($B$7*E12,2))) -> 8037.04 | G12: =IF(D11>=$B$5,"",G11-F12) -> 19444.44
A13: =IF(D12>=$B$5,"",3) -> 3 | B13: =IF(D12>=$B$5,"","—") -> — | C13: =IF(D12>=$B$5,"",D12+1) -> 46327 | D13: =IF(D12>=$B$5,"",MIN(EOMONTH(C13,0),$B$5)) -> 46356 | E13: =IF(D12>=$B$5,"",IF(3=1,D13-$B$4,D13-C13+1)) -> 30 | F13: =IF(D12>=$B$5,"",IF(D13>=$B$5,G12,ROUND($B$7*E13,2))) -> 7777.78 | G13: =IF(D12>=$B$5,"",G12-F13) -> 11666.66
A14: =IF(D13>=$B$5,"",4) -> 4 | B14: =IF(D13>=$B$5,"","—") -> — | C14: =IF(D13>=$B$5,"",D13+1) -> 46357 | D14: =IF(D13>=$B$5,"",MIN(EOMONTH(C14,0),$B$5)) -> 46387 | E14: =IF(D13>=$B$5,"",IF(4=1,D14-$B$4,D14-C14+1)) -> 31 | F14: =IF(D13>=$B$5,"",IF(D14>=$B$5,G13,ROUND($B$7*E14,2))) -> 8037.04 | G14: =IF(D13>=$B$5,"",G13-F14) -> 3629.62
A15: =IF(D14>=$B$5,"",5) -> 5 | B15: =IF(D14>=$B$5,"","—") -> — | C15: =IF(D14>=$B$5,"",D14+1) -> 46388 | D15: =IF(D14>=$B$5,"",MIN(EOMONTH(C15,0),$B$5)) -> 46401 | E15: =IF(D14>=$B$5,"",IF(5=1,D15-$B$4,D15-C15+1)) -> 14 | F15: =IF(D14>=$B$5,"",IF(D15>=$B$5,G14,ROUND($B$7*E15,2))) -> 3629.62 | G15: =IF(D14>=$B$5,"",G14-F15) -> 0
