Workbook

Sheet คำนวณค่างวด
A1: ตรวจการคำนวณค่างวด (INSTALLMENT) — PAYMENT TYPE: Grace Period and Fix Installment
A2: กรอกช่องสีเหลือง (ตาม label หน้าจอ Schedule Information) → คำนวณค่างวดให้ · เทียบกับช่อง INSTALLMENT ที่ระบบแสดง
A4: ข้อมูลนำเข้า — ตาม label หน้าจอ
A5: PRINCIPAL | B5: 1000000
A6: EFFECTIVE INTEREST RATE / YEAR (%) | B6: 2
A7: TERM (MONTHS) | B7: 24
A8: GRACE PERIOD (MONTHS) | B8: 3
A9: PAYMENT TYPE | B9: Grace Period and Fix Installment
A10: PAYMENT TIMING | B10: ชำระปลายงวด (Arrears)
A12: ขั้นตอนการคำนวณ (สูตรลดต้นลดดอก)
A13: r = EFFECTIVE INTEREST RATE / YEAR ÷ 12 ÷ 100 | B13: =B6/12/100 -> 0.0016666667
A14: n = TERM (MONTHS) − GRACE PERIOD (MONTHS) | B14: =B7-B8 -> 21
A15: (1 + r) ^ n | B15: =(1+B13)^B14 -> 1.0355895
A16: ตัวเศษ = PRINCIPAL × r × (1+r)^n | B16: =B5*B13*B15 -> 1725.9826
A17: ตัวส่วน = (1+r)^n − 1 | B17: =B15-1 -> 0.035589537
A18: INSTALLMENT (คำนวณ) = ตัวเศษ ÷ ตัวส่วน | B18: =ROUND(B16/B17,2) -> 48496.91
A20: INSTALLMENT (ที่ระบบแสดง) — กรอกเพื่อเทียบ | B20: 48496.91
A21: ผลตรวจ (PASS/FAIL) | B21: =IF(ABS(B18-B20)<0.01,"PASS ✓","FAIL ✗") -> PASS ✓
A23: หมายเหตุ: อัตราต่อเดือน "ห้ามคูณ n ตรง ๆ" (flat) — สูตรลดต้นลดดอกยกกำลัง (1+r)^n เพราะดอกเบี้ยคิดบนยอดคงเหลือที่ลดลงทุกงวด · n ใช้ = TERM − GRACE (ช่วง Grace จ่ายดอกอย่างเดียว ยังไม่ตัดต้น)

Sheet ตารางผ่อน
A1: ตารางผ่อนชำระ (Amortization) — GRACE PERIOD 3 งวด + ผ่อนเงินต้น 21 งวด
A3: งวดที่ | B3: ประเภท | C3: ยอดต้นต้นงวด | D3: ดอกเบี้ย | E3: เงินต้น | F3: INSTALLMENT | G3: ยอดต้นปลายงวด
A4: 1 | B4: =IF(1<=คำนวณค่างวด!$B$8,"Grace (ดอกอย่างเดียว)","ผ่อนปกติ") -> Grace (ดอกอย่างเดียว) | C4: =คำนวณค่างวด!$B$5 -> 1000000 | D4: =ROUND(C4*คำนวณค่างวด!B13,2) -> 1666.67 | E4: =F4-D4 -> 0 | F4: =IF(1<=คำนวณค่างวด!$B$8,D4,IF(1=คำนวณค่างวด!$B$7,C4+D4,คำนวณค่างวด!$B$18)) -> 1666.67 | G4: =C4-E4 -> 1000000
A5: 2 | B5: =IF(2<=คำนวณค่างวด!$B$8,"Grace (ดอกอย่างเดียว)","ผ่อนปกติ") -> Grace (ดอกอย่างเดียว) | C5: =G4 -> 1000000 | D5: =ROUND(C5*คำนวณค่างวด!B13,2) -> 1666.67 | E5: =F5-D5 -> 0 | F5: =IF(2<=คำนวณค่างวด!$B$8,D5,IF(2=คำนวณค่างวด!$B$7,C5+D5,คำนวณค่างวด!$B$18)) -> 1666.67 | G5: =C5-E5 -> 1000000
A6: 3 | B6: =IF(3<=คำนวณค่างวด!$B$8,"Grace (ดอกอย่างเดียว)","ผ่อนปกติ") -> Grace (ดอกอย่างเดียว) | C6: =G5 -> 1000000 | D6: =ROUND(C6*คำนวณค่างวด!B13,2) -> 1666.67 | E6: =F6-D6 -> 0 | F6: =IF(3<=คำนวณค่างวด!$B$8,D6,IF(3=คำนวณค่างวด!$B$7,C6+D6,คำนวณค่างวด!$B$18)) -> 1666.67 | G6: =C6-E6 -> 1000000
A7: 4 | B7: =IF(4<=คำนวณค่างวด!$B$8,"Grace (ดอกอย่างเดียว)","ผ่อนปกติ") -> ผ่อนปกติ | C7: =G6 -> 1000000 | D7: =ROUND(C7*คำนวณค่างวด!B13,2) -> 1666.67 | E7: =F7-D7 -> 46830.24 | F7: =IF(4<=คำนวณค่างวด!$B$8,D7,IF(4=คำนวณค่างวด!$B$7,C7+D7,คำนวณค่างวด!$B$18)) -> 48496.91 | G7: =C7-E7 -> 953169.76
A8: 5 | B8: =IF(5<=คำนวณค่างวด!$B$8,"Grace (ดอกอย่างเดียว)","ผ่อนปกติ") -> ผ่อนปกติ | C8: =G7 -> 953169.76 | D8: =ROUND(C8*คำนวณค่างวด!B13,2) -> 1588.62 | E8: =F8-D8 -> 46908.29 | F8: =IF(5<=คำนวณค่างวด!$B$8,D8,IF(5=คำนวณค่างวด!$B$7,C8+D8,คำนวณค่างวด!$B$18)) -> 48496.91 | G8: =C8-E8 -> 906261.47
A9: 6 | B9: =IF(6<=คำนวณค่างวด!$B$8,"Grace (ดอกอย่างเดียว)","ผ่อนปกติ") -> ผ่อนปกติ | C9: =G8 -> 906261.47 | D9: =ROUND(C9*คำนวณค่างวด!B13,2) -> 1510.44 | E9: =F9-D9 -> 46986.47 | F9: =IF(6<=คำนวณค่างวด!$B$8,D9,IF(6=คำนวณค่างวด!$B$7,C9+D9,คำนวณค่างวด!$B$18)) -> 48496.91 | G9: =C9-E9 -> 859275
A10: 7 | B10: =IF(7<=คำนวณค่างวด!$B$8,"Grace (ดอกอย่างเดียว)","ผ่อนปกติ") -> ผ่อนปกติ | C10: =G9 -> 859275 | D10: =ROUND(C10*คำนวณค่างวด!B13,2) -> 1432.13 | E10: =F10-D10 -> 47064.78 | F10: =IF(7<=คำนวณค่างวด!$B$8,D10,IF(7=คำนวณค่างวด!$B$7,C10+D10,คำนวณค่างวด!$B$18)) -> 48496.91 | G10: =C10-E10 -> 812210.22
A11: 8 | B11: =IF(8<=คำนวณค่างวด!$B$8,"Grace (ดอกอย่างเดียว)","ผ่อนปกติ") -> ผ่อนปกติ | C11: =G10 -> 812210.22 | D11: =ROUND(C11*คำนวณค่างวด!B13,2) -> 1353.68 | E11: =F11-D11 -> 47143.23 | F11: =IF(8<=คำนวณค่างวด!$B$8,D11,IF(8=คำนวณค่างวด!$B$7,C11+D11,คำนวณค่างวด!$B$18)) -> 48496.91 | G11: =C11-E11 -> 765066.99
A12: 9 | B12: =IF(9<=คำนวณค่างวด!$B$8,"Grace (ดอกอย่างเดียว)","ผ่อนปกติ") -> ผ่อนปกติ | C12: =G11 -> 765066.99 | D12: =ROUND(C12*คำนวณค่างวด!B13,2) -> 1275.11 | E12: =F12-D12 -> 47221.8 | F12: =IF(9<=คำนวณค่างวด!$B$8,D12,IF(9=คำนวณค่างวด!$B$7,C12+D12,คำนวณค่างวด!$B$18)) -> 48496.91 | G12: =C12-E12 -> 717845.19
A13: 10 | B13: =IF(10<=คำนวณค่างวด!$B$8,"Grace (ดอกอย่างเดียว)","ผ่อนปกติ") -> ผ่อนปกติ | C13: =G12 -> 717845.19 | D13: =ROUND(C13*คำนวณค่างวด!B13,2) -> 1196.41 | E13: =F13-D13 -> 47300.5 | F13: =IF(10<=คำนวณค่างวด!$B$8,D13,IF(10=คำนวณค่างวด!$B$7,C13+D13,คำนวณค่างวด!$B$18)) -> 48496.91 | G13: =C13-E13 -> 670544.69
A14: 11 | B14: =IF(11<=คำนวณค่างวด!$B$8,"Grace (ดอกอย่างเดียว)","ผ่อนปกติ") -> ผ่อนปกติ | C14: =G13 -> 670544.69 | D14: =ROUND(C14*คำนวณค่างวด!B13,2) -> 1117.57 | E14: =F14-D14 -> 47379.34 | F14: =IF(11<=คำนวณค่างวด!$B$8,D14,IF(11=คำนวณค่างวด!$B$7,C14+D14,คำนวณค่างวด!$B$18)) -> 48496.91 | G14: =C14-E14 -> 623165.35
A15: 12 | B15: =IF(12<=คำนวณค่างวด!$B$8,"Grace (ดอกอย่างเดียว)","ผ่อนปกติ") -> ผ่อนปกติ | C15: =G14 -> 623165.35 | D15: =ROUND(C15*คำนวณค่างวด!B13,2) -> 1038.61 | E15: =F15-D15 -> 47458.3 | F15: =IF(12<=คำนวณค่างวด!$B$8,D15,IF(12=คำนวณค่างวด!$B$7,C15+D15,คำนวณค่างวด!$B$18)) -> 48496.91 | G15: =C15-E15 -> 575707.05
A16: 13 | B16: =IF(13<=คำนวณค่างวด!$B$8,"Grace (ดอกอย่างเดียว)","ผ่อนปกติ") -> ผ่อนปกติ | C16: =G15 -> 575707.05 | D16: =ROUND(C16*คำนวณค่างวด!B13,2) -> 959.51 | E16: =F16-D16 -> 47537.4 | F16: =IF(13<=คำนวณค่างวด!$B$8,D16,IF(13=คำนวณค่างวด!$B$7,C16+D16,คำนวณค่างวด!$B$18)) -> 48496.91 | G16: =C16-E16 -> 528169.65
A17: 14 | B17: =IF(14<=คำนวณค่างวด!$B$8,"Grace (ดอกอย่างเดียว)","ผ่อนปกติ") -> ผ่อนปกติ | C17: =G16 -> 528169.65 | D17: =ROUND(C17*คำนวณค่างวด!B13,2) -> 880.28 | E17: =F17-D17 -> 47616.63 | F17: =IF(14<=คำนวณค่างวด!$B$8,D17,IF(14=คำนวณค่างวด!$B$7,C17+D17,คำนวณค่างวด!$B$18)) -> 48496.91 | G17: =C17-E17 -> 480553.02
A18: 15 | B18: =IF(15<=คำนวณค่างวด!$B$8,"Grace (ดอกอย่างเดียว)","ผ่อนปกติ") -> ผ่อนปกติ | C18: =G17 -> 480553.02 | D18: =ROUND(C18*คำนวณค่างวด!B13,2) -> 800.92 | E18: =F18-D18 -> 47695.99 | F18: =IF(15<=คำนวณค่างวด!$B$8,D18,IF(15=คำนวณค่างวด!$B$7,C18+D18,คำนวณค่างวด!$B$18)) -> 48496.91 | G18: =C18-E18 -> 432857.03
A19: 16 | B19: =IF(16<=คำนวณค่างวด!$B$8,"Grace (ดอกอย่างเดียว)","ผ่อนปกติ") -> ผ่อนปกติ | C19: =G18 -> 432857.03 | D19: =ROUND(C19*คำนวณค่างวด!B13,2) -> 721.43 | E19: =F19-D19 -> 47775.48 | F19: =IF(16<=คำนวณค่างวด!$B$8,D19,IF(16=คำนวณค่างวด!$B$7,C19+D19,คำนวณค่างวด!$B$18)) -> 48496.91 | G19: =C19-E19 -> 385081.55
A20: 17 | B20: =IF(17<=คำนวณค่างวด!$B$8,"Grace (ดอกอย่างเดียว)","ผ่อนปกติ") -> ผ่อนปกติ | C20: =G19 -> 385081.55 | D20: =ROUND(C20*คำนวณค่างวด!B13,2) -> 641.8 | E20: =F20-D20 -> 47855.11 | F20: =IF(17<=คำนวณค่างวด!$B$8,D20,IF(17=คำนวณค่างวด!$B$7,C20+D20,คำนวณค่างวด!$B$18)) -> 48496.91 | G20: =C20-E20 -> 337226.44
A21: 18 | B21: =IF(18<=คำนวณค่างวด!$B$8,"Grace (ดอกอย่างเดียว)","ผ่อนปกติ") -> ผ่อนปกติ | C21: =G20 -> 337226.44 | D21: =ROUND(C21*คำนวณค่างวด!B13,2) -> 562.04 | E21: =F21-D21 -> 47934.87 | F21: =IF(18<=คำนวณค่างวด!$B$8,D21,IF(18=คำนวณค่างวด!$B$7,C21+D21,คำนวณค่างวด!$B$18)) -> 48496.91 | G21: =C21-E21 -> 289291.57
A22: 19 | B22: =IF(19<=คำนวณค่างวด!$B$8,"Grace (ดอกอย่างเดียว)","ผ่อนปกติ") -> ผ่อนปกติ | C22: =G21 -> 289291.57 | D22: =ROUND(C22*คำนวณค่างวด!B13,2) -> 482.15 | E22: =F22-D22 -> 48014.76 | F22: =IF(19<=คำนวณค่างวด!$B$8,D22,IF(19=คำนวณค่างวด!$B$7,C22+D22,คำนวณค่างวด!$B$18)) -> 48496.91 | G22: =C22-E22 -> 241276.81
A23: 20 | B23: =IF(20<=คำนวณค่างวด!$B$8,"Grace (ดอกอย่างเดียว)","ผ่อนปกติ") -> ผ่อนปกติ | C23: =G22 -> 241276.81 | D23: =ROUND(C23*คำนวณค่างวด!B13,2) -> 402.13 | E23: =F23-D23 -> 48094.78 | F23: =IF(20<=คำนวณค่างวด!$B$8,D23,IF(20=คำนวณค่างวด!$B$7,C23+D23,คำนวณค่างวด!$B$18)) -> 48496.91 | G23: =C23-E23 -> 193182.03
A24: 21 | B24: =IF(21<=คำนวณค่างวด!$B$8,"Grace (ดอกอย่างเดียว)","ผ่อนปกติ") -> ผ่อนปกติ | C24: =G23 -> 193182.03 | D24: =ROUND(C24*คำนวณค่างวด!B13,2) -> 321.97 | E24: =F24-D24 -> 48174.94 | F24: =IF(21<=คำนวณค่างวด!$B$8,D24,IF(21=คำนวณค่างวด!$B$7,C24+D24,คำนวณค่างวด!$B$18)) -> 48496.91 | G24: =C24-E24 -> 145007.09
A25: 22 | B25: =IF(22<=คำนวณค่างวด!$B$8,"Grace (ดอกอย่างเดียว)","ผ่อนปกติ") -> ผ่อนปกติ | C25: =G24 -> 145007.09 | D25: =ROUND(C25*คำนวณค่างวด!B13,2) -> 241.68 | E25: =F25-D25 -> 48255.23 | F25: =IF(22<=คำนวณค่างวด!$B$8,D25,IF(22=คำนวณค่างวด!$B$7,C25+D25,คำนวณค่างวด!$B$18)) -> 48496.91 | G25: =C25-E25 -> 96751.86
A26: 23 | B26: =IF(23<=คำนวณค่างวด!$B$8,"Grace (ดอกอย่างเดียว)","ผ่อนปกติ") -> ผ่อนปกติ | C26: =G25 -> 96751.86 | D26: =ROUND(C26*คำนวณค่างวด!B13,2) -> 161.25 | E26: =F26-D26 -> 48335.66 | F26: =IF(23<=คำนวณค่างวด!$B$8,D26,IF(23=คำนวณค่างวด!$B$7,C26+D26,คำนวณค่างวด!$B$18)) -> 48496.91 | G26: =C26-E26 -> 48416.2
A27: 24 | B27: =IF(24<=คำนวณค่างวด!$B$8,"Grace (ดอกอย่างเดียว)","ผ่อนปกติ") -> ผ่อนปกติ | C27: =G26 -> 48416.2 | D27: =ROUND(C27*คำนวณค่างวด!B13,2) -> 80.69 | E27: =F27-D27 -> 48416.2 | F27: =IF(24<=คำนวณค่างวด!$B$8,D27,IF(24=คำนวณค่างวด!$B$7,C27+D27,คำนวณค่างวด!$B$18)) -> 48496.89 | G27: =C27-E27 -> 0
B28: รวม | D28: =SUM(D4:D27) -> 23435.1 | E28: =SUM(E4:E27) -> 1000000 | F28: =SUM(F4:F27) -> 1023435.1
A30: หมายเหตุ: ระบบจริงคิดดอกเบี้ยแบบรายวัน (actual/365) ตามวันสิ้นงวดจริง — ตัวเลขดอกเบี้ยรายงวดในชีทนี้ (ใช้ r คงที่/เดือน) อาจต่างจากระบบเล็กน้อย แต่ค่า INSTALLMENT (ค่างวดคงที่) ตรงกันเป๊ะ

Sheet IRR-MONTH
A1: ตรวจ IRR / MONTH (%) — คิดจากกระแสเงินสดจริง (actual/365) ไม่ใช่ rate ÷ 12
A2: กรอกช่องเหลือง → คำนวณ IRR/เดือน ให้ · เทียบกับช่อง IRR / MONTH (%) ที่ระบบแสดง
A4: ข้อมูลนำเข้า (label หน้าจอ)
A5: PRINCIPAL | B5: =คำนวณค่างวด!B5 -> 1000000
A6: EFFECTIVE INTEREST RATE / YEAR (%) | B6: =คำนวณค่างวด!B6 -> 2
A7: TERM (MONTHS) | B7: =คำนวณค่างวด!B7 -> 24
A8: GRACE PERIOD (MONTHS) | B8: =คำนวณค่างวด!B8 -> 3
A9: INSTALLMENT START DATE | B9: 46295
A10: PAY AT END OF MONTH | B10: ใช่ (month-end)
A11: INSTALLMENT (level) = PMT | B11: =-PMT($B$6/100/12,$B$7-$B$8,$B$5) -> 48496.909
A12: i ที่ใช้ทอน = IRR เต็มค่า (ไม่ปัด) | B12: =IRR(H14:H38,$B$6/100/12) -> 0.0016676881
A13: t (งวด) | B13: วันเริ่มงวด | C13: วันสิ้นงวด | D13: วัน | E13: ยอดต้นต้นงวด | F13: ดอกเบี้ย (actual/365) | G13: เงินต้น | H13: กระแสเงินสด (Cashflow) | I13: ยอดต้นปลายงวด | J13: (1+i)ᵗ | K13: มูลค่าปัจจุบัน = ค่างวด ÷ (1+i)ᵗ
A14: 0 | B14: =$B$9 -> 46295 | H14: =-$B$5 -> -1000000 | J14: =(1+$B$12)^A14 -> 1 | K14: =H14/J14 -> -1000000
A15: 1 | B15: =EOMONTH($B$9,0) -> 46295 | C15: =EOMONTH($B$9,1) -> 46326 | D15: =C15-B15 -> 31 | E15: =$B$5 -> 1000000 | F15: =E15*$B$6/100*D15/365 -> 1698.6301 | G15: =H15-F15 -> 0 | H15: =IF(1<=$B$8,F15,IF(1=$B$7,E15+F15,$B$11)) -> 1698.6301 | I15: =E15-G15 -> 1000000 | J15: =(1+$B$12)^A15 -> 1.0016677 | K15: =H15/J15 -> 1695.8021
A16: 2 | B16: =EOMONTH($B$9,1) -> 46326 | C16: =EOMONTH($B$9,2) -> 46356 | D16: =C16-B16 -> 30 | E16: =I15 -> 1000000 | F16: =E16*$B$6/100*D16/365 -> 1643.8356 | G16: =H16-F16 -> 0 | H16: =IF(2<=$B$8,F16,IF(2=$B$7,E16+F16,$B$11)) -> 1643.8356 | I16: =E16-G16 -> 1000000 | J16: =(1+$B$12)^A16 -> 1.0033382 | K16: =H16/J16 -> 1638.3665
A17: 3 | B17: =EOMONTH($B$9,2) -> 46356 | C17: =EOMONTH($B$9,3) -> 46387 | D17: =C17-B17 -> 31 | E17: =I16 -> 1000000 | F17: =E17*$B$6/100*D17/365 -> 1698.6301 | G17: =H17-F17 -> 0 | H17: =IF(3<=$B$8,F17,IF(3=$B$7,E17+F17,$B$11)) -> 1698.6301 | I17: =E17-G17 -> 1000000 | J17: =(1+$B$12)^A17 -> 1.0050114 | K17: =H17/J17 -> 1690.16
A18: 4 | B18: =EOMONTH($B$9,3) -> 46387 | C18: =EOMONTH($B$9,4) -> 46418 | D18: =C18-B18 -> 31 | E18: =I17 -> 1000000 | F18: =E18*$B$6/100*D18/365 -> 1698.6301 | G18: =H18-F18 -> 46798.279 | H18: =IF(4<=$B$8,F18,IF(4=$B$7,E18+F18,$B$11)) -> 48496.909 | I18: =E18-G18 -> 953201.72 | J18: =(1+$B$12)^A18 -> 1.0066875 | K18: =H18/J18 -> 48174.743
A19: 5 | B19: =EOMONTH($B$9,4) -> 46418 | C19: =EOMONTH($B$9,5) -> 46446 | D19: =C19-B19 -> 28 | E19: =I18 -> 953201.72 | F19: =E19*$B$6/100*D19/365 -> 1462.4465 | G19: =H19-F19 -> 47034.463 | H19: =IF(5<=$B$8,F19,IF(5=$B$7,E19+F19,$B$11)) -> 48496.909 | I19: =E19-G19 -> 906167.26 | J19: =(1+$B$12)^A19 -> 1.0083663 | K19: =H19/J19 -> 48094.536
A20: 6 | B20: =EOMONTH($B$9,5) -> 46446 | C20: =EOMONTH($B$9,6) -> 46477 | D20: =C20-B20 -> 31 | E20: =I19 -> 906167.26 | F20: =E20*$B$6/100*D20/365 -> 1539.243 | G20: =H20-F20 -> 46957.666 | H20: =IF(6<=$B$8,F20,IF(6=$B$7,E20+F20,$B$11)) -> 48496.909 | I20: =E20-G20 -> 859209.59 | J20: =(1+$B$12)^A20 -> 1.0100479 | K20: =H20/J20 -> 48014.463
A21: 7 | B21: =EOMONTH($B$9,6) -> 46477 | C21: =EOMONTH($B$9,7) -> 46507 | D21: =C21-B21 -> 30 | E21: =I20 -> 859209.59 | F21: =E21*$B$6/100*D21/365 -> 1412.3993 | G21: =H21-F21 -> 47084.51 | H21: =IF(7<=$B$8,F21,IF(7=$B$7,E21+F21,$B$11)) -> 48496.909 | I21: =E21-G21 -> 812125.08 | J21: =(1+$B$12)^A21 -> 1.0117324 | K21: =H21/J21 -> 47934.523
A22: 8 | B22: =EOMONTH($B$9,7) -> 46507 | C22: =EOMONTH($B$9,8) -> 46538 | D22: =C22-B22 -> 31 | E22: =I21 -> 812125.08 | F22: =E22*$B$6/100*D22/365 -> 1379.5001 | G22: =H22-F22 -> 47117.409 | H22: =IF(8<=$B$8,F22,IF(8=$B$7,E22+F22,$B$11)) -> 48496.909 | I22: =E22-G22 -> 765007.67 | J22: =(1+$B$12)^A22 -> 1.0134196 | K22: =H22/J22 -> 47854.716
A23: 9 | B23: =EOMONTH($B$9,8) -> 46538 | C23: =EOMONTH($B$9,9) -> 46568 | D23: =C23-B23 -> 30 | E23: =I22 -> 765007.67 | F23: =E23*$B$6/100*D23/365 -> 1257.5469 | G23: =H23-F23 -> 47239.363 | H23: =IF(9<=$B$8,F23,IF(9=$B$7,E23+F23,$B$11)) -> 48496.909 | I23: =E23-G23 -> 717768.31 | J23: =(1+$B$12)^A23 -> 1.0151097 | K23: =H23/J23 -> 47775.043
A24: 10 | B24: =EOMONTH($B$9,9) -> 46568 | C24: =EOMONTH($B$9,10) -> 46599 | D24: =C24-B24 -> 31 | E24: =I23 -> 717768.31 | F24: =E24*$B$6/100*D24/365 -> 1219.2229 | G24: =H24-F24 -> 47277.687 | H24: =IF(10<=$B$8,F24,IF(10=$B$7,E24+F24,$B$11)) -> 48496.909 | I24: =E24-G24 -> 670490.62 | J24: =(1+$B$12)^A24 -> 1.0168026 | K24: =H24/J24 -> 47695.501
A25: 11 | B25: =EOMONTH($B$9,10) -> 46599 | C25: =EOMONTH($B$9,11) -> 46630 | D25: =C25-B25 -> 31 | E25: =I24 -> 670490.62 | F25: =E25*$B$6/100*D25/365 -> 1138.9156 | G25: =H25-F25 -> 47357.994 | H25: =IF(11<=$B$8,F25,IF(11=$B$7,E25+F25,$B$11)) -> 48496.909 | I25: =E25-G25 -> 623132.63 | J25: =(1+$B$12)^A25 -> 1.0184983 | K25: =H25/J25 -> 47616.093
A26: 12 | B26: =EOMONTH($B$9,11) -> 46630 | C26: =EOMONTH($B$9,12) -> 46660 | D26: =C26-B26 -> 30 | E26: =I25 -> 623132.63 | F26: =E26*$B$6/100*D26/365 -> 1024.3276 | G26: =H26-F26 -> 47472.582 | H26: =IF(12<=$B$8,F26,IF(12=$B$7,E26+F26,$B$11)) -> 48496.909 | I26: =E26-G26 -> 575660.05 | J26: =(1+$B$12)^A26 -> 1.0201968 | K26: =H26/J26 -> 47536.816
A27: 13 | B27: =EOMONTH($B$9,12) -> 46660 | C27: =EOMONTH($B$9,13) -> 46691 | D27: =C27-B27 -> 31 | E27: =I26 -> 575660.05 | F27: =E27*$B$6/100*D27/365 -> 977.8335 | G27: =H27-F27 -> 47519.076 | H27: =IF(13<=$B$8,F27,IF(13=$B$7,E27+F27,$B$11)) -> 48496.909 | I27: =E27-G27 -> 528140.97 | J27: =(1+$B$12)^A27 -> 1.0218982 | K27: =H27/J27 -> 47457.671
A28: 14 | B28: =EOMONTH($B$9,13) -> 46691 | C28: =EOMONTH($B$9,14) -> 46721 | D28: =C28-B28 -> 30 | E28: =I27 -> 528140.97 | F28: =E28*$B$6/100*D28/365 -> 868.17694 | G28: =H28-F28 -> 47628.733 | H28: =IF(14<=$B$8,F28,IF(14=$B$7,E28+F28,$B$11)) -> 48496.909 | I28: =E28-G28 -> 480512.24 | J28: =(1+$B$12)^A28 -> 1.0236024 | K28: =H28/J28 -> 47378.659
A29: 15 | B29: =EOMONTH($B$9,14) -> 46721 | C29: =EOMONTH($B$9,15) -> 46752 | D29: =C29-B29 -> 31 | E29: =I28 -> 480512.24 | F29: =E29*$B$6/100*D29/365 -> 816.21257 | G29: =H29-F29 -> 47680.697 | H29: =IF(15<=$B$8,F29,IF(15=$B$7,E29+F29,$B$11)) -> 48496.909 | I29: =E29-G29 -> 432831.54 | J29: =(1+$B$12)^A29 -> 1.0253095 | K29: =H29/J29 -> 47299.777
A30: 16 | B30: =EOMONTH($B$9,15) -> 46752 | C30: =EOMONTH($B$9,16) -> 46783 | D30: =C30-B30 -> 31 | E30: =I29 -> 432831.54 | F30: =E30*$B$6/100*D30/365 -> 735.2207 | G30: =H30-F30 -> 47761.689 | H30: =IF(16<=$B$8,F30,IF(16=$B$7,E30+F30,$B$11)) -> 48496.909 | I30: =E30-G30 -> 385069.85 | J30: =(1+$B$12)^A30 -> 1.0270194 | K30: =H30/J30 -> 47221.027
A31: 17 | B31: =EOMONTH($B$9,16) -> 46783 | C31: =EOMONTH($B$9,17) -> 46812 | D31: =C31-B31 -> 29 | E31: =I30 -> 385069.85 | F31: =E31*$B$6/100*D31/365 -> 611.89182 | G31: =H31-F31 -> 47885.018 | H31: =IF(17<=$B$8,F31,IF(17=$B$7,E31+F31,$B$11)) -> 48496.909 | I31: =E31-G31 -> 337184.84 | J31: =(1+$B$12)^A31 -> 1.0287321 | K31: =H31/J31 -> 47142.409
A32: 18 | B32: =EOMONTH($B$9,17) -> 46812 | C32: =EOMONTH($B$9,18) -> 46843 | D32: =C32-B32 -> 31 | E32: =I31 -> 337184.84 | F32: =E32*$B$6/100*D32/365 -> 572.75232 | G32: =H32-F32 -> 47924.157 | H32: =IF(18<=$B$8,F32,IF(18=$B$7,E32+F32,$B$11)) -> 48496.909 | I32: =E32-G32 -> 289260.68 | J32: =(1+$B$12)^A32 -> 1.0304477 | K32: =H32/J32 -> 47063.921
A33: 19 | B33: =EOMONTH($B$9,18) -> 46843 | C33: =EOMONTH($B$9,19) -> 46873 | D33: =C33-B33 -> 30 | E33: =I32 -> 289260.68 | F33: =E33*$B$6/100*D33/365 -> 475.49701 | G33: =H33-F33 -> 48021.412 | H33: =IF(19<=$B$8,F33,IF(19=$B$7,E33+F33,$B$11)) -> 48496.909 | I33: =E33-G33 -> 241239.27 | J33: =(1+$B$12)^A33 -> 1.0321662 | K33: =H33/J33 -> 46985.563
A34: 20 | B34: =EOMONTH($B$9,19) -> 46873 | C34: =EOMONTH($B$9,20) -> 46904 | D34: =C34-B34 -> 31 | E34: =I33 -> 241239.27 | F34: =E34*$B$6/100*D34/365 -> 409.77629 | G34: =H34-F34 -> 48087.133 | H34: =IF(20<=$B$8,F34,IF(20=$B$7,E34+F34,$B$11)) -> 48496.909 | I34: =E34-G34 -> 193152.13 | J34: =(1+$B$12)^A34 -> 1.0338875 | K34: =H34/J34 -> 46907.337
A35: 21 | B35: =EOMONTH($B$9,20) -> 46904 | C35: =EOMONTH($B$9,21) -> 46934 | D35: =C35-B35 -> 30 | E35: =I34 -> 193152.13 | F35: =E35*$B$6/100*D35/365 -> 317.51035 | G35: =H35-F35 -> 48179.399 | H35: =IF(21<=$B$8,F35,IF(21=$B$7,E35+F35,$B$11)) -> 48496.909 | I35: =E35-G35 -> 144972.73 | J35: =(1+$B$12)^A35 -> 1.0356117 | K35: =H35/J35 -> 46829.24
A36: 22 | B36: =EOMONTH($B$9,21) -> 46934 | C36: =EOMONTH($B$9,22) -> 46965 | D36: =C36-B36 -> 31 | E36: =I35 -> 144972.73 | F36: =E36*$B$6/100*D36/365 -> 246.25505 | G36: =H36-F36 -> 48250.654 | H36: =IF(22<=$B$8,F36,IF(22=$B$7,E36+F36,$B$11)) -> 48496.909 | I36: =E36-G36 -> 96722.079 | J36: =(1+$B$12)^A36 -> 1.0373388 | K36: =H36/J36 -> 46751.273
A37: 23 | B37: =EOMONTH($B$9,22) -> 46965 | C37: =EOMONTH($B$9,23) -> 46996 | D37: =C37-B37 -> 31 | E37: =I36 -> 96722.079 | F37: =E37*$B$6/100*D37/365 -> 164.29504 | G37: =H37-F37 -> 48332.614 | H37: =IF(23<=$B$8,F37,IF(23=$B$7,E37+F37,$B$11)) -> 48496.909 | I37: =E37-G37 -> 48389.465 | J37: =(1+$B$12)^A37 -> 1.0390687 | K37: =H37/J37 -> 46673.437
A38: 24 | B38: =EOMONTH($B$9,23) -> 46996 | C38: =EOMONTH($B$9,24) -> 47026 | D38: =C38-B38 -> 30 | E38: =I37 -> 48389.465 | F38: =E38*$B$6/100*D38/365 -> 79.544326 | G38: =H38-F38 -> 48389.465 | H38: =IF(24<=$B$8,F38,IF(24=$B$7,E38+F38,$B$11)) -> 48469.009 | I38: =E38-G38 -> 0 | J38: =(1+$B$12)^A38 -> 1.0408016 | K38: =H38/J38 -> 46568.923
I39: ผลรวมมูลค่าปัจจุบัน (NPV) → | K39: =SUM(K14:K38) -> 1.0179519e-09
A40: IRR / MONTH (%) — คำนวณ | E40: =ROUND(IRR(H14:H38,$B$6/100/12)*100,4) -> 0.1668 | I40: (≈ 0 → ยืนยันว่า i นี้คือ IRR)
A41: IRR / MONTH (%) — ที่ระบบแสดง (กรอกเทียบ) | E41: 0.1668
...
