Workbook

Sheet MoM Requirements
A1: Minutes of Meeting (MoM) — MGC Loan & Leasing
A2: Meeting Date: 30 September 2026 (30/09/2569) Topic: MGC – Loan & Leasing Objective: Review Prototype, confirm business requirements, identify required enhancements, and define next actions.
A4: ลำดับ | B4: หัวข้อ (Module) | C4: ประเภท | D4: รายละเอียด | E4: มีใน BRD? | F4: หมายเหตุ | G4: สถานะ | H4: ผู้รับผิดชอบ | I4: กำหนดเสร็จ
A5: 1 | B5: 1 Dashboard | C5: Requirement | D5: Dashboard ต้องสามารถแสดงภาพรวมวงเงิน และเลือกดูข้อมูลแยกตาม Bank / MA / CA | E5: มี | F5: BRD เป็นภาพรวม ถ้าเจาะจงตามที่ต้องการต้องปรับเพิ่มใหม่
A6: 2 | B6: 1 Dashboard | C6: Requirement | D6: ผู้ใช้งานต้องสามารถดูได้ว่าแต่ละวงเงิน • วงเงินทั้งหมดเท่าไร • ใช้ไปแล้วเท่าไร • คงเหลือเท่าไร • ใช้ไปแล้วคิดเป็นกี่เปอร์เซ็นต์ | E6: มี | F6: BRD เป็นภาพรวม ถ้าเจาะจงตามที่ต้องการต้องปรับเพิ่มใหม่
A7: 3 | B7: 1 Dashboard | C7: Requirement | D7: กรณีเป็น Shared Credit Line ต้องสามารถดูการใช้งานของแต่ละบริษัทลูกได้ว่าใช้ไปและคงเหลือเท่าไร | E7: มี | F7: BRD เป็นภาพรวม ถ้าเจาะจงตามที่ต้องการต้องปรับเพิ่มใหม่
A8: 4 | B8: 1 Dashboard | C8: Requirement | D8: ต้องสามารถ Filter และเลือกดูแต่ละวงเงินของธนาคารได้ | E8: ไม่มี | F8: BRD เป็นภาพรวม ถ้าเจาะจงตามที่ต้องการต้องปรับเพิ่มใหม่
A9: 5 | B9: 1 Dashboard | C9: Requirement | D9: ต้องการให้สามารถตรวจสอบรายการที่ยังดำเนินการไม่ครบ เช่น • LC ที่ยังไม่มี FX • FX ที่ยังไม่ได้ผูก / Map กับ LC | E9: มี | F9: BRD เป็นภาพรวม ถ้าเจาะจงตามที่ต้องการต้องปรับเพิ่มใหม่
A10: 6 | B10: 2 Master Agreement (MA) | C10: Requirement | D10: MA ที่นำเข้าระบบถือว่าได้รับการอนุมัติจากธนาคารแล้ว | E10: มี | F10: ระบบทำได้อยู่แล้ว | G10: Done
A11: 7 | B11: 2 Master Agreement (MA) | C11: Requirement | D11: ระหว่างขั้นตอนจัดทำ/รออนุมัติในระบบ ให้มีสถานะเป็น Draft | E11: มี | F11: ระบบทำได้อยู่แล้ว | G11: Done
A12: 8 | B12: 2 Master Agreement (MA) | C12: Requirement | D12: เปลี่ยนคำว่า Subsidiary สำหรับวงเงินหลักเป็น Main | E12: ไม่มี | F12: ต้องปรับ wording
A13: 9 | B13: 2 Master Agreement (MA) | C13: Requirement | D13: การ Key-in วงเงินระดับ Subsidiary สามารถกรอกเกิน Allocation บางส่วนได้ แต่ยอดใช้งานรวมต้องไม่เกินวงเงิน Main | E13: มี | F13: BRD เป็นภาพรวม เงื่อนไขต้องปรับใหม่
A14: 10 | B14: 2 Master Agreement (MA) | C14: Requirement | D14: ในส่วน Condition ต้องการข้อมูล Ticker โดยต้องเชื่อมต่อกับ NetSuite | E14: มีบางส่วน | F14: ถ้าเชื่อมต่อ netsuite ต้องทำเพิ่ม
A15: 11 | B15: 2 Master Agreement (MA) | C15: Requirement | D15: ต้องกำหนดว่าข้อมูลจาก NetSuite จะดึงอะไรบ้าง และกำหนด Frequency โดยเบื้องต้นเป็น รายเดือน | E15: มีบางส่วน | F15: ถ้าเชื่อมต่อ netsuite ต้องทำเพิ่ม
A16: 12 | B16: 2 Master Agreement (MA) | C16: Requirement | D16: ในส่วน Collateral ต้องสามารถ Upload File ได้ | E16: ไม่มี | F16: สามารถ upload file ได้ที่ tab document
A17: 13 | B17: 3 Credit Agreement (CA) | C17: Requirement | D17: เมื่อสร้าง CA ต้องดึง Credit Line จาก MA อัตโนมัติ | E17: ไม่มี | F17: ถ้าดึงอัตโนมัติต้องใส่เพิ่ม logic
A18: 14 | B18: 3 Credit Agreement (CA) | C18: Requirement | D18: ข้อมูลที่ดึงจาก MA ต้องสามารถแก้ไขได้ตามสิทธิ์/เงื่อนไขที่กำหนด | E18: มีบางส่วน
A19: 15 | B19: 3 Credit Agreement (CA) | C19: Requirement | D19: ส่วน Accounting ไม่ต้องการให้ User เลือก Account เองทุกครั้ง โดยควร Default / Set Account ไว้จาก Mapping | E19: ไม่มี | F19: ปรับเงื่อนไขใหม่ เพราะ BRD ให้เลือกเอง แต่ระบบทำไว้ให้รองรับแล้ว
A20: 16 | B20: 3 Credit Agreement (CA) | C20: Requirement | D20: ต้องหารือเพิ่มเติมเรื่อง Accounting Mapping | E20: มีบางส่วน
A21: 17 | B21: 3 Credit Agreement (CA) | C21: Requirement | D21: ตอนส่งข้อมูลต้องระบุว่าเป็น Vendor ใด | E21: ไม่มี
A22: 18 | B22: 3 Credit Agreement (CA) | C22: Requirement | D22: หากเป็นไปได้ ระบบควรเลือก Card / Vendor ที่เกี่ยวข้องให้อัตโนมัติ | E22: ไม่มี
A23: 19 | B23: 3 Credit Agreement (CA) | C23: Requirement | D23: พบประเด็น UI บางส่วนไม่สอดคล้องกัน | E23: รอตรวจสอบ
A24: 20 | B24: 4 Promissory Note (PN) | C24: Requirement | D24: เมื่อเลือก CA แล้ว ระบบต้อง Lock Bank ตาม CA ทันที | E24: มีบางส่วน | F24: เพิ่มการ filter
A25: 21 | B25: 4 Promissory Note (PN) | C25: Requirement | D25: Currency ของ PN ต้องอ้างอิงตาม Currency ของ CA | E25: มีบางส่วน | F25: BRD เป็นภาพรวมถ้าให้ดึงตามต้องเพิ่มเงื่อนไข
A26: 22 | B26: 4 Promissory Note (PN) | C26: Requirement | D26: หาก Transaction บันทึกเป็น Foreign Currency ต้องการให้ส่งไป NetSuite ด้วย Currency เดิม เช่น CNY → ส่ง CNY โดยไม่ต้องแปลงเป็น THB ในระบบ Loan & Leasing และให้ NetSuite เป็นผู้จัดการ Exchange Rate | E26: มีบางส่วน | F26: BRD เป็นภาพรวมถ้าให้ดึงตามต้องเพิ่มเงื่อนไข
A27: 23 | B27: 4 Promissory Note (PN) | C27: Requirement | D27: ต้องสามารถเพิ่ม PO มากกว่า 1 รายการ | E27: มีบางส่วน | F27: BRD เป็นภาพรวมถ้าให้ดึงตามต้องเพิ่มเงื่อนไข
A28: 24 | B28: 4 Promissory Note (PN) | C28: Requirement | D28: Chassis สามารถมีข้อมูลซ้ำได้ จึงต้องเพิ่ม Search Criteria เพื่อช่วยค้นหา | E28: มีบางส่วน | F28: BRD เป็นภาพรวมถ้าให้ดึงตามต้องเพิ่มเงื่อนไข
A29: 25 | B29: 4 Promissory Note (PN) | C29: Requirement | D29: ต้อง Confirm Logic เรื่อง VAT / Cost เช่น • Cost รวม VAT • Cost ไม่รวม VAT • VAT | E29: มีบางส่วน | F29: ถ้าต้องการดึงข้อมูลรถยนต์ว่า VAT หรือ ไม่ ทาง mgc ต้อง confirm รายละเอียดให้อีกครั้ง
A30: 26 | B30: 4 Promissory Note (PN) | C30: Requirement | D30: ต้องตรวจสอบกรณีมีรถใหม่เข้ามาว่า Chassis จะถูก Add เข้าระบบอัตโนมัติหรือไม่ | E30: มี | F30: ระบบ L&L รองรับอยู่แล้ว ขึ้นอยู่กับข้อมูล Netsuite | G30: Done
A31: 27 | B31: 4 Promissory Note (PN) | C31: Requirement | D31: Reconcile ต้องรองรับกรณี • ตัดเกิน • ตัดขาด | E31: มีบางส่วน | F31: ตัดขาดต้องทำเพิ่ม
A32: 28 | B32: 5 RP | C32: Requirement | D32: ต้องสามารถดึงค่าจาก Schedule Calculate มาใช้ได้ | E32: ไม่มี
A33: 29 | B33: 5 RP | C33: Requirement | D33: ค่าที่ดึงมาต้องสามารถแก้ไขได้ | E33: ไม่มี
A34: 30 | B34: 6 Journal Entry (JE) | C34: Requirement | D34: ต้องมีขั้นตอน Recheck JE ก่อนส่งข้อมูลไป NetSuite | E34: มี | F34: มีอยู่หน้า JE detail แล้ว
A35: 31 | B35: 6 Journal Entry (JE) | C35: Requirement | D35: ต้องตรวจสอบความถูกต้องของ Account และ Amount ก่อน Interface | E35: มี | F35: มีอยู่หน้า JE detail แล้ว
A36: 32 | B36: 7 LG / BG | C36: Requirement | D36: รองรับกรณี ค่าธรรมเนียมรับคืน | E36: ไม่มี
A37: 33 | B37: 7 LG / BG | C37: Requirement | D37: ต้องมี Amortization Table | E37: ไม่มี
A38: 34 | B38: 8 Letter of Credit (LC) | C38: Requirement | D38: ต้องทบทวน Logic เรื่อง วันที่ / วันที่เริ่มต้น | E38: ไม่มี
A39: 35 | B39: 8 Letter of Credit (LC) | C39: Requirement | D39: หลังปรับแก้แล้วต้องนำกลับมา Confirm อีกครั้ง | E39: NA
A40: 36 | B40: 8 Letter of Credit (LC) | C40: Requirement | D40: LC 1 รายการต้องสามารถผูก FX ได้หลายรายการ | E40: ไม่มี
A41: 37 | B41: 8 Letter of Credit (LC) | C41: Requirement | D41: LC เป็นลักษณะ จ่ายปิดครั้งเดียว | E41: NA
...

Sheet สรุป มีใน BRD
A1: สรุปสถานะ "มีใน BRD?" — MGC Loan & Leasing
A2: อัปเดตอัตโนมัติจากหน้า MoM Requirements (ใช้สูตร COUNTIF) — แก้สถานะหน้า detail แล้วตัวเลขที่นี่เปลี่ยนตาม
A4: ภาพรวมทั้งระบบ
A5: สถานะ | B5: จำนวน | C5: สัดส่วน
A6: มี | B6: =COUNTIF('MoM Requirements'!$E$5:$E$79,A6) | C6: =IF($B$11=0,0,B6/$B$11)
A7: มีบางส่วน | B7: =COUNTIF('MoM Requirements'!$E$5:$E$79,A7) | C7: =IF($B$11=0,0,B7/$B$11)
A8: ไม่มี | B8: =COUNTIF('MoM Requirements'!$E$5:$E$79,A8) | C8: =IF($B$11=0,0,B8/$B$11)
A9: รอตรวจสอบ | B9: =COUNTIF('MoM Requirements'!$E$5:$E$79,A9) | C9: =IF($B$11=0,0,B9/$B$11)
A10: NA | B10: =COUNTIF('MoM Requirements'!$E$5:$E$79,A10) | C10: =IF($B$11=0,0,B10/$B$11)
A11: รวม | B11: =SUM(B6:B10) | C11: =SUM(C6:C10)
A13: แยกตามหัวข้อ (Module)
A14: หัวข้อ (Module) | B14: มี | C14: มีบางส่วน | D14: ไม่มี | E14: รอตรวจสอบ | F14: NA | G14: รวม
A15: 1 Dashboard | B15: =COUNTIFS('MoM Requirements'!$B$5:$B$79,$A15,'MoM Requirements'!$E$5:$E$79,B$14) | C15: =COUNTIFS('MoM Requirements'!$B$5:$B$79,$A15,'MoM Requirements'!$E$5:$E$79,C$14) | D15: =COUNTIFS('MoM Requirements'!$B$5:$B$79,$A15,'MoM Requirements'!$E$5:$E$79,D$14) | E15: =COUNTIFS('MoM Requirements'!$B$5:$B$79,$A15,'MoM Requirements'!$E$5:$E$79,E$14) | F15: =COUNTIFS('MoM Requirements'!$B$5:$B$79,$A15,'MoM Requirements'!$E$5:$E$79,F$14) | G15: =SUM(B15:F15)
A16: 2 Master Agreement (MA) | B16: =COUNTIFS('MoM Requirements'!$B$5:$B$79,$A16,'MoM Requirements'!$E$5:$E$79,B$14) | C16: =COUNTIFS('MoM Requirements'!$B$5:$B$79,$A16,'MoM Requirements'!$E$5:$E$79,C$14) | D16: =COUNTIFS('MoM Requirements'!$B$5:$B$79,$A16,'MoM Requirements'!$E$5:$E$79,D$14) | E16: =COUNTIFS('MoM Requirements'!$B$5:$B$79,$A16,'MoM Requirements'!$E$5:$E$79,E$14) | F16: =COUNTIFS('MoM Requirements'!$B$5:$B$79,$A16,'MoM Requirements'!$E$5:$E$79,F$14) | G16: =SUM(B16:F16)
A17: 3 Credit Agreement (CA) | B17: =COUNTIFS('MoM Requirements'!$B$5:$B$79,$A17,'MoM Requirements'!$E$5:$E$79,B$14) | C17: =COUNTIFS('MoM Requirements'!$B$5:$B$79,$A17,'MoM Requirements'!$E$5:$E$79,C$14) | D17: =COUNTIFS('MoM Requirements'!$B$5:$B$79,$A17,'MoM Requirements'!$E$5:$E$79,D$14) | E17: =COUNTIFS('MoM Requirements'!$B$5:$B$79,$A17,'MoM Requirements'!$E$5:$E$79,E$14) | F17: =COUNTIFS('MoM Requirements'!$B$5:$B$79,$A17,'MoM Requirements'!$E$5:$E$79,F$14) | G17: =SUM(B17:F17)
A18: 4 Promissory Note (PN) | B18: =COUNTIFS('MoM Requirements'!$B$5:$B$79,$A18,'MoM Requirements'!$E$5:$E$79,B$14) | C18: =COUNTIFS('MoM Requirements'!$B$5:$B$79,$A18,'MoM Requirements'!$E$5:$E$79,C$14) | D18: =COUNTIFS('MoM Requirements'!$B$5:$B$79,$A18,'MoM Requirements'!$E$5:$E$79,D$14) | E18: =COUNTIFS('MoM Requirements'!$B$5:$B$79,$A18,'MoM Requirements'!$E$5:$E$79,E$14) | F18: =COUNTIFS('MoM Requirements'!$B$5:$B$79,$A18,'MoM Requirements'!$E$5:$E$79,F$14) | G18: =SUM(B18:F18)
A19: 5 RP | B19: =COUNTIFS('MoM Requirements'!$B$5:$B$79,$A19,'MoM Requirements'!$E$5:$E$79,B$14) | C19: =COUNTIFS('MoM Requirements'!$B$5:$B$79,$A19,'MoM Requirements'!$E$5:$E$79,C$14) | D19: =COUNTIFS('MoM Requirements'!$B$5:$B$79,$A19,'MoM Requirements'!$E$5:$E$79,D$14) | E19: =COUNTIFS('MoM Requirements'!$B$5:$B$79,$A19,'MoM Requirements'!$E$5:$E$79,E$14) | F19: =COUNTIFS('MoM Requirements'!$B$5:$B$79,$A19,'MoM Requirements'!$E$5:$E$79,F$14) | G19: =SUM(B19:F19)
A20: 6 Journal Entry (JE) | B20: =COUNTIFS('MoM Requirements'!$B$5:$B$79,$A20,'MoM Requirements'!$E$5:$E$79,B$14) | C20: =COUNTIFS('MoM Requirements'!$B$5:$B$79,$A20,'MoM Requirements'!$E$5:$E$79,C$14) | D20: =COUNTIFS('MoM Requirements'!$B$5:$B$79,$A20,'MoM Requirements'!$E$5:$E$79,D$14) | E20: =COUNTIFS('MoM Requirements'!$B$5:$B$79,$A20,'MoM Requirements'!$E$5:$E$79,E$14) | F20: =COUNTIFS('MoM Requirements'!$B$5:$B$79,$A20,'MoM Requirements'!$E$5:$E$79,F$14) | G20: =SUM(B20:F20)
A21: 7 LG / BG | B21: =COUNTIFS('MoM Requirements'!$B$5:$B$79,$A21,'MoM Requirements'!$E$5:$E$79,B$14) | C21: =COUNTIFS('MoM Requirements'!$B$5:$B$79,$A21,'MoM Requirements'!$E$5:$E$79,C$14) | D21: =COUNTIFS('MoM Requirements'!$B$5:$B$79,$A21,'MoM Requirements'!$E$5:$E$79,D$14) | E21: =COUNTIFS('MoM Requirements'!$B$5:$B$79,$A21,'MoM Requirements'!$E$5:$E$79,E$14) | F21: =COUNTIFS('MoM Requirements'!$B$5:$B$79,$A21,'MoM Requirements'!$E$5:$E$79,F$14) | G21: =SUM(B21:F21)
A22: 8 Letter of Credit (LC) | B22: =COUNTIFS('MoM Requirements'!$B$5:$B$79,$A22,'MoM Requirements'!$E$5:$E$79,B$14) | C22: =COUNTIFS('MoM Requirements'!$B$5:$B$79,$A22,'MoM Requirements'!$E$5:$E$79,C$14) | D22: =COUNTIFS('MoM Requirements'!$B$5:$B$79,$A22,'MoM Requirements'!$E$5:$E$79,D$14) | E22: =COUNTIFS('MoM Requirements'!$B$5:$B$79,$A22,'MoM Requirements'!$E$5:$E$79,E$14) | F22: =COUNTIFS('MoM Requirements'!$B$5:$B$79,$A22,'MoM Requirements'!$E$5:$E$79,F$14) | G22: =SUM(B22:F22)
A23: 9 Floor Plan (FP) | B23: =COUNTIFS('MoM Requirements'!$B$5:$B$79,$A23,'MoM Requirements'!$E$5:$E$79,B$14) | C23: =COUNTIFS('MoM Requirements'!$B$5:$B$79,$A23,'MoM Requirements'!$E$5:$E$79,C$14) | D23: =COUNTIFS('MoM Requirements'!$B$5:$B$79,$A23,'MoM Requirements'!$E$5:$E$79,D$14) | E23: =COUNTIFS('MoM Requirements'!$B$5:$B$79,$A23,'MoM Requirements'!$E$5:$E$79,E$14) | F23: =COUNTIFS('MoM Requirements'!$B$5:$B$79,$A23,'MoM Requirements'!$E$5:$E$79,F$14) | G23: =SUM(B23:F23)
A24: 10 Overdraft (OD) | B24: =COUNTIFS('MoM Requirements'!$B$5:$B$79,$A24,'MoM Requirements'!$E$5:$E$79,B$14) | C24: =COUNTIFS('MoM Requirements'!$B$5:$B$79,$A24,'MoM Requirements'!$E$5:$E$79,C$14) | D24: =COUNTIFS('MoM Requirements'!$B$5:$B$79,$A24,'MoM Requirements'!$E$5:$E$79,D$14) | E24: =COUNTIFS('MoM Requirements'!$B$5:$B$79,$A24,'MoM Requirements'!$E$5:$E$79,E$14) | F24: =COUNTIFS('MoM Requirements'!$B$5:$B$79,$A24,'MoM Requirements'!$E$5:$E$79,F$14) | G24: =SUM(B24:F24)
A25: 11 Loan (LN) | B25: =COUNTIFS('MoM Requirements'!$B$5:$B$79,$A25,'MoM Requirements'!$E$5:$E$79,B$14) | C25: =COUNTIFS('MoM Requirements'!$B$5:$B$79,$A25,'MoM Requirements'!$E$5:$E$79,C$14) | D25: =COUNTIFS('MoM Requirements'!$B$5:$B$79,$A25,'MoM Requirements'!$E$5:$E$79,D$14) | E25: =COUNTIFS('MoM Requirements'!$B$5:$B$79,$A25,'MoM Requirements'!$E$5:$E$79,E$14) | F25: =COUNTIFS('MoM Requirements'!$B$5:$B$79,$A25,'MoM Requirements'!$E$5:$E$79,F$14) | G25: =SUM(B25:F25)
A26: 12.1 Schedule Calculate | B26: =COUNTIFS('MoM Requirements'!$B$5:$B$79,$A26,'MoM Requirements'!$E$5:$E$79,B$14) | C26: =COUNTIFS('MoM Requirements'!$B$5:$B$79,$A26,'MoM Requirements'!$E$5:$E$79,C$14) | D26: =COUNTIFS('MoM Requirements'!$B$5:$B$79,$A26,'MoM Requirements'!$E$5:$E$79,D$14) | E26: =COUNTIFS('MoM Requirements'!$B$5:$B$79,$A26,'MoM Requirements'!$E$5:$E$79,E$14) | F26: =COUNTIFS('MoM Requirements'!$B$5:$B$79,$A26,'MoM Requirements'!$E$5:$E$79,F$14) | G26: =SUM(B26:F26)
... A31: Overall Next Step | B31: =COUNTIFS('MoM Requirements'!$B$5:$B$79,$A31,'MoM Requirements'!$E$5:$E$79,B$14) | C31: =COUNTIFS('MoM Requirements'!$B$5:$B$79,$A31,'MoM Requirements'!$E$5:$E$79,C$14) | D31: =COUNTIFS('MoM Requirements'!$B$5:$B$79,$A31,'MoM Requirements'!$E$5:$E$79,D$14) | E31: =COUNTIFS('MoM Requirements'!$B$5:$B$79,$A31,'MoM Requirements'!$E$5:$E$79,E$14) | F31: =COUNTIFS('MoM Requirements'!$B$5:$B$79,$A31,'MoM Requirements'!$E$5:$E$79,F$14) | G31: =SUM(B31:F31)
A32: รวม | B32: =SUM(B15:B31) | C32: =SUM(C15:C31) | D32: =SUM(D15:D31) | E32: =SUM(E15:E31) | F32: =SUM(F15:F31) | G32: =SUM(G15:G31)

Sheet Summary
A1: สรุปจำนวน Requirement ต่อหัวข้อ
A3: หัวข้อ (Module) | B3: จำนวน
A4: 1 Dashboard | B4: 5
A5: 2 Master Agreement (MA) | B5: 7
A6: 3 Credit Agreement (CA) | B6: 7
A7: 4 Promissory Note (PN) | B7: 8
A8: 5 RP | B8: 2
A9: 6 Journal Entry (JE) | B9: 2
A10: 7 LG / BG | B10: 2
A11: 8 Letter of Credit (LC) | B11: 12
A12: 9 Floor Plan (FP) | B12: 8
A13: 10 Overdraft (OD) | B13: 4
A14: 11 Loan (LN) | B14: 10
A15: 12.1 Schedule Calculate | B15: 1
... A20: Overall Next Step | B20: 2
